Workbook

Sheet Luchenza
A1: SOUTHERN REGION WATER BOARD
A3: MONTHLY REPORTS - 2026/2027
A4: MULANJE ZONE
A5: MULANJE ZONE
A7: PARAMETERS | C7: UNITS | D7: APRIL | E7: MAY | F7: JUNE | G7: JULY | H7: AUGUST | I7: SEPTEMBER | J7: OCTOBER | K7: NOVEMBER | L7: DECEMBER | M7: JANUARY | N7: FEBRUARY | O7: MARCH | P7: TOTALS
A8: PRODUCTION
A9: Volume Produced | C9: m3 | D9: 13271 | E9: 16000 | F9: 16444 | P9: =SUM(D9:O9) -> 45715
A10: REVENUE WATER - POSTPAID
A11: Volume Billed Individuals | C11: m3 | D11: 4244 | E11: 4852 | F11: 7133 | P11: =SUM(D11:O11) -> 16229
A12: Volume Billed CWPs | C12: m3 | D12: 8 | E12: 27 | F12: 31 | P12: =SUM(D12:O12) -> 66
A13: Volume Billed Institutions | C13: m3 | D13: 8 | E13: 12 | F13: 12 | P13: =SUM(D13:O13) -> 32
A14: Volume Billed Commercial/Industrial | C14: m3 | D14: 23 | E14: 25 | F14: 19 | P14: =SUM(D14:O14) -> 67
A15: Total Volume Billed Post Paid | C15: m3 | D15: =SUM(D11:D14) -> 4283 | E15: =SUM(E11:E14) -> 4916 | F15: =SUM(F11:F14) -> 7195 | G15: =SUM(G11:G14) -> 0 | H15: =SUM(H11:H14) -> 0 | I15: =SUM(I11:I14) -> 0 | J15: =SUM(J11:J14) -> 0 | K15: =SUM(K11:K14) -> 0 | ... P15: =SUM(P11:P14) -> 16394
A16: REVENUE WATER - PREPAID
A17: Individuals | C17: m3 | D17: 4714 | E17: 5402 | F17: 4013 | P17: =SUM(D17:O17) -> 14129
A18: CWPs | C18: m3 | D18: 186 | E18: 246 | F18: 209 | P18: =SUM(D18:O18) -> 641
A19: Institutions | C19: m3 | D19: 167 | E19: 228 | F19: 137 | P19: =SUM(D19:O19) -> 532
A20: Commercial/Industrial | C20: m3 | D20: 203 | E20: 366 | F20: 220 | P20: =SUM(D20:O20) -> 789
A21: Total Volume Prepaid | C21: m3 | D21: =SUM(D17:D20) -> 5270 | E21: =SUM(E17:E20) -> 6242 | F21: =SUM(F17:F20) -> 4579 | G21: =SUM(G17:G20) -> 0 | H21: =SUM(H17:H20) -> 0 | I21: =SUM(I17:I20) -> 0 | J21: =SUM(J17:J20) -> 0 | K21: =SUM(K17:K20) -> 0 | ... P21: =SUM(P17:P20) -> 16091
A22: TOTAL REVENUE WATER | C22: m3 | D22: =D21+D15 -> 9553 | E22: =E21+E15 -> 11158 | F22: =F21+F15 -> 11774 | G22: =G21+G15 -> 0 | H22: =H21+H15 -> 0 | I22: =I21+I15 -> 0 | J22: =J21+J15 -> 0 | K22: =K21+K15 -> 0 | ... P22: =P21+P15 -> 32485
A24: Non-Revenue Water (NRW) | B24: Volume | C24: m3 | D24: =D9-D22 -> 3718 | E24: =E9-E22 -> 4842 | F24: =F9-F22 -> 4670 | G24: =G9-G22 -> 0 | H24: =H9-H22 -> 0 | I24: =I9-I22 -> 0 | J24: =J9-J22 -> 0 | K24: =K9-K22 -> 0 | ... P24: =P9-P22 -> 13230
B25: Percentage | C25: % | D25: =D24/D9 -> 0.28015975 | E25: =E24/E9 -> 0.302625 | F25: =F24/F9 -> 0.28399416 | G25: =G24/G9 -> #DIV/0! | H25: =H24/H9 -> #DIV/0! | I25: =I24/I9 -> #DIV/0! | J25: =J24/J9 -> #DIV/0! | K25: =K24/K9 -> #DIV/0! | ... P25: =P24/P9 -> 0.28940173
A26: OPERATING EXPENSES
A27: Chemicals
A28: Chemical | B28: Rate(MK/kg)
A29: Chlorine | B29: 5111.67 | C29: kg | D29: 35 | E29: 41 | F29: 42 | P29: =SUM(D29:O29) -> 118
C30: kg/mg litre | D30: =D29/(D9/1000) -> 2.6373295 | E30: =E29/(E9/1000) -> 2.5625 | F30: =F29/(F9/1000) -> 2.5541231 | G30: =G29/(G9/1000) -> #DIV/0! | H30: =H29/(H9/1000) -> #DIV/0! | I30: =I29/(I9/1000) -> #DIV/0! | J30: =J29/(J9/1000) -> #DIV/0! | K30: =K29/(K9/1000) -> #DIV/0! | ... N30: =N29/(N9/1000) -> #DIV/0! | P30: =P29/(P9/1000) -> 2.5812097
A31: Aluminium sulphate | B31: 1537 | C31: kg | P31: =SUM(D31:O31) -> 0
C32: kg/mg litre | D32: =D31/(D9/1000) -> 0 | E32: =E31/(E9/1000) -> 0 | F32: =F31/(F9/1000) -> 0 | G32: =G31/(G9/1000) -> #DIV/0! | H32: =H31/(H9/1000) -> #DIV/0! | I32: =I31/(I9/1000) -> #DIV/0! | J32: =J31/(J9/1000) -> #DIV/0! | K32: =K31/(K9/1000) -> #DIV/0! | ... N32: =N31/(N9/1000) -> #DIV/0! | P32: =P31/(P9/1000) -> 0
A33: Soda | B33: 1781.02 | C33: kg | P33: =SUM(D33:O33) -> 0
C34: kg/mg litre | D34: =D33/(D9/1000) -> 0 | E34: =E33/(E9/1000) -> 0 | F34: =F33/(F9/1000) -> 0 | G34: =G33/(G9/1000) -> #DIV/0! | H34: =H33/(H9/1000) -> #DIV/0! | I34: =I33/(I9/1000) -> #DIV/0! | J34: =J33/(J9/1000) -> #DIV/0! | K34: =K33/(K9/1000) -> #DIV/0! | ... N34: =N33/(N9/1000) -> #DIV/0! | P34: =P33/(P9/1000) -> 0
A35: Algae floc | B35: 5979.95 | C35: litres
C36: litres/mg litre
A37: Sud floc | B37: 5403.75 | C37: litres | P37: =SUM(D37:O37) -> 0
C38: litres/mg litre | D38: =D37/(D9/1000) -> 0 | E38: =E37/(E9/1000) -> 0 | F38: =F37/(F9/1000) -> 0 | G38: =G37/(G9/1000) -> #DIV/0! | H38: =H37/(H9/1000) -> #DIV/0! | I38: =I37/(I9/1000) -> #DIV/0! | J38: =J37/(J9/1000) -> #DIV/0! | K38: =K37/(K9/1000) -> #DIV/0! | ... N38: =N37/(N9/1000) -> #DIV/0! | P38: =P37/(P9/1000) -> 0
A39: Potasium permanganate | B39: 1950 | C39: kg | P39: =SUM(D39:O39) -> 0
C40: kg/mg litre | D40: =D39/(D9/1000) -> 0 | E40: =E39/(E9/1000) -> 0 | F40: =F39/(F9/1000) -> 0 | G40: =G39/(G9/1000) -> #DIV/0! | H40: =H39/(H9/1000) -> #DIV/0! | I40: =I39/(I9/1000) -> #DIV/0! | J40: =J39/(J9/1000) -> #DIV/0! | K40: =K39/(K9/1000) -> #DIV/0! | ... N40: =N39/(N9/1000) -> #DIV/0! | P40: =P39/(P9/1000) -> 0
A41: Cost of Chemicals | C41: Mk | D41: =(D29*$B29)+(D31*$B31)+(D33*$B33)+(D35*$B35)+(D37*$B37)+(D39*$B39) -> 178908.45 | E41: =(E29*$B29)+(E31*$B31)+(E33*$B33)+(E35*$B35)+(E37*$B37)+(E39*$B39) -> 209578.47 | F41: =(F29*$B29)+(F31*$B31)+(F33*$B33)+(F35*$B35)+(F37*$B37)+(F39*$B39) -> 214690.14 | G41: =(G29*$B29)+(G31*$B31)+(G33*$B33)+(G35*$B35)+(G37*$B37)+(G39*$B39) -> 0 | H41: =(H29*$B29)+(H31*$B31)+(H33*$B33)+(H35*$B35)+(H37*$B37)+(H39*$B39) -> 0 | I41: =(I29*$B29)+(I31*$B31)+(I33*$B33)+(I35*$B35)+(I37*$B37)+(I39*$B39) -> 0 | J41: =(J29*$B29)+(J31*$B31)+(J33*$B33)+(J35*$B35)+(J37*$B37)+(J39*$B39) -> 0 | K41: =(K29*$B29)+(K31*$B31)+(K33*$B33)+(K35*$B35)+(K37*$B37)+(K39*$B39) -> 0 | ... O41: =(O29*$B29)+(O31*$B31)+(O33*$B33)+(O35*$B35)+(O37*$B37)+(O39*$B39) -> 0 | P41: =SUM(D41:O41) -> 603177.06
A42: Cost/vol. Produced (chemicals) | C42: Mk/m3 | D42: =D41/D9 -> 13.481158 | E42: =E41/E9 -> 13.098654 | F42: =F41/F9 -> 13.055834 | G42: =G41/G9 -> #DIV/0! | H42: =H41/H9 -> #DIV/0! | I42: =I41/I9 -> #DIV/0! | J42: =J41/J9 -> #DIV/0! | K42: =K41/K9 -> #DIV/0! | ... P42: =P41/P9 -> 13.194292
A43: Power
...

Sheet Mulanje
A1: SOUTHERN REGION WATER BOARD
A3: MONTHLY REPORTS - 2026/2027
A4: MULANJE ZONE
A5: MULANJE ZONE
A7: PARAMETERS | C7: UNITS | D7: APRIL | E7: MAY | F7: JUNE | G7: JULY | H7: AUGUST | I7: SEPTEMBER | J7: OCTOBER | K7: NOVEMBER | L7: DECEMBER | M7: JANUARY | N7: FEBRUARY | O7: MARCH | P7: TOTALS
A8: PRODUCTION
A9: Volume Produced | C9: m3 | D9: 43194 | E9: 47903 | F9: 48675 | P9: =SUM(D9:O9) -> 139772
A10: REVENUE WATER - POSTPAID
A11: Volume Billed Individuals | C11: m3 | D11: 15725 | E11: 15973 | F11: 18757 | P11: =SUM(D11:O11) -> 50455
A12: Volume Billed CWPs | C12: m3 | D12: 813 | E12: 877 | F12: 1050 | P12: =SUM(D12:O12) -> 2740
A13: Volume Billed Institutions | C13: m3 | D13: 117 | E13: 85 | F13: 161 | P13: =SUM(D13:O13) -> 363
A14: Volume Billed Commercial/Industrial | C14: m3 | D14: 113 | E14: 240 | F14: 219 | P14: =SUM(D14:O14) -> 572
A15: Total Volume Billed Post Paid | C15: m3 | D15: =SUM(D11:D14) -> 16768 | E15: =SUM(E11:E14) -> 17175 | F15: =SUM(F11:F14) -> 20187 | G15: =SUM(G11:G14) -> 0 | H15: =SUM(H11:H14) -> 0 | I15: =SUM(I11:I14) -> 0 | J15: =SUM(J11:J14) -> 0 | K15: =SUM(K11:K14) -> 0 | ... P15: =SUM(P11:P14) -> 54130
A16: REVENUE WATER - PREPAID
A17: Individuals | C17: m3 | D17: 7965.53 | E17: 8716.5 | F17: 8365.2 | P17: =SUM(D17:O17) -> 25047.23
A18: CWPs | C18: m3 | P18: =SUM(D18:O18) -> 0
A19: Institutions | C19: m3 | D19: 5415.63 | E19: 6954.9 | F19: 5241.8 | P19: =SUM(D19:O19) -> 17612.33
A20: Commercial/Industrial | C20: m3 | D20: 714 | E20: 989 | F20: 916 | P20: =SUM(D20:O20) -> 2619
A21: Total Volume Prepaid | C21: m3 | D21: =SUM(D17:D20) -> 14095.16 | E21: =SUM(E17:E20) -> 16660.4 | F21: =SUM(F17:F20) -> 14523 | G21: =SUM(G17:G20) -> 0 | H21: =SUM(H17:H20) -> 0 | I21: =SUM(I17:I20) -> 0 | J21: =SUM(J17:J20) -> 0 | K21: =SUM(K17:K20) -> 0 | ... P21: =SUM(P17:P20) -> 45278.56
A22: TOTAL REVENUE WATER | C22: m3 | D22: =D21+D15 -> 30863.16 | E22: =E21+E15 -> 33835.4 | F22: =F21+F15 -> 34710 | G22: =G21+G15 -> 0 | H22: =H21+H15 -> 0 | I22: =I21+I15 -> 0 | J22: =J21+J15 -> 0 | K22: =K21+K15 -> 0 | ... P22: =P21+P15 -> 99408.56
A24: Non-Revenue Water (NRW) | B24: Volume | C24: m3 | D24: =D9-D22 -> 12330.84 | E24: =E9-E22 -> 14067.6 | F24: =F9-F22 -> 13965 | G24: =G9-G22 -> 0 | H24: =H9-H22 -> 0 | I24: =I9-I22 -> 0 | J24: =J9-J22 -> 0 | K24: =K9-K22 -> 0 | ... P24: =P9-P22 -> 40363.44
B25: Percentage | C25: % | D25: =D24/D9 -> 0.28547576 | E25: =E24/E9 -> 0.29366846 | F25: =F24/F9 -> 0.28690293 | G25: =G24/G9 -> #DIV/0! | H25: =H24/H9 -> #DIV/0! | I25: =I24/I9 -> #DIV/0! | J25: =J24/J9 -> #DIV/0! | K25: =K24/K9 -> #DIV/0! | ... P25: =P24/P9 -> 0.28878059
A26: OPERATING EXPENSES
A27: Chemicals
A28: Chemical | B28: Rate(MK/kg)
A29: Chlorine | B29: 5111.67 | C29: kg | D29: 90 | E29: 94 | F29: 97 | P29: =SUM(D29:O29) -> 281
C30: kg/mg litre | D30: =D29/(D9/1000) -> 2.0836227 | E30: =E29/(E9/1000) -> 1.9622988 | F30: =F29/(F9/1000) -> 1.9928095 | G30: =G29/(G9/1000) -> #DIV/0! | H30: =H29/(H9/1000) -> #DIV/0! | I30: =I29/(I9/1000) -> #DIV/0! | J30: =J29/(J9/1000) -> #DIV/0! | K30: =K29/(K9/1000) -> #DIV/0! | ... N30: =N29/(N9/1000) -> #DIV/0! | P30: =P29/(P9/1000) -> 2.010417
A31: Aluminium sulphate | B31: 1537 | C31: kg | P31: =SUM(D31:O31) -> 0
C32: kg/mg litre | D32: =D31/(D9/1000) -> 0 | E32: =E31/(E9/1000) -> 0 | F32: =F31/(F9/1000) -> 0 | G32: =G31/(G9/1000) -> #DIV/0! | H32: =H31/(H9/1000) -> #DIV/0! | I32: =I31/(I9/1000) -> #DIV/0! | J32: =J31/(J9/1000) -> #DIV/0! | K32: =K31/(K9/1000) -> #DIV/0! | ... N32: =N31/(N9/1000) -> #DIV/0! | P32: =P31/(P9/1000) -> 0
A33: Soda | B33: 1781.02 | C33: kg | P33: =SUM(D33:O33) -> 0
C34: kg/mg litre | D34: =D33/(D9/1000) -> 0 | E34: =E33/(E9/1000) -> 0 | F34: =F33/(F9/1000) -> 0 | G34: =G33/(G9/1000) -> #DIV/0! | H34: =H33/(H9/1000) -> #DIV/0! | I34: =I33/(I9/1000) -> #DIV/0! | J34: =J33/(J9/1000) -> #DIV/0! | K34: =K33/(K9/1000) -> #DIV/0! | ... N34: =N33/(N9/1000) -> #DIV/0! | P34: =P33/(P9/1000) -> 0
A35: Algae floc | B35: 5979.95 | C35: litres
C36: litres/mg litre
A37: Sud floc | B37: 5403.75 | C37: litres | P37: =SUM(D37:O37) -> 0
C38: litres/mg litre | D38: =D37/(D9/1000) -> 0 | E38: =E37/(E9/1000) -> 0 | F38: =F37/(F9/1000) -> 0 | G38: =G37/(G9/1000) -> #DIV/0! | H38: =H37/(H9/1000) -> #DIV/0! | I38: =I37/(I9/1000) -> #DIV/0! | J38: =J37/(J9/1000) -> #DIV/0! | K38: =K37/(K9/1000) -> #DIV/0! | ... N38: =N37/(N9/1000) -> #DIV/0! | P38: =P37/(P9/1000) -> 0
A39: Potasium permanganate | B39: 1950 | C39: kg | P39: =SUM(D39:O39) -> 0
C40: kg/mg litre | D40: =D39/(D9/1000) -> 0 | E40: =E39/(E9/1000) -> 0 | F40: =F39/(F9/1000) -> 0 | G40: =G39/(G9/1000) -> #DIV/0! | H40: =H39/(H9/1000) -> #DIV/0! | I40: =I39/(I9/1000) -> #DIV/0! | J40: =J39/(J9/1000) -> #DIV/0! | K40: =K39/(K9/1000) -> #DIV/0! | ... N40: =N39/(N9/1000) -> #DIV/0! | P40: =P39/(P9/1000) -> 0
A41: Cost of Chemicals | C41: Mk | D41: =(D29*$B29)+(D31*$B31)+(D33*$B33)+(D35*$B35)+(D37*$B37)+(D39*$B39) -> 460050.3 | E41: =(E29*$B29)+(E31*$B31)+(E33*$B33)+(E35*$B35)+(E37*$B37)+(E39*$B39) -> 480496.98 | F41: =(F29*$B29)+(F31*$B31)+(F33*$B33)+(F35*$B35)+(F37*$B37)+(F39*$B39) -> 495831.99 | G41: =(G29*$B29)+(G31*$B31)+(G33*$B33)+(G35*$B35)+(G37*$B37)+(G39*$B39) -> 0 | H41: =(H29*$B29)+(H31*$B31)+(H33*$B33)+(H35*$B35)+(H37*$B37)+(H39*$B39) -> 0 | I41: =(I29*$B29)+(I31*$B31)+(I33*$B33)+(I35*$B35)+(I37*$B37)+(I39*$B39) -> 0 | J41: =(J29*$B29)+(J31*$B31)+(J33*$B33)+(J35*$B35)+(J37*$B37)+(J39*$B39) -> 0 | K41: =(K29*$B29)+(K31*$B31)+(K33*$B33)+(K35*$B35)+(K37*$B37)+(K39*$B39) -> 0 | ... O41: =(O29*$B29)+(O31*$B31)+(O33*$B33)+(O35*$B35)+(O37*$B37)+(O39*$B39) -> 0 | P41: =SUM(D41:O41) -> 1436379.3
A42: Cost/vol. Produced (chemicals) | C42: Mk/m3 | D42: =D41/D9 -> 10.650792 | E42: =E41/E9 -> 10.030624 | F42: =F41/F9 -> 10.186584 | G42: =G41/G9 -> #DIV/0! | H42: =H41/H9 -> #DIV/0! | I42: =I41/I9 -> #DIV/0! | J42: =J41/J9 -> #DIV/0! | K42: =K41/K9 -> #DIV/0! | ... P42: =P41/P9 -> 10.276588
A43: Power
...

Sheet Thyolo
A1: SOUTHERN REGION WATER BOARD
A3: MONTHLY REPORTS - 2026/2027
A4: MULANJE ZONE
A5: MULANJE ZONE
A7: PARAMETERS | C7: UNITS | D7: APRIL | E7: MAY | F7: JUNE | G7: JULY | H7: AUGUST | I7: SEPTEMBER | J7: OCTOBER | K7: NOVEMBER | L7: DECEMBER | M7: JANUARY | N7: FEBRUARY | O7: MARCH | P7: TOTALS
A8: PRODUCTION
A9: Volume Produced | C9: m3 | D9: 13500 | E9: 14160 | F9: 16850 | P9: =SUM(D9:O9) -> 44510
A10: REVENUE WATER - POSTPAID
A11: Volume Billed Individuals | C11: m3 | D11: 3924 | E11: 3444 | F11: 4557 | P11: =SUM(D11:O11) -> 11925
A12: Volume Billed CWPs | C12: m3 | D12: 4 | E12: 4 | F12: 4 | P12: =SUM(D12:O12) -> 12
A13: Volume Billed Institutions | C13: m3 | P13: =SUM(D13:O13) -> 0
A14: Volume Billed Commercial/Industrial | C14: m3 | D14: 29 | E14: 38 | F14: 26 | P14: =SUM(D14:O14) -> 93
A15: Total Volume Billed Post Paid | C15: m3 | D15: =SUM(D11:D14) -> 3957 | E15: =SUM(E11:E14) -> 3486 | F15: =SUM(F11:F14) -> 4587 | G15: =SUM(G11:G14) -> 0 | H15: =SUM(H11:H14) -> 0 | I15: =SUM(I11:I14) -> 0 | J15: =SUM(J11:J14) -> 0 | K15: =SUM(K11:K14) -> 0 | ... P15: =SUM(P11:P14) -> 12030
A16: REVENUE WATER - PREPAID
A17: Individuals | C17: m3 | D17: 4440 | E17: 3436.8 | F17: 4922 | P17: =SUM(D17:O17) -> 12798.8
A18: CWPs | C18: m3 | D18: 10 | E18: 2 | F18: 10 | P18: =SUM(D18:O18) -> 22
A19: Institutions | C19: m3 | D19: 313 | E19: 1866 | F19: 774 | P19: =SUM(D19:O19) -> 2953
A20: Commercial/Industrial | C20: m3 | D20: 214 | E20: 372 | F20: 389 | P20: =SUM(D20:O20) -> 975
A21: Total Volume Prepaid | C21: m3 | D21: =SUM(D17:D20) -> 4977 | E21: =SUM(E17:E20) -> 5676.8 | F21: =SUM(F17:F20) -> 6095 | G21: =SUM(G17:G20) -> 0 | H21: =SUM(H17:H20) -> 0 | I21: =SUM(I17:I20) -> 0 | J21: =SUM(J17:J20) -> 0 | K21: =SUM(K17:K20) -> 0 | ... P21: =SUM(P17:P20) -> 16748.8
A22: TOTAL REVENUE WATER | C22: m3 | D22: =D21+D15 -> 8934 | E22: =E21+E15 -> 9162.8 | F22: =F21+F15 -> 10682 | G22: =G21+G15 -> 0 | H22: =H21+H15 -> 0 | I22: =I21+I15 -> 0 | J22: =J21+J15 -> 0 | K22: =K21+K15 -> 0 | ... P22: =P21+P15 -> 28778.8
A24: Non-Revenue Water (NRW) | B24: Volume | C24: m3 | D24: =D9-D22 -> 4566 | E24: =E9-E22 -> 4997.2 | F24: =F9-F22 -> 6168 | G24: =G9-G22 -> 0 | H24: =H9-H22 -> 0 | I24: =I9-I22 -> 0 | J24: =J9-J22 -> 0 | K24: =K9-K22 -> 0 | ... P24: =P9-P22 -> 15731.2
B25: Percentage | C25: % | D25: =D24/D9 -> 0.33822222 | E25: =E24/E9 -> 0.3529096 | F25: =F24/F9 -> 0.36605341 | G25: =G24/G9 -> #DIV/0! | H25: =H24/H9 -> #DIV/0! | I25: =I24/I9 -> #DIV/0! | J25: =J24/J9 -> #DIV/0! | K25: =K24/K9 -> #DIV/0! | ... P25: =P24/P9 -> 0.35343069
A26: OPERATING EXPENSES
A27: Chemicals
A28: Chemical | B28: Rate(MK/kg)
A29: Chlorine | B29: 5111.67 | C29: kg | D29: 80 | E29: 60 | F29: 80 | P29: =SUM(D29:O29) -> 220
C30: kg/mg litre | D30: =D29/(D9/1000) -> 5.9259259 | E30: =E29/(E9/1000) -> 4.2372881 | F30: =F29/(F9/1000) -> 4.7477745 | G30: =G29/(G9/1000) -> #DIV/0! | H30: =H29/(H9/1000) -> #DIV/0! | I30: =I29/(I9/1000) -> #DIV/0! | J30: =J29/(J9/1000) -> #DIV/0! | K30: =K29/(K9/1000) -> #DIV/0! | ... N30: =N29/(N9/1000) -> #DIV/0! | P30: =P29/(P9/1000) -> 4.9427095
A31: Aluminium sulphate | B31: 1537 | C31: kg | P31: =SUM(D31:O31) -> 0
C32: kg/mg litre | D32: =D31/(D9/1000) -> 0 | E32: =E31/(E9/1000) -> 0 | F32: =F31/(F9/1000) -> 0 | G32: =G31/(G9/1000) -> #DIV/0! | H32: =H31/(H9/1000) -> #DIV/0! | I32: =I31/(I9/1000) -> #DIV/0! | J32: =J31/(J9/1000) -> #DIV/0! | K32: =K31/(K9/1000) -> #DIV/0! | ... N32: =N31/(N9/1000) -> #DIV/0! | P32: =P31/(P9/1000) -> 0
A33: Soda | B33: 1781.02 | C33: kg | P33: =SUM(D33:O33) -> 0
C34: kg/mg litre | D34: =D33/(D9/1000) -> 0 | E34: =E33/(E9/1000) -> 0 | F34: =F33/(F9/1000) -> 0 | G34: =G33/(G9/1000) -> #DIV/0! | H34: =H33/(H9/1000) -> #DIV/0! | I34: =I33/(I9/1000) -> #DIV/0! | J34: =J33/(J9/1000) -> #DIV/0! | K34: =K33/(K9/1000) -> #DIV/0! | ... N34: =N33/(N9/1000) -> #DIV/0! | P34: =P33/(P9/1000) -> 0
A35: Algae floc | B35: 5979.95 | C35: litres | D35: 84 | E35: 54 | F35: 81
C36: litres/mg litre | D36: =D35/(D15/1000) -> 21.228203 | E36: =E35/(E15/1000) -> 15.490534 | F36: =F35/(F15/1000) -> 17.6586 | G36: =G35/(G15/1000) -> #DIV/0! | H36: =H35/(H15/1000) -> #DIV/0! | I36: =I35/(I15/1000) -> #DIV/0! | J36: =J35/(J15/1000) -> #DIV/0! | K36: =K35/(K15/1000) -> #DIV/0! | ... N36: =N35/(N15/1000) -> #DIV/0! | P36: =P35/(P15/1000) -> 0
A37: Sud floc | B37: 5403.75 | C37: litres | P37: =SUM(D37:O37) -> 0
C38: litres/mg litre | D38: =D37/(D9/1000) -> 0 | E38: =E37/(E9/1000) -> 0 | F38: =F37/(F9/1000) -> 0 | G38: =G37/(G9/1000) -> #DIV/0! | H38: =H37/(H9/1000) -> #DIV/0! | I38: =I37/(I9/1000) -> #DIV/0! | J38: =J37/(J9/1000) -> #DIV/0! | K38: =K37/(K9/1000) -> #DIV/0! | ... N38: =N37/(N9/1000) -> #DIV/0! | P38: =P37/(P9/1000) -> 0
A39: Potasium permanganate | B39: 1950 | C39: kg | P39: =SUM(D39:O39) -> 0
C40: kg/mg litre | D40: =D39/(D9/1000) -> 0 | E40: =E39/(E9/1000) -> 0 | F40: =F39/(F9/1000) -> 0 | G40: =G39/(G9/1000) -> #DIV/0! | H40: =H39/(H9/1000) -> #DIV/0! | I40: =I39/(I9/1000) -> #DIV/0! | J40: =J39/(J9/1000) -> #DIV/0! | K40: =K39/(K9/1000) -> #DIV/0! | ... N40: =N39/(N9/1000) -> #DIV/0! | P40: =P39/(P9/1000) -> 0
A41: Cost of Chemicals | C41: Mk | D41: =(D29*$B29)+(D31*$B31)+(D33*$B33)+(D35*$B35)+(D37*$B37)+(D39*$B39) -> 911249.4 | E41: =(E29*$B29)+(E31*$B31)+(E33*$B33)+(E35*$B35)+(E37*$B37)+(E39*$B39) -> 629617.5 | F41: =(F29*$B29)+(F31*$B31)+(F33*$B33)+(F35*$B35)+(F37*$B37)+(F39*$B39) -> 893309.55 | G41: =(G29*$B29)+(G31*$B31)+(G33*$B33)+(G35*$B35)+(G37*$B37)+(G39*$B39) -> 0 | H41: =(H29*$B29)+(H31*$B31)+(H33*$B33)+(H35*$B35)+(H37*$B37)+(H39*$B39) -> 0 | I41: =(I29*$B29)+(I31*$B31)+(I33*$B33)+(I35*$B35)+(I37*$B37)+(I39*$B39) -> 0 | J41: =(J29*$B29)+(J31*$B31)+(J33*$B33)+(J35*$B35)+(J37*$B37)+(J39*$B39) -> 0 | K41: =(K29*$B29)+(K31*$B31)+(K33*$B33)+(K35*$B35)+(K37*$B37)+(K39*$B39) -> 0 | ... O41: =(O29*$B29)+(O31*$B31)+(O33*$B33)+(O35*$B35)+(O37*$B37)+(O39*$B39) -> 0 | P41: =SUM(D41:O41) -> 2434176.5
A42: Cost/vol. Produced (chemicals) | C42: Mk/m3 | D42: =D41/D9 -> 67.499956 | E42: =E41/E9 -> 44.464513 | F42: =F41/F9 -> 53.015404 | G42: =G41/G9 -> #DIV/0! | H42: =H41/H9 -> #DIV/0! | I42: =I41/I9 -> #DIV/0! | J42: =J41/J9 -> #DIV/0! | K42: =K41/K9 -> #DIV/0! | ... P42: =P41/P9 -> 54.688305
A43: Power
...

Sheet Muloza
A1: SOUTHERN REGION WATER BOARD
A3: MONTHLY REPORTS - 2026/2027
A4: MULANJE ZONE
A5: MULANJE ZONE
A7: PARAMETERS | C7: UNITS | D7: APRIL | E7: MAY | F7: JUNE | G7: JULY | H7: AUGUST | I7: SEPTEMBER | J7: OCTOBER | K7: NOVEMBER | L7: DECEMBER | M7: JANUARY | N7: FEBRUARY | O7: MARCH | P7: TOTALS
A8: PRODUCTION
A9: Volume Produced | C9: m3 | D9: 11073 | E9: 9222 | F9: 8783 | P9: =SUM(D9:O9) -> 29078
A10: REVENUE WATER - POSTPAID
A11: Volume Billed Individuals | C11: m3 | D11: 2780 | E11: 2655 | F11: 3160 | P11: =SUM(D11:O11) -> 8595
A12: Volume Billed CWPs | C12: m3 | D12: 17 | E12: 14 | F12: 6 | P12: =SUM(D12:O12) -> 37
A13: Volume Billed Institutions | C13: m3 | P13: =SUM(D13:O13) -> 0
A14: Volume Billed Commercial/Industrial | C14: m3 | D14: 18 | E14: 8 | F14: 8 | P14: =SUM(D14:O14) -> 34
A15: Total Volume Billed Post Paid | C15: m3 | D15: =SUM(D11:D14) -> 2815 | E15: =SUM(E11:E14) -> 2677 | F15: =SUM(F11:F14) -> 3174 | G15: =SUM(G11:G14) -> 0 | H15: =SUM(H11:H14) -> 0 | I15: =SUM(I11:I14) -> 0 | J15: =SUM(J11:J14) -> 0 | K15: =SUM(K11:K14) -> 0 | ... P15: =SUM(P11:P14) -> 8666
A16: REVENUE WATER - PREPAID
A17: Individuals | C17: m3 | D17: 3079 | E17: 3325 | F17: 3028 | P17: =SUM(D17:O17) -> 9432
A18: CWPs | C18: m3 | D18: 26 | E18: 25 | F18: 9 | P18: =SUM(D18:O18) -> 60
A19: Institutions | C19: m3 | D19: 91 | E19: 116 | F19: 78 | P19: =SUM(D19:O19) -> 285
A20: Commercial/Industrial | C20: m3 | D20: 177 | E20: 283 | F20: 63 | P20: =SUM(D20:O20) -> 523
A21: Total Volume Prepaid | C21: m3 | D21: =SUM(D17:D20) -> 3373 | E21: =SUM(E17:E20) -> 3749 | F21: =SUM(F17:F20) -> 3178 | G21: =SUM(G17:G20) -> 0 | H21: =SUM(H17:H20) -> 0 | I21: =SUM(I17:I20) -> 0 | J21: =SUM(J17:J20) -> 0 | K21: =SUM(K17:K20) -> 0 | ... P21: =SUM(P17:P20) -> 10300
A22: TOTAL REVENUE WATER | C22: m3 | D22: =D21+D15 -> 6188 | E22: =E21+E15 -> 6426 | F22: =F21+F15 -> 6352 | G22: =G21+G15 -> 0 | H22: =H21+H15 -> 0 | I22: =I21+I15 -> 0 | J22: =J21+J15 -> 0 | K22: =K21+K15 -> 0 | ... P22: =P21+P15 -> 18966
A24: Non-Revenue Water (NRW) | B24: Volume | C24: m3 | D24: =D9-D22 -> 4885 | E24: =E9-E22 -> 2796 | F24: =F9-F22 -> 2431 | G24: =G9-G22 -> 0 | H24: =H9-H22 -> 0 | I24: =I9-I22 -> 0 | J24: =J9-J22 -> 0 | K24: =K9-K22 -> 0 | ... P24: =P9-P22 -> 10112
B25: Percentage | C25: % | D25: =D24/D9 -> 0.44116319 | E25: =E24/E9 -> 0.30318803 | F25: =F24/F9 -> 0.2767847 | G25: =G24/G9 -> #DIV/0! | H25: =H24/H9 -> #DIV/0! | I25: =I24/I9 -> #DIV/0! | J25: =J24/J9 -> #DIV/0! | K25: =K24/K9 -> #DIV/0! | ... P25: =P24/P9 -> 0.34775432
A26: OPERATING EXPENSES
A27: Chemicals
A28: Chemical | B28: Rate(MK/kg)
A29: Chlorine | B29: 5111.67 | C29: kg | D29: 15 | E29: 15 | F29: 15 | P29: =SUM(D29:O29) -> 45
C30: kg/mg litre | D30: =D29/(D9/1000) -> 1.3546464 | E30: =E29/(E9/1000) -> 1.6265452 | F30: =F29/(F9/1000) -> 1.7078447 | G30: =G29/(G9/1000) -> #DIV/0! | H30: =H29/(H9/1000) -> #DIV/0! | I30: =I29/(I9/1000) -> #DIV/0! | J30: =J29/(J9/1000) -> #DIV/0! | K30: =K29/(K9/1000) -> #DIV/0! | ... N30: =N29/(N9/1000) -> #DIV/0! | P30: =P29/(P9/1000) -> 1.5475617
A31: Aluminium sulphate | B31: 1537 | C31: kg | P31: =SUM(D31:O31) -> 0
C32: kg/mg litre | D32: =D31/(D9/1000) -> 0 | E32: =E31/(E9/1000) -> 0 | F32: =F31/(F9/1000) -> 0 | G32: =G31/(G9/1000) -> #DIV/0! | H32: =H31/(H9/1000) -> #DIV/0! | I32: =I31/(I9/1000) -> #DIV/0! | J32: =J31/(J9/1000) -> #DIV/0! | K32: =K31/(K9/1000) -> #DIV/0! | ... N32: =N31/(N9/1000) -> #DIV/0! | P32: =P31/(P9/1000) -> 0
A33: Soda | B33: 1781.02 | C33: kg | P33: =SUM(D33:O33) -> 0
C34: kg/mg litre | D34: =D33/(D9/1000) -> 0 | E34: =E33/(E9/1000) -> 0 | F34: =F33/(F9/1000) -> 0 | G34: =G33/(G9/1000) -> #DIV/0! | H34: =H33/(H9/1000) -> #DIV/0! | I34: =I33/(I9/1000) -> #DIV/0! | J34: =J33/(J9/1000) -> #DIV/0! | K34: =K33/(K9/1000) -> #DIV/0! | ... N34: =N33/(N9/1000) -> #DIV/0! | P34: =P33/(P9/1000) -> 0
A35: Algae floc | B35: 5979.95 | C35: litres
C36: litres/mg litre
A37: Sud floc | B37: 5403.75 | C37: litres | P37: =SUM(D37:O37) -> 0
C38: litres/mg litre | D38: =D37/(D9/1000) -> 0 | E38: =E37/(E9/1000) -> 0 | F38: =F37/(F9/1000) -> 0 | G38: =G37/(G9/1000) -> #DIV/0! | H38: =H37/(H9/1000) -> #DIV/0! | I38: =I37/(I9/1000) -> #DIV/0! | J38: =J37/(J9/1000) -> #DIV/0! | K38: =K37/(K9/1000) -> #DIV/0! | ... N38: =N37/(N9/1000) -> #DIV/0! | P38: =P37/(P9/1000) -> 0
A39: Potasium permanganate | B39: 1950 | C39: kg | P39: =SUM(D39:O39) -> 0
C40: kg/mg litre | D40: =D39/(D9/1000) -> 0 | E40: =E39/(E9/1000) -> 0 | F40: =F39/(F9/1000) -> 0 | G40: =G39/(G9/1000) -> #DIV/0! | H40: =H39/(H9/1000) -> #DIV/0! | I40: =I39/(I9/1000) -> #DIV/0! | J40: =J39/(J9/1000) -> #DIV/0! | K40: =K39/(K9/1000) -> #DIV/0! | ... N40: =N39/(N9/1000) -> #DIV/0! | P40: =P39/(P9/1000) -> 0
A41: Cost of Chemicals | C41: Mk | D41: =(D29*$B29)+(D31*$B31)+(D33*$B33)+(D35*$B35)+(D37*$B37)+(D39*$B39) -> 76675.05 | E41: =(E29*$B29)+(E31*$B31)+(E33*$B33)+(E35*$B35)+(E37*$B37)+(E39*$B39) -> 76675.05 | F41: =(F29*$B29)+(F31*$B31)+(F33*$B33)+(F35*$B35)+(F37*$B37)+(F39*$B39) -> 76675.05 | G41: =(G29*$B29)+(G31*$B31)+(G33*$B33)+(G35*$B35)+(G37*$B37)+(G39*$B39) -> 0 | H41: =(H29*$B29)+(H31*$B31)+(H33*$B33)+(H35*$B35)+(H37*$B37)+(H39*$B39) -> 0 | I41: =(I29*$B29)+(I31*$B31)+(I33*$B33)+(I35*$B35)+(I37*$B37)+(I39*$B39) -> 0 | J41: =(J29*$B29)+(J31*$B31)+(J33*$B33)+(J35*$B35)+(J37*$B37)+(J39*$B39) -> 0 | K41: =(K29*$B29)+(K31*$B31)+(K33*$B33)+(K35*$B35)+(K37*$B37)+(K39*$B39) -> 0 | ... N41: =(N29*$B29)+(N31*$B31)+(N33*$B33)+(N35*$B35)+(N37*$B37)+(N39*$B39) -> 0 | P41: =SUM(D41:O41) -> 230025.15
A42: Cost/vol. Produced (chemicals) | C42: Mk/m3 | D42: =D41/D9 -> 6.9245056 | E42: =E41/E9 -> 8.3143624 | F42: =F41/F9 -> 8.7299385 | G42: =G41/G9 -> #DIV/0! | H42: =H41/H9 -> #DIV/0! | I42: =I41/I9 -> #DIV/0! | J42: =J41/J9 -> #DIV/0! | K42: =K41/K9 -> #DIV/0! | ... P42: =P41/P9 -> 7.9106249
A43: Power
...

Sheet MUST
A1: SOUTHERN REGION WATER BOARD
A3: MONTHLY REPORTS - 2026/2027
A4: MULANJE ZONE
A5: MULANJE ZONE
A7: PARAMETERS | C7: UNITS | D7: APRIL | E7: MAY | F7: JUNE | G7: JULY | H7: AUGUST | I7: SEPTEMBER | J7: OCTOBER | K7: NOVEMBER | L7: DECEMBER | M7: JANUARY | N7: FEBRUARY | O7: MARCH | P7: TOTALS
A8: PRODUCTION
A9: Volume Produced | C9: m3 | D9: 18871 | E9: 23837 | F9: 17677 | P9: =SUM(D9:O9) -> 60385
A10: REVENUE WATER - POSTPAID
A11: Volume Billed Individuals | C11: m3 | D11: 770 | E11: 748 | F11: 933 | P11: =SUM(D11:O11) -> 2451
A12: Volume Billed CWPs | C12: m3 | P12: =SUM(D12:O12) -> 0
A13: Volume Billed Institutions | C13: m3 | E13: 14 | F13: 58 | P13: =SUM(D13:O13) -> 72
A14: Volume Billed Commercial/Industrial | C14: m3 | P14: =SUM(D14:O14) -> 0
A15: Total Volume Billed Post Paid | C15: m3 | D15: =SUM(D11:D14) -> 770 | E15: =SUM(E11:E14) -> 762 | F15: =SUM(F11:F14) -> 991 | G15: =SUM(G11:G14) -> 0 | H15: =SUM(H11:H14) -> 0 | I15: =SUM(I11:I14) -> 0 | J15: =SUM(J11:J14) -> 0 | K15: =SUM(K11:K14) -> 0 | ... P15: =SUM(P11:P14) -> 2523
A16: REVENUE WATER - PREPAID
A17: Individuals | C17: m3 | D17: 2282 | E17: 2841 | F17: 1408 | P17: =SUM(D17:O17) -> 6531
A18: CWPs | C18: m3 | P18: =SUM(D18:O18) -> 0
A19: Institutions | C19: m3 | D19: 11520 | E19: 13810 | F19: 10798 | P19: =SUM(D19:O19) -> 36128
A20: Commercial/Industrial | C20: m3 | D20: 854 | E20: 1621 | F20: 113 | P20: =SUM(D20:O20) -> 2588
A21: Total Volume Prepaid | C21: m3 | D21: =SUM(D17:D20) -> 14656 | E21: =SUM(E17:E20) -> 18272 | F21: =SUM(F17:F20) -> 12319 | G21: =SUM(G17:G20) -> 0 | H21: =SUM(H17:H20) -> 0 | I21: =SUM(I17:I20) -> 0 | J21: =SUM(J17:J20) -> 0 | K21: =SUM(K17:K20) -> 0 | ... P21: =SUM(P17:P20) -> 45247
A22: TOTAL REVENUE WATER | C22: m3 | D22: =D21+D15 -> 15426 | E22: =E21+E15 -> 19034 | F22: =F21+F15 -> 13310 | G22: =G21+G15 -> 0 | H22: =H21+H15 -> 0 | I22: =I21+I15 -> 0 | J22: =J21+J15 -> 0 | K22: =K21+K15 -> 0 | ... P22: =P21+P15 -> 47770
A24: Non-Revenue Water (NRW) | B24: Volume | C24: m3 | D24: =D9-D22 -> 3445 | E24: =E9-E22 -> 4803 | F24: =F9-F22 -> 4367 | G24: =G9-G22 -> 0 | H24: =H9-H22 -> 0 | I24: =I9-I22 -> 0 | J24: =J9-J22 -> 0 | K24: =K9-K22 -> 0 | ... P24: =P9-P22 -> 12615
B25: Percentage | C25: % | D25: =D24/D9 -> 0.18255524 | E25: =E24/E9 -> 0.20149348 | F25: =F24/F9 -> 0.24704418 | G25: =G24/G9 -> #DIV/0! | H25: =H24/H9 -> #DIV/0! | I25: =I24/I9 -> #DIV/0! | J25: =J24/J9 -> #DIV/0! | K25: =K24/K9 -> #DIV/0! | ... P25: =P24/P9 -> 0.2089095
A26: OPERATING EXPENSES
A27: Chemicals
A28: Chemical | B28: Rate(MK/kg)
A29: Chlorine | B29: 5111.67 | C29: kg | D29: 19 | E29: 22 | F29: 15 | P29: =SUM(D29:O29) -> 56
C30: kg/mg litre | D30: =D29/(D9/1000) -> 1.0068359 | E30: =E29/(E9/1000) -> 0.92293493 | F30: =F29/(F9/1000) -> 0.84856028 | G30: =G29/(G9/1000) -> #DIV/0! | H30: =H29/(H9/1000) -> #DIV/0! | I30: =I29/(I9/1000) -> #DIV/0! | J30: =J29/(J9/1000) -> #DIV/0! | K30: =K29/(K9/1000) -> #DIV/0! | ... N30: =N29/(N9/1000) -> #DIV/0! | P30: =P29/(P9/1000) -> 0.92738263
A31: Aluminium sulphate | B31: 1537 | C31: kg | P31: =SUM(D31:O31) -> 0
C32: kg/mg litre | D32: =D31/(D9/1000) -> 0 | E32: =E31/(E9/1000) -> 0 | F32: =F31/(F9/1000) -> 0 | G32: =G31/(G9/1000) -> #DIV/0! | H32: =H31/(H9/1000) -> #DIV/0! | I32: =I31/(I9/1000) -> #DIV/0! | J32: =J31/(J9/1000) -> #DIV/0! | K32: =K31/(K9/1000) -> #DIV/0! | ... N32: =N31/(N9/1000) -> #DIV/0! | P32: =P31/(P9/1000) -> 0
A33: Soda | B33: 1781.02 | C33: kg | P33: =SUM(D33:O33) -> 0
C34: kg/mg litre | D34: =D33/(D9/1000) -> 0 | E34: =E33/(E9/1000) -> 0 | F34: =F33/(F9/1000) -> 0 | G34: =G33/(G9/1000) -> #DIV/0! | H34: =H33/(H9/1000) -> #DIV/0! | I34: =I33/(I9/1000) -> #DIV/0! | J34: =J33/(J9/1000) -> #DIV/0! | K34: =K33/(K9/1000) -> #DIV/0! | ... N34: =N33/(N9/1000) -> #DIV/0! | P34: =P33/(P9/1000) -> 0
A35: Algae floc | B35: 5979.95 | C35: litres
C36: litres/mg litre
A37: Sud floc | B37: 5403.75 | C37: litres | P37: =SUM(D37:O37) -> 0
C38: litres/mg litre | D38: =D37/(D9/1000) -> 0 | E38: =E37/(E9/1000) -> 0 | F38: =F37/(F9/1000) -> 0 | G38: =G37/(G9/1000) -> #DIV/0! | H38: =H37/(H9/1000) -> #DIV/0! | I38: =I37/(I9/1000) -> #DIV/0! | J38: =J37/(J9/1000) -> #DIV/0! | K38: =K37/(K9/1000) -> #DIV/0! | ... N38: =N37/(N9/1000) -> #DIV/0! | P38: =P37/(P9/1000) -> 0
A39: Potasium permanganate | B39: 1950 | C39: kg | P39: =SUM(D39:O39) -> 0
C40: kg/mg litre | D40: =D39/(D9/1000) -> 0 | E40: =E39/(E9/1000) -> 0 | F40: =F39/(F9/1000) -> 0 | G40: =G39/(G9/1000) -> #DIV/0! | H40: =H39/(H9/1000) -> #DIV/0! | I40: =I39/(I9/1000) -> #DIV/0! | J40: =J39/(J9/1000) -> #DIV/0! | K40: =K39/(K9/1000) -> #DIV/0! | ... N40: =N39/(N9/1000) -> #DIV/0! | P40: =P39/(P9/1000) -> 0
A41: Cost of Chemicals | C41: Mk | D41: =(D29*$B29)+(D31*$B31)+(D33*$B33)+(D35*$B35)+(D37*$B37)+(D39*$B39) -> 97121.73 | E41: =(E29*$B29)+(E31*$B31)+(E33*$B33)+(E35*$B35)+(E37*$B37)+(E39*$B39) -> 112456.74 | F41: =(F29*$B29)+(F31*$B31)+(F33*$B33)+(F35*$B35)+(F37*$B37)+(F39*$B39) -> 76675.05 | G41: =(G29*$B29)+(G31*$B31)+(G33*$B33)+(G35*$B35)+(G37*$B37)+(G39*$B39) -> 0 | H41: =(H29*$B29)+(H31*$B31)+(H33*$B33)+(H35*$B35)+(H37*$B37)+(H39*$B39) -> 0 | I41: =(I29*$B29)+(I31*$B31)+(I33*$B33)+(I35*$B35)+(I37*$B37)+(I39*$B39) -> 0 | J41: =(J29*$B29)+(J31*$B31)+(J33*$B33)+(J35*$B35)+(J37*$B37)+(J39*$B39) -> 0 | K41: =(K29*$B29)+(K31*$B31)+(K33*$B33)+(K35*$B35)+(K37*$B37)+(K39*$B39) -> 0 | ... O41: =(O29*$B29)+(O31*$B31)+(O33*$B33)+(O35*$B35)+(O37*$B37)+(O39*$B39) -> 0 | P41: =SUM(D41:O41) -> 286253.52
A42: Cost/vol. Produced (chemicals) | C42: Mk/m3 | D42: =D41/D9 -> 5.1466128 | E42: =E41/E9 -> 4.7177388 | F42: =F41/F9 -> 4.3375601 | G42: =G41/G9 -> #DIV/0! | H42: =H41/H9 -> #DIV/0! | I42: =I41/I9 -> #DIV/0! | J42: =J41/J9 -> #DIV/0! | K42: =K41/K9 -> #DIV/0! | ... P42: =P41/P9 -> 4.740474
A43: Power
...

Sheet Phalombe
A1: SOUTHERN REGION WATER BOARD
A3: MONTHLY REPORTS - 2026/2027
A4: MULANJE ZONE
A5: MULANJE ZONE
A7: PARAMETERS | C7: UNITS | D7: APRIL | E7: MAY | F7: JUNE | G7: JULY | H7: AUGUST | I7: SEPTEMBER | J7: OCTOBER | K7: NOVEMBER | L7: DECEMBER | M7: JANUARY | N7: FEBRUARY | O7: MARCH | P7: TOTALS
A8: PRODUCTION
A9: Volume Produced | C9: m3 | D9: 8721 | E9: 8182 | F9: 9627 | P9: =SUM(D9:O9) -> 26530
A10: REVENUE WATER - POSTPAID
A11: Volume Billed Individuals | C11: m3 | D11: 2418 | E11: 2324 | F11: 2959 | P11: =SUM(D11:O11) -> 7701
A12: Volume Billed CWPs | C12: m3 | P12: =SUM(D12:O12) -> 0
A13: Volume Billed Institutions | C13: m3 | P13: =SUM(D13:O13) -> 0
A14: Volume Billed Commercial/Industrial | C14: m3 | D14: 4 | E14: 5 | F14: 4 | P14: =SUM(D14:O14) -> 13
A15: Total Volume Billed Post Paid | C15: m3 | D15: =SUM(D11:D14) -> 2422 | E15: =SUM(E11:E14) -> 2329 | F15: =SUM(F11:F14) -> 2963 | G15: =SUM(G11:G14) -> 0 | H15: =SUM(H11:H14) -> 0 | I15: =SUM(I11:I14) -> 0 | J15: =SUM(J11:J14) -> 0 | K15: =SUM(K11:K14) -> 0 | ... P15: =SUM(P11:P14) -> 7714
A16: REVENUE WATER - PREPAID
A17: Individuals | C17: m3 | D17: 3726.5 | E17: 3179 | F17: 2942 | P17: =SUM(D17:O17) -> 9847.5
A18: CWPs | C18: m3 | D18: 40.4 | E18: 50 | F18: 50 | P18: =SUM(D18:O18) -> 140.4
A19: Institutions | C19: m3 | D19: 157.6 | E19: 66 | F19: 744.3 | P19: =SUM(D19:O19) -> 967.9
A20: Commercial/Industrial | C20: m3 | D20: 111 | E20: 77 | F20: 159.9 | P20: =SUM(D20:O20) -> 347.9
A21: Total Volume Prepaid | C21: m3 | D21: =SUM(D17:D20) -> 4035.5 | E21: =SUM(E17:E20) -> 3372 | F21: =SUM(F17:F20) -> 3896.2 | G21: =SUM(G17:G20) -> 0 | H21: =SUM(H17:H20) -> 0 | I21: =SUM(I17:I20) -> 0 | J21: =SUM(J17:J20) -> 0 | K21: =SUM(K17:K20) -> 0 | ... P21: =SUM(P17:P20) -> 11303.7
A22: TOTAL REVENUE WATER | C22: m3 | D22: =D21+D15 -> 6457.5 | E22: =E21+E15 -> 5701 | F22: =F21+F15 -> 6859.2 | G22: =G21+G15 -> 0 | H22: =H21+H15 -> 0 | I22: =I21+I15 -> 0 | J22: =J21+J15 -> 0 | K22: =K21+K15 -> 0 | ... P22: =P21+P15 -> 19017.7
A24: Non-Revenue Water (NRW) | B24: Volume | C24: m3 | D24: =D9-D22 -> 2263.5 | E24: =E9-E22 -> 2481 | F24: =F9-F22 -> 2767.8 | G24: =G9-G22 -> 0 | H24: =H9-H22 -> 0 | I24: =I9-I22 -> 0 | J24: =J9-J22 -> 0 | K24: =K9-K22 -> 0 | ... P24: =P9-P22 -> 7512.3
B25: Percentage | C25: % | D25: =D24/D9 -> 0.25954592 | E25: =E24/E9 -> 0.30322659 | F25: =F24/F9 -> 0.2875039 | G25: =G24/G9 -> #DIV/0! | H25: =H24/H9 -> #DIV/0! | I25: =I24/I9 -> #DIV/0! | J25: =J24/J9 -> #DIV/0! | K25: =K24/K9 -> #DIV/0! | ... P25: =P24/P9 -> 0.28316246
A26: OPERATING EXPENSES
A27: Chemicals
A28: Chemical | B28: Rate(MK/kg)
A29: Chlorine | B29: 5111.67 | C29: kg | D29: 24 | E29: 24 | F29: 24 | P29: =SUM(D29:O29) -> 72
C30: kg/mg litre | D30: =D29/(D9/1000) -> 2.751978 | E30: =E29/(E9/1000) -> 2.9332681 | F30: =F29/(F9/1000) -> 2.4929885 | G30: =G29/(G9/1000) -> #DIV/0! | H30: =H29/(H9/1000) -> #DIV/0! | I30: =I29/(I9/1000) -> #DIV/0! | J30: =J29/(J9/1000) -> #DIV/0! | K30: =K29/(K9/1000) -> #DIV/0! | ... N30: =N29/(N9/1000) -> #DIV/0! | P30: =P29/(P9/1000) -> 2.7139088
A31: Aluminium sulphate | B31: 1537 | C31: kg | P31: =SUM(D31:O31) -> 0
C32: kg/mg litre | D32: =D31/(D9/1000) -> 0 | E32: =E31/(E9/1000) -> 0 | F32: =F31/(F9/1000) -> 0 | G32: =G31/(G9/1000) -> #DIV/0! | H32: =H31/(H9/1000) -> #DIV/0! | I32: =I31/(I9/1000) -> #DIV/0! | J32: =J31/(J9/1000) -> #DIV/0! | K32: =K31/(K9/1000) -> #DIV/0! | ... N32: =N31/(N9/1000) -> #DIV/0! | P32: =P31/(P9/1000) -> 0
A33: Soda | B33: 1781.02 | C33: kg | P33: =SUM(D33:O33) -> 0
C34: kg/mg litre | D34: =D33/(D9/1000) -> 0 | E34: =E33/(E9/1000) -> 0 | F34: =F33/(F9/1000) -> 0 | G34: =G33/(G9/1000) -> #DIV/0! | H34: =H33/(H9/1000) -> #DIV/0! | I34: =I33/(I9/1000) -> #DIV/0! | J34: =J33/(J9/1000) -> #DIV/0! | K34: =K33/(K9/1000) -> #DIV/0! | ... N34: =N33/(N9/1000) -> #DIV/0! | P34: =P33/(P9/1000) -> 0
A35: Algae floc | B35: 5979.95 | C35: litres
C36: litres/mg litre
A37: Sud floc | B37: 5403.75 | C37: litres | P37: =SUM(D37:O37) -> 0
C38: litres/mg litre | D38: =D37/(D9/1000) -> 0 | E38: =E37/(E9/1000) -> 0 | F38: =F37/(F9/1000) -> 0 | G38: =G37/(G9/1000) -> #DIV/0! | H38: =H37/(H9/1000) -> #DIV/0! | I38: =I37/(I9/1000) -> #DIV/0! | J38: =J37/(J9/1000) -> #DIV/0! | K38: =K37/(K9/1000) -> #DIV/0! | ... N38: =N37/(N9/1000) -> #DIV/0! | P38: =P37/(P9/1000) -> 0
A39: Potasium permanganate | B39: 1950 | C39: kg | P39: =SUM(D39:O39) -> 0
C40: kg/mg litre | D40: =D39/(D9/1000) -> 0 | E40: =E39/(E9/1000) -> 0 | F40: =F39/(F9/1000) -> 0 | G40: =G39/(G9/1000) -> #DIV/0! | H40: =H39/(H9/1000) -> #DIV/0! | I40: =I39/(I9/1000) -> #DIV/0! | J40: =J39/(J9/1000) -> #DIV/0! | K40: =K39/(K9/1000) -> #DIV/0! | ... N40: =N39/(N9/1000) -> #DIV/0! | P40: =P39/(P9/1000) -> 0
A41: Cost of Chemicals | C41: Mk | D41: =(D29*$B29)+(D31*$B31)+(D33*$B33)+(D35*$B35)+(D37*$B37)+(D39*$B39) -> 122680.08 | E41: =(E29*$B29)+(E31*$B31)+(E33*$B33)+(E35*$B35)+(E37*$B37)+(E39*$B39) -> 122680.08 | F41: =(F29*$B29)+(F31*$B31)+(F33*$B33)+(F35*$B35)+(F37*$B37)+(F39*$B39) -> 122680.08 | G41: =(G29*$B29)+(G31*$B31)+(G33*$B33)+(G35*$B35)+(G37*$B37)+(G39*$B39) -> 0 | H41: =(H29*$B29)+(H31*$B31)+(H33*$B33)+(H35*$B35)+(H37*$B37)+(H39*$B39) -> 0 | I41: =(I29*$B29)+(I31*$B31)+(I33*$B33)+(I35*$B35)+(I37*$B37)+(I39*$B39) -> 0 | J41: =(J29*$B29)+(J31*$B31)+(J33*$B33)+(J35*$B35)+(J37*$B37)+(J39*$B39) -> 0 | K41: =(K29*$B29)+(K31*$B31)+(K33*$B33)+(K35*$B35)+(K37*$B37)+(K39*$B39) -> 0 | ... O41: =(O29*$B29)+(O31*$B31)+(O33*$B33)+(O35*$B35)+(O37*$B37)+(O39*$B39) -> 0 | P41: =SUM(D41:O41) -> 368040.24
A42: Cost/vol. Produced (chemicals) | C42: Mk/m3 | D42: =D41/D9 -> 14.067203 | E42: =E41/E9 -> 14.993899 | F42: =F41/F9 -> 12.743334 | G42: =G41/G9 -> #DIV/0! | H42: =H41/H9 -> #DIV/0! | I42: =I41/I9 -> #DIV/0! | J42: =J41/J9 -> #DIV/0! | K42: =K41/K9 -> #DIV/0! | ... P42: =P41/P9 -> 13.872606
A43: Power
...

Sheet Mikolongwe
A1: SOUTHERN REGION WATER BOARD
A3: MONTHLY REPORTS - 2026/2027
A4: MULANJE ZONE
A5: MULANJE ZONE
A7: PARAMETERS | C7: UNITS | D7: APRIL | E7: MAY | F7: JUNE | G7: JULY | H7: AUGUST | I7: SEPTEMBER | J7: OCTOBER | K7: NOVEMBER | L7: DECEMBER | M7: JANUARY | N7: FEBRUARY | O7: MARCH | P7: TOTALS
A8: PRODUCTION
A9: Volume Produced | C9: m3 | D9: 802 | E9: 981 | F9: 607 | P9: =SUM(D9:O9) -> 2390
A10: REVENUE WATER - POSTPAID
A11: Volume Billed Individuals | C11: m3 | P11: =SUM(D11:O11) -> 0
A12: Volume Billed CWPs | C12: m3 | P12: =SUM(D12:O12) -> 0
A13: Volume Billed Institutions | C13: m3 | P13: =SUM(D13:O13) -> 0
A14: Volume Billed Commercial/Industrial | C14: m3 | P14: =SUM(D14:O14) -> 0
A15: Total Volume Billed Post Paid | C15: m3 | D15: =SUM(D11:D14) -> 0 | E15: =SUM(E11:E14) -> 0 | F15: =SUM(F11:F14) -> 0 | G15: =SUM(G11:G14) -> 0 | H15: =SUM(H11:H14) -> 0 | I15: =SUM(I11:I14) -> 0 | J15: =SUM(J11:J14) -> 0 | K15: =SUM(K11:K14) -> 0 | ... P15: =SUM(P11:P14) -> 0
A16: REVENUE WATER - PREPAID
A17: Individuals | C17: m3 | D17: 271 | E17: 212 | F17: 201 | P17: =SUM(D17:O17) -> 684
A18: CWPs | C18: m3 | P18: =SUM(D18:O18) -> 0
A19: Institutions | C19: m3 | D19: 401 | E19: 577 | F19: 274 | P19: =SUM(D19:O19) -> 1252
A20: Commercial/Industrial | C20: m3 | D20: 5 | E20: 10 | P20: =SUM(D20:O20) -> 15
A21: Total Volume Prepaid | C21: m3 | D21: =SUM(D17:D20) -> 677 | E21: =SUM(E17:E20) -> 799 | F21: =SUM(F17:F20) -> 475 | G21: =SUM(G17:G20) -> 0 | H21: =SUM(H17:H20) -> 0 | I21: =SUM(I17:I20) -> 0 | J21: =SUM(J17:J20) -> 0 | K21: =SUM(K17:K20) -> 0 | ... P21: =SUM(P17:P20) -> 1951
A22: TOTAL REVENUE WATER | C22: m3 | D22: =D21+D15 -> 677 | E22: =E21+E15 -> 799 | F22: =F21+F15 -> 475 | G22: =G21+G15 -> 0 | H22: =H21+H15 -> 0 | I22: =I21+I15 -> 0 | J22: =J21+J15 -> 0 | K22: =K21+K15 -> 0 | ... P22: =P21+P15 -> 1951
A24: Non-Revenue Water (NRW) | B24: Volume | C24: m3 | D24: =D9-D22 -> 125 | E24: =E9-E22 -> 182 | F24: =F9-F22 -> 132 | G24: =G9-G22 -> 0 | H24: =H9-H22 -> 0 | I24: =I9-I22 -> 0 | J24: =J9-J22 -> 0 | K24: =K9-K22 -> 0 | ... P24: =P9-P22 -> 439
B25: Percentage | C25: % | D25: =D24/D9 -> 0.15586035 | E25: =E24/E9 -> 0.18552497 | F25: =F24/F9 -> 0.21746293 | G25: =G24/G9 -> #DIV/0! | H25: =H24/H9 -> #DIV/0! | I25: =I24/I9 -> #DIV/0! | J25: =J24/J9 -> #DIV/0! | K25: =K24/K9 -> #DIV/0! | ... P25: =P24/P9 -> 0.18368201
A26: OPERATING EXPENSES
A27: Chemicals
A28: Chemical | B28: Rate(MK/kg)
A29: Chlorine | B29: 5111.67 | C29: kg | D29: 5 | E29: 5 | F29: 4 | P29: =SUM(D29:O29) -> 14
C30: kg/mg litre | D30: =D29/(D9/1000) -> 6.234414 | E30: =E29/(E9/1000) -> 5.09684 | F30: =F29/(F9/1000) -> 6.5897858 | G30: =G29/(G9/1000) -> #DIV/0! | H30: =H29/(H9/1000) -> #DIV/0! | I30: =I29/(I9/1000) -> #DIV/0! | J30: =J29/(J9/1000) -> #DIV/0! | K30: =K29/(K9/1000) -> #DIV/0! | ... N30: =N29/(N9/1000) -> #DIV/0! | P30: =P29/(P9/1000) -> 5.8577406
A31: Aluminium sulphate | B31: 1537 | C31: kg | P31: =SUM(D31:O31) -> 0
C32: kg/mg litre | D32: =D31/(D9/1000) -> 0 | E32: =E31/(E9/1000) -> 0 | F32: =F31/(F9/1000) -> 0 | G32: =G31/(G9/1000) -> #DIV/0! | H32: =H31/(H9/1000) -> #DIV/0! | I32: =I31/(I9/1000) -> #DIV/0! | J32: =J31/(J9/1000) -> #DIV/0! | K32: =K31/(K9/1000) -> #DIV/0! | ... N32: =N31/(N9/1000) -> #DIV/0! | P32: =P31/(P9/1000) -> 0
A33: Soda | B33: 1781.02 | C33: kg | P33: =SUM(D33:O33) -> 0
C34: kg/mg litre | D34: =D33/(D9/1000) -> 0 | E34: =E33/(E9/1000) -> 0 | F34: =F33/(F9/1000) -> 0 | G34: =G33/(G9/1000) -> #DIV/0! | H34: =H33/(H9/1000) -> #DIV/0! | I34: =I33/(I9/1000) -> #DIV/0! | J34: =J33/(J9/1000) -> #DIV/0! | K34: =K33/(K9/1000) -> #DIV/0! | ... N34: =N33/(N9/1000) -> #DIV/0! | P34: =P33/(P9/1000) -> 0
A35: Algae floc | B35: 5979.95 | C35: litres
C36: litres/mg litre
A37: Sud floc | B37: 5403.75 | C37: litres | P37: =SUM(D37:O37) -> 0
C38: litres/mg litre | D38: =D37/(D9/1000) -> 0 | E38: =E37/(E9/1000) -> 0 | F38: =F37/(F9/1000) -> 0 | G38: =G37/(G9/1000) -> #DIV/0! | H38: =H37/(H9/1000) -> #DIV/0! | I38: =I37/(I9/1000) -> #DIV/0! | J38: =J37/(J9/1000) -> #DIV/0! | K38: =K37/(K9/1000) -> #DIV/0! | ... N38: =N37/(N9/1000) -> #DIV/0! | P38: =P37/(P9/1000) -> 0
A39: Potasium permanganate | B39: 1950 | C39: kg | P39: =SUM(D39:O39) -> 0
C40: kg/mg litre | D40: =D39/(D9/1000) -> 0 | E40: =E39/(E9/1000) -> 0 | F40: =F39/(F9/1000) -> 0 | G40: =G39/(G9/1000) -> #DIV/0! | H40: =H39/(H9/1000) -> #DIV/0! | I40: =I39/(I9/1000) -> #DIV/0! | J40: =J39/(J9/1000) -> #DIV/0! | K40: =K39/(K9/1000) -> #DIV/0! | ... N40: =N39/(N9/1000) -> #DIV/0! | P40: =P39/(P9/1000) -> 0
A41: Cost of Chemicals | C41: Mk | D41: =(D29*$B29)+(D31*$B31)+(D33*$B33)+(D35*$B35)+(D37*$B37)+(D39*$B39) -> 25558.35 | E41: =(E29*$B29)+(E31*$B31)+(E33*$B33)+(E35*$B35)+(E37*$B37)+(E39*$B39) -> 25558.35 | F41: =(F29*$B29)+(F31*$B31)+(F33*$B33)+(F35*$B35)+(F37*$B37)+(F39*$B39) -> 20446.68 | G41: =(G29*$B29)+(G31*$B31)+(G33*$B33)+(G35*$B35)+(G37*$B37)+(G39*$B39) -> 0 | H41: =(H29*$B29)+(H31*$B31)+(H33*$B33)+(H35*$B35)+(H37*$B37)+(H39*$B39) -> 0 | I41: =(I29*$B29)+(I31*$B31)+(I33*$B33)+(I35*$B35)+(I37*$B37)+(I39*$B39) -> 0 | J41: =(J29*$B29)+(J31*$B31)+(J33*$B33)+(J35*$B35)+(J37*$B37)+(J39*$B39) -> 0 | K41: =(K29*$B29)+(K31*$B31)+(K33*$B33)+(K35*$B35)+(K37*$B37)+(K39*$B39) -> 0 | ... O41: =(O29*$B29)+(O31*$B31)+(O33*$B33)+(O35*$B35)+(O37*$B37)+(O39*$B39) -> 0 | P41: =SUM(D41:O41) -> 71563.38
A42: Cost/vol. Produced (chemicals) | C42: Mk/m3 | D42: =D41/D9 -> 31.868267 | E42: =E41/E9 -> 26.053364 | F42: =F41/F9 -> 33.684811 | G42: =G41/G9 -> #DIV/0! | H42: =H41/H9 -> #DIV/0! | I42: =I41/I9 -> #DIV/0! | J42: =J41/J9 -> #DIV/0! | K42: =K41/K9 -> #DIV/0! | ... P42: =P41/P9 -> 29.942837
A43: Power
...

Sheet Migowi
A1: SOUTHERN REGION WATER BOARD
A3: MONTHLY REPORTS - 2026/2027
A4: MULANJE ZONE
A5: MULANJE ZONE
A7: PARAMETERS | C7: UNITS | D7: APRIL | E7: MAY | F7: JUNE | G7: JULY | H7: AUGUST | I7: SEPTEMBER | J7: OCTOBER | K7: NOVEMBER | L7: DECEMBER | M7: JANUARY | N7: FEBRUARY | O7: MARCH | P7: TOTALS
A8: PRODUCTION
A9: Volume Produced | C9: m3 | D9: 1150 | E9: 937 | F9: 889 | P9: =SUM(D9:O9) -> 2976
A10: REVENUE WATER - POSTPAID
A11: Volume Billed Individuals | C11: m3 | P11: =SUM(D11:O11) -> 0
A12: Volume Billed CWPs | C12: m3 | P12: =SUM(D12:O12) -> 0
A13: Volume Billed Institutions | C13: m3 | P13: =SUM(D13:O13) -> 0
A14: Volume Billed Commercial/Industrial | C14: m3 | P14: =SUM(D14:O14) -> 0
A15: Total Volume Billed Post Paid | C15: m3 | D15: =SUM(D11:D14) -> 0 | E15: =SUM(E11:E14) -> 0 | F15: =SUM(F11:F14) -> 0 | G15: =SUM(G11:G14) -> 0 | H15: =SUM(H11:H14) -> 0 | I15: =SUM(I11:I14) -> 0 | J15: =SUM(J11:J14) -> 0 | K15: =SUM(K11:K14) -> 0 | ... P15: =SUM(P11:P14) -> 0
A16: REVENUE WATER - PREPAID
A17: Individuals | C17: m3 | D17: 930 | E17: 801 | F17: 733 | P17: =SUM(D17:O17) -> 2464
A18: CWPs | C18: m3 | P18: =SUM(D18:O18) -> 0
A19: Institutions | C19: m3 | P19: =SUM(D19:O19) -> 0
A20: Commercial/Industrial | C20: m3 | P20: =SUM(D20:O20) -> 0
A21: Total Volume Prepaid | C21: m3 | D21: =SUM(D17:D20) -> 930 | E21: =SUM(E17:E20) -> 801 | F21: =SUM(F17:F20) -> 733 | G21: =SUM(G17:G20) -> 0 | H21: =SUM(H17:H20) -> 0 | I21: =SUM(I17:I20) -> 0 | J21: =SUM(J17:J20) -> 0 | K21: =SUM(K17:K20) -> 0 | ... P21: =SUM(P17:P20) -> 2464
A22: TOTAL REVENUE WATER | C22: m3 | D22: =D21+D15 -> 930 | E22: =E21+E15 -> 801 | F22: =F21+F15 -> 733 | G22: =G21+G15 -> 0 | H22: =H21+H15 -> 0 | I22: =I21+I15 -> 0 | J22: =J21+J15 -> 0 | K22: =K21+K15 -> 0 | ... P22: =P21+P15 -> 2464
A24: Non-Revenue Water (NRW) | B24: Volume | C24: m3 | D24: =D9-D22 -> 220 | E24: =E9-E22 -> 136 | F24: =F9-F22 -> 156 | G24: =G9-G22 -> 0 | H24: =H9-H22 -> 0 | I24: =I9-I22 -> 0 | J24: =J9-J22 -> 0 | K24: =K9-K22 -> 0 | ... P24: =P9-P22 -> 512
B25: Percentage | C25: % | D25: =D24/D9 -> 0.19130435 | E25: =E24/E9 -> 0.14514408 | F25: =F24/F9 -> 0.17547807 | G25: =G24/G9 -> #DIV/0! | H25: =H24/H9 -> #DIV/0! | I25: =I24/I9 -> #DIV/0! | J25: =J24/J9 -> #DIV/0! | K25: =K24/K9 -> #DIV/0! | ... P25: =P24/P9 -> 0.17204301
A26: OPERATING EXPENSES
A27: Chemicals
A28: Chemical | B28: Rate(MK/kg)
A29: Chlorine | B29: 5111.67 | C29: kg | D29: 1 | E29: 1 | F29: 1 | P29: =SUM(D29:O29) -> 3
C30: kg/mg litre | D30: =D29/(D9/1000) -> 0.86956522 | E30: =E29/(E9/1000) -> 1.0672359 | F30: =F29/(F9/1000) -> 1.1248594 | G30: =G29/(G9/1000) -> #DIV/0! | H30: =H29/(H9/1000) -> #DIV/0! | I30: =I29/(I9/1000) -> #DIV/0! | J30: =J29/(J9/1000) -> #DIV/0! | K30: =K29/(K9/1000) -> #DIV/0! | ... N30: =N29/(N9/1000) -> #DIV/0! | P30: =P29/(P9/1000) -> 1.0080645
A31: Aluminium sulphate | B31: 1537 | C31: kg | P31: =SUM(D31:O31) -> 0
C32: kg/mg litre | D32: =D31/(D9/1000) -> 0 | E32: =E31/(E9/1000) -> 0 | F32: =F31/(F9/1000) -> 0 | G32: =G31/(G9/1000) -> #DIV/0! | H32: =H31/(H9/1000) -> #DIV/0! | I32: =I31/(I9/1000) -> #DIV/0! | J32: =J31/(J9/1000) -> #DIV/0! | K32: =K31/(K9/1000) -> #DIV/0! | ... N32: =N31/(N9/1000) -> #DIV/0! | P32: =P31/(P9/1000) -> 0
A33: Soda | B33: 1781.02 | C33: kg | P33: =SUM(D33:O33) -> 0
C34: kg/mg litre | D34: =D33/(D9/1000) -> 0 | E34: =E33/(E9/1000) -> 0 | F34: =F33/(F9/1000) -> 0 | G34: =G33/(G9/1000) -> #DIV/0! | H34: =H33/(H9/1000) -> #DIV/0! | I34: =I33/(I9/1000) -> #DIV/0! | J34: =J33/(J9/1000) -> #DIV/0! | K34: =K33/(K9/1000) -> #DIV/0! | ... N34: =N33/(N9/1000) -> #DIV/0! | P34: =P33/(P9/1000) -> 0
A35: Algae floc | B35: 5979.95 | C35: litres
C36: litres/mg litre
A37: Sud floc | B37: 5403.75 | C37: litres | P37: =SUM(D37:O37) -> 0
C38: litres/mg litre | D38: =D37/(D9/1000) -> 0 | E38: =E37/(E9/1000) -> 0 | F38: =F37/(F9/1000) -> 0 | G38: =G37/(G9/1000) -> #DIV/0! | H38: =H37/(H9/1000) -> #DIV/0! | I38: =I37/(I9/1000) -> #DIV/0! | J38: =J37/(J9/1000) -> #DIV/0! | K38: =K37/(K9/1000) -> #DIV/0! | ... N38: =N37/(N9/1000) -> #DIV/0! | P38: =P37/(P9/1000) -> 0
A39: Potasium permanganate | B39: 1950 | C39: kg | P39: =SUM(D39:O39) -> 0
C40: kg/mg litre | D40: =D39/(D9/1000) -> 0 | E40: =E39/(E9/1000) -> 0 | F40: =F39/(F9/1000) -> 0 | G40: =G39/(G9/1000) -> #DIV/0! | H40: =H39/(H9/1000) -> #DIV/0! | I40: =I39/(I9/1000) -> #DIV/0! | J40: =J39/(J9/1000) -> #DIV/0! | K40: =K39/(K9/1000) -> #DIV/0! | ... N40: =N39/(N9/1000) -> #DIV/0! | P40: =P39/(P9/1000) -> 0
A41: Cost of Chemicals | C41: Mk | D41: =(D29*$B29)+(D31*$B31)+(D33*$B33)+(D35*$B35)+(D37*$B37)+(D39*$B39) -> 5111.67 | E41: =(E29*$B29)+(E31*$B31)+(E33*$B33)+(E35*$B35)+(E37*$B37)+(E39*$B39) -> 5111.67 | F41: =(F29*$B29)+(F31*$B31)+(F33*$B33)+(F35*$B35)+(F37*$B37)+(F39*$B39) -> 5111.67 | G41: =(G29*$B29)+(G31*$B31)+(G33*$B33)+(G35*$B35)+(G37*$B37)+(G39*$B39) -> 0 | H41: =(H29*$B29)+(H31*$B31)+(H33*$B33)+(H35*$B35)+(H37*$B37)+(H39*$B39) -> 0 | I41: =(I29*$B29)+(I31*$B31)+(I33*$B33)+(I35*$B35)+(I37*$B37)+(I39*$B39) -> 0 | J41: =(J29*$B29)+(J31*$B31)+(J33*$B33)+(J35*$B35)+(J37*$B37)+(J39*$B39) -> 0 | K41: =(K29*$B29)+(K31*$B31)+(K33*$B33)+(K35*$B35)+(K37*$B37)+(K39*$B39) -> 0 | ... O41: =(O29*$B29)+(O31*$B31)+(O33*$B33)+(O35*$B35)+(O37*$B37)+(O39*$B39) -> 0 | P41: =SUM(D41:O41) -> 15335.01
A42: Cost/vol. Produced (chemicals) | C42: Mk/m3 | D42: =D41/D9 -> 4.4449304 | E42: =E41/E9 -> 5.4553575 | F42: =F41/F9 -> 5.74991 | G42: =G41/G9 -> #DIV/0! | H42: =H41/H9 -> #DIV/0! | I42: =I41/I9 -> #DIV/0! | J42: =J41/J9 -> #DIV/0! | K42: =K41/K9 -> #DIV/0! | ... P42: =P41/P9 -> 5.1528931
A43: Power
...

Sheet Nkando
A1: SOUTHERN REGION WATER BOARD
A3: MONTHLY REPORTS - 2026/2027
A4: MULANJE ZONE
A5: MULANJE ZONE
A7: PARAMETERS | C7: UNITS | D7: APRIL | E7: MAY | F7: JUNE | G7: JULY | H7: AUGUST | I7: SEPTEMBER | J7: OCTOBER | K7: NOVEMBER | L7: DECEMBER | M7: JANUARY | N7: FEBRUARY | O7: MARCH | P7: TOTALS
A8: PRODUCTION
A9: Volume Produced | C9: m3 | D9: 2150 | E9: 2312 | F9: 2100 | P9: =SUM(D9:O9) -> 6562
A10: REVENUE WATER - POSTPAID
A11: Volume Billed Individuals | C11: m3 | P11: =SUM(D11:O11) -> 0
A12: Volume Billed CWPs | C12: m3 | P12: =SUM(D12:O12) -> 0
A13: Volume Billed Institutions | C13: m3 | P13: =SUM(D13:O13) -> 0
A14: Volume Billed Commercial/Industrial | C14: m3 | P14: =SUM(D14:O14) -> 0
A15: Total Volume Billed Post Paid | C15: m3 | D15: =SUM(D11:D14) -> 0 | F15: =SUM(F11:F14) -> 0 | G15: =SUM(G11:G14) -> 0 | H15: =SUM(H11:H14) -> 0 | I15: =SUM(I11:I14) -> 0 | J15: =SUM(J11:J14) -> 0 | K15: =SUM(K11:K14) -> 0 | L15: =SUM(L11:L14) -> 0 | M15: =SUM(M11:M14) -> 0 | ... P15: =SUM(P11:P14) -> 0
A16: REVENUE WATER - PREPAID
A17: Individuals | C17: m3 | D17: 1566 | E17: 1735.1 | F17: 1566.8 | P17: =SUM(D17:O17) -> 4867.9
A18: CWPs | C18: m3 | D18: 12 | E18: 4 | F18: 4 | P18: =SUM(D18:O18) -> 20
A19: Institutions | C19: m3 | D19: 18 | E19: 22 | F19: 14 | P19: =SUM(D19:O19) -> 54
A20: Commercial/Industrial | C20: m3 | D20: 47 | E20: 39 | F20: 27 | P20: =SUM(D20:O20) -> 113
A21: Total Volume Prepaid | C21: m3 | D21: =SUM(D17:D20) -> 1643 | E21: =SUM(E17:E20) -> 1800.1 | F21: =SUM(F17:F20) -> 1611.8 | G21: =SUM(G17:G20) -> 0 | H21: =SUM(H17:H20) -> 0 | I21: =SUM(I17:I20) -> 0 | J21: =SUM(J17:J20) -> 0 | K21: =SUM(K17:K20) -> 0 | ... P21: =SUM(P17:P20) -> 5054.9
A22: TOTAL REVENUE WATER | C22: m3 | D22: =D21+D15 -> 1643 | E22: =E21+E15 -> 1800.1 | F22: =F21+F15 -> 1611.8 | G22: =G21+G15 -> 0 | H22: =H21+H15 -> 0 | I22: =I21+I15 -> 0 | J22: =J21+J15 -> 0 | K22: =K21+K15 -> 0 | ... P22: =P21+P15 -> 5054.9
A24: Non-Revenue Water (NRW) | B24: Volume | C24: m3 | D24: =D9-D22 -> 507 | E24: =E9-E22 -> 511.9 | F24: =F9-F22 -> 488.2 | G24: =G9-G22 -> 0 | H24: =H9-H22 -> 0 | I24: =I9-I22 -> 0 | J24: =J9-J22 -> 0 | K24: =K9-K22 -> 0 | ... P24: =P9-P22 -> 1507.1
B25: Percentage | C25: % | D25: =D24/D9 -> 0.23581395 | E25: =E24/E9 -> 0.22141003 | F25: =F24/F9 -> 0.23247619 | G25: =G24/G9 -> #DIV/0! | H25: =H24/H9 -> #DIV/0! | I25: =I24/I9 -> #DIV/0! | J25: =J24/J9 -> #DIV/0! | K25: =K24/K9 -> #DIV/0! | ... P25: =P24/P9 -> 0.22967083
A26: OPERATING EXPENSES
A27: Chemicals
A28: Chemical | B28: Rate(MK/kg)
A29: Chlorine | B29: 5111.67 | C29: kg | D29: 6 | E29: 6 | F29: 5 | P29: =SUM(D29:O29) -> 17
C30: kg/mg litre | D30: =D29/(D9/1000) -> 2.7906977 | E30: =E29/(E9/1000) -> 2.5951557 | F30: =F29/(F9/1000) -> 2.3809524 | G30: =G29/(G9/1000) -> #DIV/0! | H30: =H29/(H9/1000) -> #DIV/0! | I30: =I29/(I9/1000) -> #DIV/0! | J30: =J29/(J9/1000) -> #DIV/0! | K30: =K29/(K9/1000) -> #DIV/0! | ... N30: =N29/(N9/1000) -> #DIV/0! | P30: =P29/(P9/1000) -> 2.5906736
A31: Aluminium sulphate | B31: 1537 | C31: kg | P31: =SUM(D31:O31) -> 0
C32: kg/mg litre | D32: =D31/(D9/1000) -> 0 | E32: =E31/(E9/1000) -> 0 | F32: =F31/(F9/1000) -> 0 | G32: =G31/(G9/1000) -> #DIV/0! | H32: =H31/(H9/1000) -> #DIV/0! | I32: =I31/(I9/1000) -> #DIV/0! | J32: =J31/(J9/1000) -> #DIV/0! | K32: =K31/(K9/1000) -> #DIV/0! | ... N32: =N31/(N9/1000) -> #DIV/0! | P32: =P31/(P9/1000) -> 0
A33: Soda | B33: 1781.02 | C33: kg | P33: =SUM(D33:O33) -> 0
C34: kg/mg litre | D34: =D33/(D9/1000) -> 0 | E34: =E33/(E9/1000) -> 0 | F34: =F33/(F9/1000) -> 0 | G34: =G33/(G9/1000) -> #DIV/0! | H34: =H33/(H9/1000) -> #DIV/0! | I34: =I33/(I9/1000) -> #DIV/0! | J34: =J33/(J9/1000) -> #DIV/0! | K34: =K33/(K9/1000) -> #DIV/0! | ... N34: =N33/(N9/1000) -> #DIV/0! | P34: =P33/(P9/1000) -> 0
A35: Algae floc | B35: 5979.95 | C35: litres
C36: litres/mg litre
A37: Sud floc | B37: 5403.75 | C37: litres | P37: =SUM(D37:O37) -> 0
C38: litres/mg litre | D38: =D37/(D9/1000) -> 0 | E38: =E37/(E9/1000) -> 0 | F38: =F37/(F9/1000) -> 0 | G38: =G37/(G9/1000) -> #DIV/0! | H38: =H37/(H9/1000) -> #DIV/0! | I38: =I37/(I9/1000) -> #DIV/0! | J38: =J37/(J9/1000) -> #DIV/0! | K38: =K37/(K9/1000) -> #DIV/0! | ... N38: =N37/(N9/1000) -> #DIV/0! | P38: =P37/(P9/1000) -> 0
A39: Potasium permanganate | B39: 1950 | C39: kg | P39: =SUM(D39:O39) -> 0
C40: kg/mg litre | D40: =D39/(D9/1000) -> 0 | E40: =E39/(E9/1000) -> 0 | F40: =F39/(F9/1000) -> 0 | G40: =G39/(G9/1000) -> #DIV/0! | H40: =H39/(H9/1000) -> #DIV/0! | I40: =I39/(I9/1000) -> #DIV/0! | J40: =J39/(J9/1000) -> #DIV/0! | K40: =K39/(K9/1000) -> #DIV/0! | ... N40: =N39/(N9/1000) -> #DIV/0! | P40: =P39/(P9/1000) -> 0
A41: Cost of Chemicals | C41: Mk | D41: =(D29*$B29)+(D31*$B31)+(D33*$B33)+(D35*$B35)+(D37*$B37)+(D39*$B39) -> 30670.02 | E41: =(E29*$B29)+(E31*$B31)+(E33*$B33)+(E35*$B35)+(E37*$B37)+(E39*$B39) -> 30670.02 | F41: =(F29*$B29)+(F31*$B31)+(F33*$B33)+(F35*$B35)+(F37*$B37)+(F39*$B39) -> 25558.35 | G41: =(G29*$B29)+(G31*$B31)+(G33*$B33)+(G35*$B35)+(G37*$B37)+(G39*$B39) -> 0 | H41: =(H29*$B29)+(H31*$B31)+(H33*$B33)+(H35*$B35)+(H37*$B37)+(H39*$B39) -> 0 | I41: =(I29*$B29)+(I31*$B31)+(I33*$B33)+(I35*$B35)+(I37*$B37)+(I39*$B39) -> 0 | J41: =(J29*$B29)+(J31*$B31)+(J33*$B33)+(J35*$B35)+(J37*$B37)+(J39*$B39) -> 0 | K41: =(K29*$B29)+(K31*$B31)+(K33*$B33)+(K35*$B35)+(K37*$B37)+(K39*$B39) -> 0 | ... O41: =(O29*$B29)+(O31*$B31)+(O33*$B33)+(O35*$B35)+(O37*$B37)+(O39*$B39) -> 0 | P41: =SUM(D41:O41) -> 86898.39
A42: Cost/vol. Produced (chemicals) | C42: Mk/m3 | D42: =D41/D9 -> 14.265126 | E42: =E41/E9 -> 13.26558 | F42: =F41/F9 -> 12.170643 | G42: =G41/G9 -> #DIV/0! | H42: =H41/H9 -> #DIV/0! | I42: =I41/I9 -> #DIV/0! | J42: =J41/J9 -> #DIV/0! | K42: =K41/K9 -> #DIV/0! | ... P42: =P41/P9 -> 13.242668
A43: Power
...

Sheet Zone Monthly
A1: SOUTHERN REGION WATER BOARD
A3: MONTHLY REPORTS - 2024/2025
A4: MULANJEZONE
A5: MULANJE ZONE
A7: PARAMETERS | C7: UNITS | D7: APRIL | E7: MAY | F7: JUNE | G7: JULY | H7: AUGUST | I7: SEPTEMBER | J7: OCTOBER | K7: NOVEMBER | L7: DECEMBER | M7: JANUARY | N7: FEBRUARY | O7: MARCH | P7: TOTALS
A8: PRODUCTION
A9: Volume Produced | C9: m3 | D9: =Mulanje!D9+Luchenza!D9+Thyolo!D9+Muloza!D9+MUST!D9+Phalombe!D9+Mikolongwe!D9+Migowi!D9+Nkando!D9 -> 112732 | E9: =Mulanje!E9+Luchenza!E9+Thyolo!E9+Muloza!E9+MUST!E9+Phalombe!E9+Mikolongwe!E9+Migowi!E9+Nkando!E9 -> 123534 | F9: =Mulanje!F9+Luchenza!F9+Thyolo!F9+Muloza!F9+MUST!F9+Phalombe!F9+Mikolongwe!F9+Migowi!F9+Nkando!F9 -> 121652 | G9: =Mulanje!G9+Luchenza!G9+Thyolo!G9+Muloza!G9+MUST!G9+Phalombe!G9+Mikolongwe!G9+Migowi!G9+Nkando!G9 -> 0 | H9: =Mulanje!H9+Luchenza!H9+Thyolo!H9+Muloza!H9+MUST!H9+Phalombe!H9+Mikolongwe!H9+Migowi!H9+Nkando!H9 -> 0 | I9: =Mulanje!I9+Luchenza!I9+Thyolo!I9+Muloza!I9+MUST!I9+Phalombe!I9+Mikolongwe!I9+Migowi!I9+Nkando!I9 -> 0 | J9: =Mulanje!J9+Luchenza!J9+Thyolo!J9+Muloza!J9+MUST!J9+Phalombe!J9+Mikolongwe!J9+Migowi!J9+Nkando!J9 -> 0 | K9: =Mulanje!K9+Luchenza!K9+Thyolo!K9+Muloza!K9+MUST!K9+Phalombe!K9+Mikolongwe!K9+Migowi!K9+Nkando!K9 -> 0 | ... O9: =Mulanje!O9+Luchenza!O9+Thyolo!O9+Muloza!O9+MUST!O9+Phalombe!O9+Mikolongwe!O9+Migowi!O9+Nkando!O9 -> 0 | P9: =SUM(D9:O9) -> 357918
A10: REVENUE WATER - POSTPAID
A11: Volume Billed Individuals | C11: m3 | D11: =Mulanje!D11+Luchenza!D11+Thyolo!D11+Muloza!D11+MUST!D11+Phalombe!D11+Mikolongwe!D11+Migowi!D11+Nkando!D11 -> 29861 | E11: =Mulanje!E11+Luchenza!E11+Thyolo!E11+Muloza!E11+MUST!E11+Phalombe!E11+Mikolongwe!E11+Migowi!E11+Nkando!E11 -> 29996 | F11: =Mulanje!F11+Luchenza!F11+Thyolo!F11+Muloza!F11+MUST!F11+Phalombe!F11+Mikolongwe!F11+Migowi!F11+Nkando!F11 -> 37499 | G11: =Mulanje!G11+Luchenza!G11+Thyolo!G11+Muloza!G11+MUST!G11+Phalombe!G11+Mikolongwe!G11+Migowi!G11+Nkando!G11 -> 0 | H11: =Mulanje!H11+Luchenza!H11+Thyolo!H11+Muloza!H11+MUST!H11+Phalombe!H11+Mikolongwe!H11+Migowi!H11+Nkando!H11 -> 0 | I11: =Mulanje!I11+Luchenza!I11+Thyolo!I11+Muloza!I11+MUST!I11+Phalombe!I11+Mikolongwe!I11+Migowi!I11+Nkando!I11 -> 0 | J11: =Mulanje!J11+Luchenza!J11+Thyolo!J11+Muloza!J11+MUST!J11+Phalombe!J11+Mikolongwe!J11+Migowi!J11+Nkando!J11 -> 0 | K11: =Mulanje!K11+Luchenza!K11+Thyolo!K11+Muloza!K11+MUST!K11+Phalombe!K11+Mikolongwe!K11+Migowi!K11+Nkando!K11 -> 0 | ... O11: =Mulanje!O11+Luchenza!O11+Thyolo!O11+Muloza!O11+MUST!O11+Phalombe!O11+Mikolongwe!O11+Migowi!O11+Nkando!O11 -> 0 | P11: =SUM(D11:O11) -> 97356
A12: Volume Billed CWPs | C12: m3 | D12: =Mulanje!D12+Luchenza!D12+Thyolo!D12+Muloza!D12+MUST!D12+Phalombe!D12+Mikolongwe!D12+Migowi!D12+Nkando!D12 -> 842 | E12: =Mulanje!E12+Luchenza!E12+Thyolo!E12+Muloza!E12+MUST!E12+Phalombe!E12+Mikolongwe!E12+Migowi!E12+Nkando!E12 -> 922 | F12: =Mulanje!F12+Luchenza!F12+Thyolo!F12+Muloza!F12+MUST!F12+Phalombe!F12+Mikolongwe!F12+Migowi!F12+Nkando!F12 -> 1091 | G12: =Mulanje!G12+Luchenza!G12+Thyolo!G12+Muloza!G12+MUST!G12+Phalombe!G12+Mikolongwe!G12+Migowi!G12+Nkando!G12 -> 0 | H12: =Mulanje!H12+Luchenza!H12+Thyolo!H12+Muloza!H12+MUST!H12+Phalombe!H12+Mikolongwe!H12+Migowi!H12+Nkando!H12 -> 0 | I12: =Mulanje!I12+Luchenza!I12+Thyolo!I12+Muloza!I12+MUST!I12+Phalombe!I12+Mikolongwe!I12+Migowi!I12+Nkando!I12 -> 0 | J12: =Mulanje!J12+Luchenza!J12+Thyolo!J12+Muloza!J12+MUST!J12+Phalombe!J12+Mikolongwe!J12+Migowi!J12+Nkando!J12 -> 0 | K12: =Mulanje!K12+Luchenza!K12+Thyolo!K12+Muloza!K12+MUST!K12+Phalombe!K12+Mikolongwe!K12+Migowi!K12+Nkando!K12 -> 0 | ... O12: =Mulanje!O12+Luchenza!O12+Thyolo!O12+Muloza!O12+MUST!O12+Phalombe!O12+Mikolongwe!O12+Migowi!O12+Nkando!O12 -> 0 | P12: =SUM(D12:O12) -> 2855
A13: Volume Billed Institutions | C13: m3 | D13: =Mulanje!D13+Luchenza!D13+Thyolo!D13+Muloza!D13+MUST!D13+Phalombe!D13+Mikolongwe!D13+Migowi!D13+Nkando!D13 -> 125 | E13: =Mulanje!E13+Luchenza!E13+Thyolo!E13+Muloza!E13+MUST!E13+Phalombe!E13+Mikolongwe!E13+Migowi!E13+Nkando!E13 -> 111 | F13: =Mulanje!F13+Luchenza!F13+Thyolo!F13+Muloza!F13+MUST!F13+Phalombe!F13+Mikolongwe!F13+Migowi!F13+Nkando!F13 -> 231 | G13: =Mulanje!G13+Luchenza!G13+Thyolo!G13+Muloza!G13+MUST!G13+Phalombe!G13+Mikolongwe!G13+Migowi!G13+Nkando!G13 -> 0 | H13: =Mulanje!H13+Luchenza!H13+Thyolo!H13+Muloza!H13+MUST!H13+Phalombe!H13+Mikolongwe!H13+Migowi!H13+Nkando!H13 -> 0 | I13: =Mulanje!I13+Luchenza!I13+Thyolo!I13+Muloza!I13+MUST!I13+Phalombe!I13+Mikolongwe!I13+Migowi!I13+Nkando!I13 -> 0 | J13: =Mulanje!J13+Luchenza!J13+Thyolo!J13+Muloza!J13+MUST!J13+Phalombe!J13+Mikolongwe!J13+Migowi!J13+Nkando!J13 -> 0 | K13: =Mulanje!K13+Luchenza!K13+Thyolo!K13+Muloza!K13+MUST!K13+Phalombe!K13+Mikolongwe!K13+Migowi!K13+Nkando!K13 -> 0 | ... O13: =Mulanje!O13+Luchenza!O13+Thyolo!O13+Muloza!O13+MUST!O13+Phalombe!O13+Mikolongwe!O13+Migowi!O13+Nkando!O13 -> 0 | P13: =SUM(D13:O13) -> 467
A14: Volume Billed Commercial/Industrial | C14: m3 | D14: =Mulanje!D14+Luchenza!D14+Thyolo!D14+Muloza!D14+MUST!D14+Phalombe!D14+Mikolongwe!D14+Migowi!D14+Nkando!D14 -> 187 | E14: =Mulanje!E14+Luchenza!E14+Thyolo!E14+Muloza!E14+MUST!E14+Phalombe!E14+Mikolongwe!E14+Migowi!E14+Nkando!E14 -> 316 | F14: =Mulanje!F14+Luchenza!F14+Thyolo!F14+Muloza!F14+MUST!F14+Phalombe!F14+Mikolongwe!F14+Migowi!F14+Nkando!F14 -> 276 | G14: =Mulanje!G14+Luchenza!G14+Thyolo!G14+Muloza!G14+MUST!G14+Phalombe!G14+Mikolongwe!G14+Migowi!G14+Nkando!G14 -> 0 | H14: =Mulanje!H14+Luchenza!H14+Thyolo!H14+Muloza!H14+MUST!H14+Phalombe!H14+Mikolongwe!H14+Migowi!H14+Nkando!H14 -> 0 | I14: =Mulanje!I14+Luchenza!I14+Thyolo!I14+Muloza!I14+MUST!I14+Phalombe!I14+Mikolongwe!I14+Migowi!I14+Nkando!I14 -> 0 | J14: =Mulanje!J14+Luchenza!J14+Thyolo!J14+Muloza!J14+MUST!J14+Phalombe!J14+Mikolongwe!J14+Migowi!J14+Nkando!J14 -> 0 | K14: =Mulanje!K14+Luchenza!K14+Thyolo!K14+Muloza!K14+MUST!K14+Phalombe!K14+Mikolongwe!K14+Migowi!K14+Nkando!K14 -> 0 | ... O14: =Mulanje!O14+Luchenza!O14+Thyolo!O14+Muloza!O14+MUST!O14+Phalombe!O14+Mikolongwe!O14+Migowi!O14+Nkando!O14 -> 0 | P14: =SUM(D14:O14) -> 779
A15: Total Volume Billed Post Paid | C15: m3 | D15: =SUM(D11:D14) -> 31015 | E15: =SUM(E11:E14) -> 31345 | F15: =SUM(F11:F14) -> 39097 | G15: =SUM(G11:G14) -> 0 | H15: =SUM(H11:H14) -> 0 | I15: =SUM(I11:I14) -> 0 | J15: =SUM(J11:J14) -> 0 | K15: =SUM(K11:K14) -> 0 | ... P15: =SUM(P11:P14) -> 101457
A16: REVENUE WATER - PREPAID
