Workbook

Sheet Mangochi
A1: SOUTHERN REGION WATER BOARD
A3: MONTHLY REPORTS - 2025/2026
A4: MANGOCHI ZONE
A5: MANGOCHI ZONE
A7: PARAMETERS | C7: UNITS | D7: APRIL | E7: MAY | F7: JUNE | G7: JULY | H7: AUGUST | I7: SEPTEMBER | J7: OCTOBER | K7: NOVEMBER | L7: DECEMBER | M7: JANUARY | N7: FEBRUARY | O7: MARCH | P7: TOTALS
A8: PRODUCTION
A9: Volume Produced | C9: m3 | D9: 155427 | E9: 150181 | P9: =SUM(D9:O9) -> 305608
A10: REVENUE WATER - POSTPAID
A11: Volume Billed Individuals | C11: m3 | D11: 54507 | E11: 59377 | P11: =SUM(D11:O11) -> 113884
A12: Volume Billed CWPs | C12: m3 | P12: =SUM(D12:O12) -> 0
A13: Volume Billed Institutions | C13: m3 | D13: 105 | E13: 199 | P13: =SUM(D13:O13) -> 304
A14: Volume Billed Commercial/Industrial | C14: m3 | D14: 64 | E14: 79 | P14: =SUM(D14:O14) -> 143
A15: Total Volume Billed Post Paid | C15: m3 | D15: =SUM(D11:D14) -> 54676 | E15: =SUM(E11:E14) -> 59655 | F15: =SUM(F11:F14) -> 0 | G15: =SUM(G11:G14) -> 0 | H15: =SUM(H11:H14) -> 0 | I15: =SUM(I11:I14) -> 0 | J15: =SUM(J11:J14) -> 0 | K15: =SUM(K11:K14) -> 0 | ... P15: =SUM(P11:P14) -> 114331
A16: REVENUE WATER - PREPAID
A17: Individuals | C17: m3 | D17: 25311.5 | E17: 29446.1 | P17: =SUM(D17:O17) -> 54757.6
A18: CWPs | C18: m3 | D18: 4819.3 | E18: 4389.2 | P18: =SUM(D18:O18) -> 9208.5
A19: Institutions | C19: m3 | D19: 5386.9 | E19: 5468 | P19: =SUM(D19:O19) -> 10854.9
A20: Commercial/Industrial | C20: m3 | D20: 1783.5 | E20: 2548.1 | P20: =SUM(D20:O20) -> 4331.6
A21: Total Volume Prepaid | C21: m3 | D21: =SUM(D17:D20) -> 37301.2 | E21: =SUM(E17:E20) -> 41851.4 | F21: =SUM(F17:F20) -> 0 | G21: =SUM(G17:G20) -> 0 | H21: =SUM(H17:H20) -> 0 | I21: =SUM(I17:I20) -> 0 | J21: =SUM(J17:J20) -> 0 | K21: =SUM(K17:K20) -> 0 | ... P21: =SUM(P17:P20) -> 79152.6
A22: TOTAL REVENUE WATER | C22: m3 | D22: =D21+D15 -> 91977.2 | E22: =E21+E15 -> 101506.4 | F22: =F21+F15 -> 0 | G22: =G21+G15 -> 0 | H22: =H21+H15 -> 0 | I22: =I21+I15 -> 0 | J22: =J21+J15 -> 0 | K22: =K21+K15 -> 0 | ... P22: =P21+P15 -> 193483.6
A24: Non-Revenue Water (NRW) | B24: Volume | C24: m3 | D24: =D9-D22 -> 63449.8 | E24: =E9-E22 -> 48674.6 | F24: =F9-F22 -> 0 | G24: =G9-G22 -> 0 | H24: =H9-H22 -> 0 | I24: =I9-I22 -> 0 | J24: =J9-J22 -> 0 | K24: =K9-K22 -> 0 | ... P24: =P9-P22 -> 112124.4
B25: Percentage | C25: % | D25: =D24/D9 -> 0.40822894 | E25: =E24/E9 -> 0.32410625 | F25: =F24/F9 -> #DIV/0! | G25: =G24/G9 -> #DIV/0! | H25: =H24/H9 -> #DIV/0! | I25: =I24/I9 -> #DIV/0! | J25: =J24/J9 -> #DIV/0! | K25: =K24/K9 -> #DIV/0! | ... P25: =P24/P9 -> 0.36688961
A26: OPERATING EXPENSES
A27: Chemicals
A28: Chemical | B28: Rate(MK/kg)
A29: Chlorine | B29: 23929.1 | C29: kg | D29: 510.2 | E29: 525.19 | P29: =SUM(D29:O29) -> 1035.39
C30: kg/mg litre | D30: =D29/(D9/1000) -> 3.28257 | E30: =E29/(E9/1000) -> 3.4970469 | F30: =F29/(F9/1000) -> #DIV/0! | G30: =G29/(G9/1000) -> #DIV/0! | H30: =H29/(H9/1000) -> #DIV/0! | I30: =I29/(I9/1000) -> #DIV/0! | J30: =J29/(J9/1000) -> #DIV/0! | K30: =K29/(K9/1000) -> #DIV/0! | ... P30: =P29/(P9/1000) -> 3.3879676
A31: Aluminium sulphate | B31: 1090.4 | C31: kg | P31: =SUM(D31:O31) -> 0
C32: kg/mg litre | D32: =D31/(D9/1000) -> 0 | E32: =E31/(E9/1000) -> 0 | F32: =F31/(F9/1000) -> #DIV/0! | G32: =G31/(G9/1000) -> #DIV/0! | H32: =H31/(H9/1000) -> #DIV/0! | I32: =I31/(I9/1000) -> #DIV/0! | J32: =J31/(J9/1000) -> #DIV/0! | K32: =K31/(K9/1000) -> #DIV/0! | ... P32: =P31/(P9/1000) -> 0
A33: Soda | B33: 1228.2886 | C33: kg | P33: =SUM(D33:O33) -> 0
C34: kg/mg litre | D34: =D33/(D9/1000) -> 0 | E34: =E33/(E9/1000) -> 0 | F34: =F33/(F9/1000) -> #DIV/0! | G34: =G33/(G9/1000) -> #DIV/0! | H34: =H33/(H9/1000) -> #DIV/0! | I34: =I33/(I9/1000) -> #DIV/0! | J34: =J33/(J9/1000) -> #DIV/0! | K34: =K33/(K9/1000) -> #DIV/0! | ... P34: =P33/(P9/1000) -> 0
A35: Algae floc | B35: 3726.7258 | C35: litres
C36: litres/mg litre
A37: Sud floc | B37: 3951.5936 | C37: litres | D37: 0 | E37: 0 | F37: 0 | G37: 0 | H37: 0 | I37: 0 | J37: 0 | K37: 0 | L37: 0 | M37: 0 | N37: 0 | O37: 0 | P37: =SUM(D37:O37) -> 0
C38: litres/mg litre | D38: =D37/(D9/1000) -> 0 | E38: =E37/(E9/1000) -> 0 | F38: =F37/(F9/1000) -> #DIV/0! | G38: =G37/(G9/1000) -> #DIV/0! | H38: =H37/(H9/1000) -> #DIV/0! | I38: =I37/(I9/1000) -> #DIV/0! | J38: =J37/(J9/1000) -> #DIV/0! | K38: =K37/(K9/1000) -> #DIV/0! | ... P38: =P37/(P9/1000) -> 0
A39: Potasium permanganate | B39: 1950 | C39: kg | D39: 0 | E39: 0 | F39: 0 | G39: 0 | H39: 0 | I39: 0 | J39: 0 | K39: 0 | L39: 0 | M39: 0 | N39: 0 | O39: 0 | P39: =SUM(D39:O39) -> 0
C40: kg/mg litre | D40: =D39/(D9/1000) -> 0 | E40: =E39/(E9/1000) -> 0 | F40: =F39/(F9/1000) -> #DIV/0! | G40: =G39/(G9/1000) -> #DIV/0! | H40: =H39/(H9/1000) -> #DIV/0! | I40: =I39/(I9/1000) -> #DIV/0! | J40: =J39/(J9/1000) -> #DIV/0! | K40: =K39/(K9/1000) -> #DIV/0! | ... P40: =P39/(P9/1000) -> 0
A41: Cost of Chemicals | C41: Mk | D41: =(D29*$B29)+(D31*$B31)+(D33*$B33)+(D35*$B35)+(D37*$B37)+(D39*$B39) -> 12208627 | E41: =(E29*$B29)+(E31*$B31)+(E33*$B33)+(E35*$B35)+(E37*$B37)+(E39*$B39) -> 12567324 | F41: =(F29*$B29)+(F31*$B31)+(F33*$B33)+(F35*$B35)+(F37*$B37)+(F39*$B39) -> 0 | G41: =(G29*$B29)+(G31*$B31)+(G33*$B33)+(G35*$B35)+(G37*$B37)+(G39*$B39) -> 0 | H41: =(H29*$B29)+(H31*$B31)+(H33*$B33)+(H35*$B35)+(H37*$B37)+(H39*$B39) -> 0 | I41: =(I29*$B29)+(I31*$B31)+(I33*$B33)+(I35*$B35)+(I37*$B37)+(I39*$B39) -> 0 | J41: =(J29*$B29)+(J31*$B31)+(J33*$B33)+(J35*$B35)+(J37*$B37)+(J39*$B39) -> 0 | K41: =(K29*$B29)+(K31*$B31)+(K33*$B33)+(K35*$B35)+(K37*$B37)+(K39*$B39) -> 0 | ... O41: =(O29*$B29)+(O31*$B31)+(O33*$B33)+(O35*$B35)+(O37*$B37)+(O39*$B39) -> 0 | P41: =SUM(D41:O41) -> 24775951
A42: Cost/vol. Produced (chemicals) | C42: Mk/m3 | D42: =D41/D9 -> 78.548945 | E42: =E41/E9 -> 83.681185 | F42: =F41/F9 -> #DIV/0! | G42: =G41/G9 -> #DIV/0! | H42: =H41/H9 -> #DIV/0! | I42: =I41/I9 -> #DIV/0! | J42: =J41/J9 -> #DIV/0! | K42: =K41/K9 -> #DIV/0! | ... P42: =P41/P9 -> 81.071015
A43: Power
...

Sheet Monkey Bay
A1: SOUTHERN REGION WATER BOARD
A3: MONTHLY REPORTS - 2025/2026
A4: MANGOCHI ZONE
A5: MANGOCHI ZONE
A7: PARAMETERS | C7: UNITS | D7: APRIL | E7: MAY | F7: JUNE | G7: JULY | H7: AUGUST | I7: SEPTEMBER | J7: OCTOBER | K7: NOVEMBER | L7: DECEMBER | M7: JANUARY | N7: FEBRUARY | O7: MARCH | P7: TOTALS
A8: PRODUCTION
A9: Volume Produced | C9: m3 | D9: 55334 | E9: 60716 | P9: =SUM(D9:O9) -> 116050
A10: REVENUE WATER - POSTPAID
A11: Volume Billed Individuals | C11: m3 | D11: 16648 | E11: 19144 | P11: =SUM(D11:O11) -> 35792
A12: Volume Billed CWPs | C12: m3 | P12: =SUM(D12:O12) -> 0
A13: Volume Billed Institutions | C13: m3 | D13: 4296 | E13: 4619 | P13: =SUM(D13:O13) -> 8915
A14: Volume Billed Commercial/Industrial | C14: m3 | P14: =SUM(D14:O14) -> 0
A15: Total Volume Billed Post Paid | C15: m3 | D15: =SUM(D11:D14) -> 20944 | E15: =SUM(E11:E14) -> 23763 | F15: =SUM(F11:F14) -> 0 | G15: =SUM(G11:G14) -> 0 | H15: =SUM(H11:H14) -> 0 | I15: =SUM(I11:I14) -> 0 | J15: =SUM(J11:J14) -> 0 | K15: =SUM(K11:K14) -> 0 | ... P15: =SUM(P11:P14) -> 44707
A16: REVENUE WATER - PREPAID
A17: Individuals | C17: m3 | D17: 8292.7 | E17: 9882.4 | P17: =SUM(D17:O17) -> 18175.1
A18: CWPs | C18: m3 | D18: 1010.3 | E18: 1234.3 | P18: =SUM(D18:O18) -> 2244.6
A19: Institutions | C19: m3 | D19: 2460.9 | E19: 2137.6 | P19: =SUM(D19:O19) -> 4598.5
A20: Commercial/Industrial | C20: m3 | D20: 559.4 | E20: 608.4 | P20: =SUM(D20:O20) -> 1167.8
A21: Total Volume Prepaid | C21: m3 | D21: =SUM(D17:D20) -> 12323.3 | E21: =SUM(E17:E20) -> 13862.7 | F21: =SUM(F17:F20) -> 0 | G21: =SUM(G17:G20) -> 0 | H21: =SUM(H17:H20) -> 0 | I21: =SUM(I17:I20) -> 0 | J21: =SUM(J17:J20) -> 0 | K21: =SUM(K17:K20) -> 0 | ... P21: =SUM(P17:P20) -> 26186
A22: TOTAL REVENUE WATER | C22: m3 | D22: =D21+D15 -> 33267.3 | E22: =E21+E15 -> 37625.7 | F22: =F21+F15 -> 0 | G22: =G21+G15 -> 0 | H22: =H21+H15 -> 0 | I22: =I21+I15 -> 0 | J22: =J21+J15 -> 0 | K22: =K21+K15 -> 0 | ... P22: =P21+P15 -> 70893
A24: Non-Revenue Water (NRW) | B24: Volume | C24: m3 | D24: =D9-D22 -> 22066.7 | E24: =E9-E22 -> 23090.3 | F24: =F9-F22 -> 0 | G24: =G9-G22 -> 0 | H24: =H9-H22 -> 0 | I24: =I9-I22 -> 0 | J24: =J9-J22 -> 0 | K24: =K9-K22 -> 0 | ... P24: =P9-P22 -> 45157
B25: Percentage | C25: % | D25: =D24/D9 -> 0.39879098 | E25: =E24/E9 -> 0.38030009 | F25: =F24/F9 -> #DIV/0! | G25: =G24/G9 -> #DIV/0! | H25: =H24/H9 -> #DIV/0! | I25: =I24/I9 -> #DIV/0! | J25: =J24/J9 -> #DIV/0! | K25: =K24/K9 -> #DIV/0! | ... P25: =P24/P9 -> 0.38911676
A26: OPERATING EXPENSES
A27: Chemicals
A28: Chemical | B28: Rate(MK/kg)
A29: Chlorine | B29: 23929.1 | C29: kg | D29: 115 | E29: 115 | P29: =SUM(D29:O29) -> 230
C30: kg/mg litre | D30: =D29/(D9/1000) -> 2.0782882 | E30: =E29/(E9/1000) -> 1.8940642 | F30: =F29/(F9/1000) -> #DIV/0! | G30: =G29/(G9/1000) -> #DIV/0! | H30: =H29/(H9/1000) -> #DIV/0! | I30: =I29/(I9/1000) -> #DIV/0! | J30: =J29/(J9/1000) -> #DIV/0! | K30: =K29/(K9/1000) -> #DIV/0! | ... P30: =P29/(P9/1000) -> 1.9819044
A31: Aluminium sulphate | B31: 1090.4 | C31: kg | P31: =SUM(D31:O31) -> 0
C32: kg/mg litre | D32: =D31/(D9/1000) -> 0 | E32: =E31/(E9/1000) -> 0 | F32: =F31/(F9/1000) -> #DIV/0! | G32: =G31/(G9/1000) -> #DIV/0! | H32: =H31/(H9/1000) -> #DIV/0! | I32: =I31/(I9/1000) -> #DIV/0! | J32: =J31/(J9/1000) -> #DIV/0! | K32: =K31/(K9/1000) -> #DIV/0! | ... P32: =P31/(P9/1000) -> 0
A33: Soda | B33: 1228.2886 | C33: kg | P33: =SUM(D33:O33) -> 0
C34: kg/mg litre | D34: =D33/(D9/1000) -> 0 | E34: =E33/(E9/1000) -> 0 | F34: =F33/(F9/1000) -> #DIV/0! | G34: =G33/(G9/1000) -> #DIV/0! | H34: =H33/(H9/1000) -> #DIV/0! | I34: =I33/(I9/1000) -> #DIV/0! | J34: =J33/(J9/1000) -> #DIV/0! | K34: =K33/(K9/1000) -> #DIV/0! | ... P34: =P33/(P9/1000) -> 0
A35: Algae floc | B35: 3726.7258 | C35: litres
C36: litres/mg litre
A37: Sud floc | B37: 3951.5936 | C37: litres | D37: 0 | E37: 0 | F37: 0 | G37: 0 | H37: 0 | I37: 0 | J37: 0 | K37: 0 | L37: 0 | M37: 0 | N37: 0 | O37: 0 | P37: =SUM(D37:O37) -> 0
C38: litres/mg litre | D38: =D37/(D9/1000) -> 0 | E38: =E37/(E9/1000) -> 0 | F38: =F37/(F9/1000) -> #DIV/0! | G38: =G37/(G9/1000) -> #DIV/0! | H38: =H37/(H9/1000) -> #DIV/0! | I38: =I37/(I9/1000) -> #DIV/0! | J38: =J37/(J9/1000) -> #DIV/0! | K38: =K37/(K9/1000) -> #DIV/0! | ... P38: =P37/(P9/1000) -> 0
A39: Potasium permanganate | B39: 1950 | C39: kg | D39: 0 | E39: 0 | F39: 0 | G39: 0 | H39: 0 | I39: 0 | J39: 0 | K39: 0 | L39: 0 | M39: 0 | N39: 0 | O39: 0 | P39: =SUM(D39:O39) -> 0
C40: kg/mg litre | D40: =D39/(D9/1000) -> 0 | E40: =E39/(E9/1000) -> 0 | F40: =F39/(F9/1000) -> #DIV/0! | G40: =G39/(G9/1000) -> #DIV/0! | H40: =H39/(H9/1000) -> #DIV/0! | I40: =I39/(I9/1000) -> #DIV/0! | J40: =J39/(J9/1000) -> #DIV/0! | K40: =K39/(K9/1000) -> #DIV/0! | ... P40: =P39/(P9/1000) -> 0
A41: Cost of Chemicals | C41: Mk | D41: =(D29*$B29)+(D31*$B31)+(D33*$B33)+(D35*$B35)+(D37*$B37)+(D39*$B39) -> 2751846.5 | E41: =(E29*$B29)+(E31*$B31)+(E33*$B33)+(E35*$B35)+(E37*$B37)+(E39*$B39) -> 2751846.5 | F41: =(F29*$B29)+(F31*$B31)+(F33*$B33)+(F35*$B35)+(F37*$B37)+(F39*$B39) -> 0 | G41: =(G29*$B29)+(G31*$B31)+(G33*$B33)+(G35*$B35)+(G37*$B37)+(G39*$B39) -> 0 | H41: =(H29*$B29)+(H31*$B31)+(H33*$B33)+(H35*$B35)+(H37*$B37)+(H39*$B39) -> 0 | I41: =(I29*$B29)+(I31*$B31)+(I33*$B33)+(I35*$B35)+(I37*$B37)+(I39*$B39) -> 0 | J41: =(J29*$B29)+(J31*$B31)+(J33*$B33)+(J35*$B35)+(J37*$B37)+(J39*$B39) -> 0 | K41: =(K29*$B29)+(K31*$B31)+(K33*$B33)+(K35*$B35)+(K37*$B37)+(K39*$B39) -> 0 | ... O41: =(O29*$B29)+(O31*$B31)+(O33*$B33)+(O35*$B35)+(O37*$B37)+(O39*$B39) -> 0 | P41: =SUM(D41:O41) -> 5503693
A42: Cost/vol. Produced (chemicals) | C42: Mk/m3 | D42: =D41/D9 -> 49.731566 | E42: =E41/E9 -> 45.323251 | F42: =F41/F9 -> #DIV/0! | G42: =G41/G9 -> #DIV/0! | H42: =H41/H9 -> #DIV/0! | I42: =I41/I9 -> #DIV/0! | J42: =J41/J9 -> #DIV/0! | K42: =K41/K9 -> #DIV/0! | ... P42: =P41/P9 -> 47.425187
A43: Power
...

Sheet Namwera
A1: SOUTHERN REGION WATER BOARD
A3: MONTHLY REPORTS - 2025/2026
A4: MANGOCHI ZONE
A5: MANGOCHI ZONE
A7: PARAMETERS | C7: UNITS | D7: APRIL | E7: MAY | F7: JUNE | G7: JULY | H7: AUGUST | I7: SEPTEMBER | J7: OCTOBER | K7: NOVEMBER | L7: DECEMBER | M7: JANUARY | N7: FEBRUARY | O7: MARCH | P7: TOTALS
A8: PRODUCTION
A9: Volume Produced | C9: m3 | D9: 3422 | E9: 4964 | P9: =SUM(D9:O9) -> 8386
A10: REVENUE WATER - POSTPAID
A11: Volume Billed Individuals | C11: m3 | D11: 6 | E11: 15 | P11: =SUM(D11:O11) -> 21
A12: Volume Billed CWPs | C12: m3 | P12: =SUM(D12:O12) -> 0
A13: Volume Billed Institutions | C13: m3 | D13: 4 | E13: 3 | P13: =SUM(D13:O13) -> 7
A14: Volume Billed Commercial/Industrial | C14: m3 | P14: =SUM(D14:O14) -> 0
A15: Total Volume Billed Post Paid | C15: m3 | D15: =SUM(D11:D14) -> 10 | E15: =SUM(E11:E14) -> 18 | F15: =SUM(F11:F14) -> 0 | G15: =SUM(G11:G14) -> 0 | H15: =SUM(H11:H14) -> 0 | I15: =SUM(I11:I14) -> 0 | J15: =SUM(J11:J14) -> 0 | K15: =SUM(K11:K14) -> 0 | ... P15: =SUM(P11:P14) -> 28
A16: REVENUE WATER - PREPAID
A17: Individuals | C17: m3 | D17: 2707.1 | E17: 4142.7 | P17: =SUM(D17:O17) -> 6849.8
A18: CWPs | C18: m3 | P18: =SUM(D18:O18) -> 0
A19: Institutions | C19: m3 | D19: 580.3 | E19: 173.6 | P19: =SUM(D19:O19) -> 753.9
A20: Commercial/Industrial | C20: m3 | D20: 11.4 | E20: 16.4 | P20: =SUM(D20:O20) -> 27.8
A21: Total Volume Prepaid | C21: m3 | D21: =SUM(D17:D20) -> 3298.8 | E21: =SUM(E17:E20) -> 4332.7 | F21: =SUM(F17:F20) -> 0 | G21: =SUM(G17:G20) -> 0 | H21: =SUM(H17:H20) -> 0 | I21: =SUM(I17:I20) -> 0 | J21: =SUM(J17:J20) -> 0 | K21: =SUM(K17:K20) -> 0 | ... P21: =SUM(P17:P20) -> 7631.5
A22: TOTAL REVENUE WATER | C22: m3 | D22: =D21+D15 -> 3308.8 | E22: =E21+E15 -> 4350.7 | F22: =F21+F15 -> 0 | G22: =G21+G15 -> 0 | H22: =H21+H15 -> 0 | I22: =I21+I15 -> 0 | J22: =J21+J15 -> 0 | K22: =K21+K15 -> 0 | ... P22: =P21+P15 -> 7659.5
A24: Non-Revenue Water (NRW) | B24: Volume | C24: m3 | D24: =D9-D22 -> 113.2 | E24: =E9-E22 -> 613.3 | F24: =F9-F22 -> 0 | G24: =G9-G22 -> 0 | H24: =H9-H22 -> 0 | I24: =I9-I22 -> 0 | J24: =J9-J22 -> 0 | K24: =K9-K22 -> 0 | ... P24: =P9-P22 -> 726.5
B25: Percentage | C25: % | D25: =D24/D9 -> 0.03308007 | E25: =E24/E9 -> 0.12354956 | F25: =F24/F9 -> #DIV/0! | G25: =G24/G9 -> #DIV/0! | H25: =H24/H9 -> #DIV/0! | I25: =I24/I9 -> #DIV/0! | J25: =J24/J9 -> #DIV/0! | K25: =K24/K9 -> #DIV/0! | ... P25: =P24/P9 -> 0.086632483
A26: OPERATING EXPENSES
A27: Chemicals
A28: Chemical | B28: Rate(MK/kg)
A29: Chlorine | B29: 23929.1 | C29: kg | D29: 4.5 | E29: 4 | P29: =SUM(D29:O29) -> 8.5
C30: kg/mg litre | D30: =D29/(D9/1000) -> 1.3150205 | E30: =E29/(E9/1000) -> 0.80580177 | F30: =F29/(F9/1000) -> #DIV/0! | G30: =G29/(G9/1000) -> #DIV/0! | H30: =H29/(H9/1000) -> #DIV/0! | I30: =I29/(I9/1000) -> #DIV/0! | J30: =J29/(J9/1000) -> #DIV/0! | K30: =K29/(K9/1000) -> #DIV/0! | ... P30: =P29/(P9/1000) -> 1.0135941
A31: Aluminium sulphate | B31: 1090.4 | C31: kg | P31: =SUM(D31:O31) -> 0
C32: kg/mg litre | D32: =D31/(D9/1000) -> 0 | E32: =E31/(E9/1000) -> 0 | F32: =F31/(F9/1000) -> #DIV/0! | G32: =G31/(G9/1000) -> #DIV/0! | H32: =H31/(H9/1000) -> #DIV/0! | I32: =I31/(I9/1000) -> #DIV/0! | J32: =J31/(J9/1000) -> #DIV/0! | K32: =K31/(K9/1000) -> #DIV/0! | ... P32: =P31/(P9/1000) -> 0
A33: Soda | B33: 1228.2886 | C33: kg | P33: =SUM(D33:O33) -> 0
C34: kg/mg litre | D34: =D33/(D9/1000) -> 0 | E34: =E33/(E9/1000) -> 0 | F34: =F33/(F9/1000) -> #DIV/0! | G34: =G33/(G9/1000) -> #DIV/0! | H34: =H33/(H9/1000) -> #DIV/0! | I34: =I33/(I9/1000) -> #DIV/0! | J34: =J33/(J9/1000) -> #DIV/0! | K34: =K33/(K9/1000) -> #DIV/0! | ... P34: =P33/(P9/1000) -> 0
A35: Algae floc | B35: 3726.7258 | C35: litres
C36: litres/mg litre
A37: Sud floc | B37: 3951.5936 | C37: litres | D37: 0 | E37: 0 | F37: 0 | G37: 0 | H37: 0 | I37: 0 | J37: 0 | K37: 0 | L37: 0 | M37: 0 | N37: 0 | O37: 0 | P37: =SUM(D37:O37) -> 0
C38: litres/mg litre | D38: =D37/(D9/1000) -> 0 | E38: =E37/(E9/1000) -> 0 | F38: =F37/(F9/1000) -> #DIV/0! | G38: =G37/(G9/1000) -> #DIV/0! | H38: =H37/(H9/1000) -> #DIV/0! | I38: =I37/(I9/1000) -> #DIV/0! | J38: =J37/(J9/1000) -> #DIV/0! | K38: =K37/(K9/1000) -> #DIV/0! | ... P38: =P37/(P9/1000) -> 0
A39: Potasium permanganate | B39: 1950 | C39: kg | D39: 0 | E39: 0 | F39: 0 | G39: 0 | H39: 0 | I39: 0 | J39: 0 | K39: 0 | L39: 0 | M39: 0 | N39: 0 | O39: 0 | P39: =SUM(D39:O39) -> 0
C40: kg/mg litre | D40: =D39/(D9/1000) -> 0 | E40: =E39/(E9/1000) -> 0 | F40: =F39/(F9/1000) -> #DIV/0! | G40: =G39/(G9/1000) -> #DIV/0! | H40: =H39/(H9/1000) -> #DIV/0! | I40: =I39/(I9/1000) -> #DIV/0! | J40: =J39/(J9/1000) -> #DIV/0! | K40: =K39/(K9/1000) -> #DIV/0! | ... P40: =P39/(P9/1000) -> 0
A41: Cost of Chemicals | C41: Mk | D41: =(D29*$B29)+(D31*$B31)+(D33*$B33)+(D35*$B35)+(D37*$B37)+(D39*$B39) -> 107680.95 | E41: =(E29*$B29)+(E31*$B31)+(E33*$B33)+(E35*$B35)+(E37*$B37)+(E39*$B39) -> 95716.4 | F41: =(F29*$B29)+(F31*$B31)+(F33*$B33)+(F35*$B35)+(F37*$B37)+(F39*$B39) -> 0 | G41: =(G29*$B29)+(G31*$B31)+(G33*$B33)+(G35*$B35)+(G37*$B37)+(G39*$B39) -> 0 | H41: =(H29*$B29)+(H31*$B31)+(H33*$B33)+(H35*$B35)+(H37*$B37)+(H39*$B39) -> 0 | I41: =(I29*$B29)+(I31*$B31)+(I33*$B33)+(I35*$B35)+(I37*$B37)+(I39*$B39) -> 0 | J41: =(J29*$B29)+(J31*$B31)+(J33*$B33)+(J35*$B35)+(J37*$B37)+(J39*$B39) -> 0 | K41: =(K29*$B29)+(K31*$B31)+(K33*$B33)+(K35*$B35)+(K37*$B37)+(K39*$B39) -> 0 | ... O41: =(O29*$B29)+(O31*$B31)+(O33*$B33)+(O35*$B35)+(O37*$B37)+(O39*$B39) -> 0 | P41: =SUM(D41:O41) -> 203397.35
A42: Cost/vol. Produced (chemicals) | C42: Mk/m3 | D42: =D41/D9 -> 31.467256 | E42: =E41/E9 -> 19.282111 | F42: =F41/F9 -> #DIV/0! | G42: =G41/G9 -> #DIV/0! | H42: =H41/H9 -> #DIV/0! | I42: =I41/I9 -> #DIV/0! | J42: =J41/J9 -> #DIV/0! | K42: =K41/K9 -> #DIV/0! | ... P42: =P41/P9 -> 24.254394
A43: Power
...

Sheet Nkhudzi
A1: SOUTHERN REGION WATER BOARD
A3: MONTHLY REPORTS - 2025/2026
A4: MANGOCHI ZONE
A5: MANGOCHI ZONE
A7: PARAMETERS | C7: UNITS | D7: APRIL | E7: MAY | F7: JUNE | G7: JULY | H7: AUGUST | I7: SEPTEMBER | J7: OCTOBER | K7: NOVEMBER | L7: DECEMBER | M7: JANUARY | N7: FEBRUARY | O7: MARCH | P7: TOTALS
A8: PRODUCTION
A9: Volume Produced | C9: m3 | D9: 33477 | E9: 40074 | P9: =SUM(D9:O9) -> 73551
A10: REVENUE WATER - POSTPAID
A11: Volume Billed Individuals | C11: m3 | D11: 100 | E11: 127 | P11: =SUM(D11:O11) -> 227
A12: Volume Billed CWPs | C12: m3 | P12: =SUM(D12:O12) -> 0
A13: Volume Billed Institutions | C13: m3 | D13: 71 | E13: 332 | P13: =SUM(D13:O13) -> 403
A14: Volume Billed Commercial/Industrial | C14: m3 | D14: 1 | E14: 1 | P14: =SUM(D14:O14) -> 2
A15: Total Volume Billed Post Paid | C15: m3 | D15: =SUM(D11:D14) -> 172 | E15: =SUM(E11:E14) -> 460 | F15: =SUM(F11:F14) -> 0 | G15: =SUM(G11:G14) -> 0 | H15: =SUM(H11:H14) -> 0 | I15: =SUM(I11:I14) -> 0 | J15: =SUM(J11:J14) -> 0 | K15: =SUM(K11:K14) -> 0 | ... P15: =SUM(P11:P14) -> 632
A16: REVENUE WATER - PREPAID
A17: Individuals | C17: m3 | D17: 22914.3 | E17: 25979.5 | P17: =SUM(D17:O17) -> 48893.8
A18: CWPs | C18: m3 | D18: 728.3 | E18: 631.3 | P18: =SUM(D18:O18) -> 1359.6
A19: Institutions | C19: m3 | D19: 628.5 | E19: 339.1 | P19: =SUM(D19:O19) -> 967.6
A20: Commercial/Industrial | C20: m3 | D20: 1261.1 | E20: 1023.9 | P20: =SUM(D20:O20) -> 2285
A21: Total Volume Prepaid | C21: m3 | D21: =SUM(D17:D20) -> 25532.2 | E21: =SUM(E17:E20) -> 27973.8 | F21: =SUM(F17:F20) -> 0 | G21: =SUM(G17:G20) -> 0 | H21: =SUM(H17:H20) -> 0 | I21: =SUM(I17:I20) -> 0 | J21: =SUM(J17:J20) -> 0 | K21: =SUM(K17:K20) -> 0 | ... P21: =SUM(P17:P20) -> 53506
A22: TOTAL REVENUE WATER | C22: m3 | D22: =D21+D15 -> 25704.2 | E22: =E21+E15 -> 28433.8 | F22: =F21+F15 -> 0 | G22: =G21+G15 -> 0 | H22: =H21+H15 -> 0 | I22: =I21+I15 -> 0 | J22: =J21+J15 -> 0 | K22: =K21+K15 -> 0 | ... P22: =P21+P15 -> 54138
A24: Non-Revenue Water (NRW) | B24: Volume | C24: m3 | D24: =D9-D22 -> 7772.8 | E24: =E9-E22 -> 11640.2 | F24: =F9-F22 -> 0 | G24: =G9-G22 -> 0 | H24: =H9-H22 -> 0 | I24: =I9-I22 -> 0 | J24: =J9-J22 -> 0 | K24: =K9-K22 -> 0 | ... P24: =P9-P22 -> 19413
B25: Percentage | C25: % | D25: =D24/D9 -> 0.23218329 | E25: =E24/E9 -> 0.29046763 | F25: =F24/F9 -> #DIV/0! | G25: =G24/G9 -> #DIV/0! | H25: =H24/H9 -> #DIV/0! | I25: =I24/I9 -> #DIV/0! | J25: =J24/J9 -> #DIV/0! | K25: =K24/K9 -> #DIV/0! | ... P25: =P24/P9 -> 0.26393931
A26: OPERATING EXPENSES
A27: Chemicals
A28: Chemical | B28: Rate(MK/kg)
A29: Chlorine | B29: 23929.1 | C29: kg | D29: 64.8 | E29: 74.31 | P29: =SUM(D29:O29) -> 139.11
C30: kg/mg litre | D30: =D29/(D9/1000) -> 1.9356573 | E30: =E29/(E9/1000) -> 1.8543195 | F30: =F29/(F9/1000) -> #DIV/0! | G30: =G29/(G9/1000) -> #DIV/0! | H30: =H29/(H9/1000) -> #DIV/0! | I30: =I29/(I9/1000) -> #DIV/0! | J30: =J29/(J9/1000) -> #DIV/0! | K30: =K29/(K9/1000) -> #DIV/0! | ... P30: =P29/(P9/1000) -> 1.8913407
A31: Aluminium sulphate | B31: 1090.4 | C31: kg | P31: =SUM(D31:O31) -> 0
C32: kg/mg litre | D32: =D31/(D9/1000) -> 0 | E32: =E31/(E9/1000) -> 0 | F32: =F31/(F9/1000) -> #DIV/0! | G32: =G31/(G9/1000) -> #DIV/0! | H32: =H31/(H9/1000) -> #DIV/0! | I32: =I31/(I9/1000) -> #DIV/0! | J32: =J31/(J9/1000) -> #DIV/0! | K32: =K31/(K9/1000) -> #DIV/0! | ... P32: =P31/(P9/1000) -> 0
A33: Soda | B33: 1228.2886 | C33: kg | P33: =SUM(D33:O33) -> 0
C34: kg/mg litre | D34: =D33/(D9/1000) -> 0 | E34: =E33/(E9/1000) -> 0 | F34: =F33/(F9/1000) -> #DIV/0! | G34: =G33/(G9/1000) -> #DIV/0! | H34: =H33/(H9/1000) -> #DIV/0! | I34: =I33/(I9/1000) -> #DIV/0! | J34: =J33/(J9/1000) -> #DIV/0! | K34: =K33/(K9/1000) -> #DIV/0! | ... P34: =P33/(P9/1000) -> 0
A35: Algae floc | B35: 3726.7258 | C35: litres
C36: litres/mg litre
A37: Sud floc | B37: 3951.5936 | C37: litres | D37: 0 | E37: 0 | F37: 0 | G37: 0 | H37: 0 | I37: 0 | J37: 0 | K37: 0 | L37: 0 | M37: 0 | N37: 0 | O37: 0 | P37: =SUM(D37:O37) -> 0
C38: litres/mg litre | D38: =D37/(D9/1000) -> 0 | E38: =E37/(E9/1000) -> 0 | F38: =F37/(F9/1000) -> #DIV/0! | G38: =G37/(G9/1000) -> #DIV/0! | H38: =H37/(H9/1000) -> #DIV/0! | I38: =I37/(I9/1000) -> #DIV/0! | J38: =J37/(J9/1000) -> #DIV/0! | K38: =K37/(K9/1000) -> #DIV/0! | ... P38: =P37/(P9/1000) -> 0
A39: Potasium permanganate | B39: 1950 | C39: kg | D39: 0 | E39: 0 | F39: 0 | G39: 0 | H39: 0 | I39: 0 | J39: 0 | K39: 0 | L39: 0 | M39: 0 | N39: 0 | O39: 0 | P39: =SUM(D39:O39) -> 0
C40: kg/mg litre | D40: =D39/(D9/1000) -> 0 | E40: =E39/(E9/1000) -> 0 | F40: =F39/(F9/1000) -> #DIV/0! | G40: =G39/(G9/1000) -> #DIV/0! | H40: =H39/(H9/1000) -> #DIV/0! | I40: =I39/(I9/1000) -> #DIV/0! | J40: =J39/(J9/1000) -> #DIV/0! | K40: =K39/(K9/1000) -> #DIV/0! | ... P40: =P39/(P9/1000) -> 0
A41: Cost of Chemicals | C41: Mk | D41: =(D29*$B29)+(D31*$B31)+(D33*$B33)+(D35*$B35)+(D37*$B37)+(D39*$B39) -> 1550605.7 | E41: =(E29*$B29)+(E31*$B31)+(E33*$B33)+(E35*$B35)+(E37*$B37)+(E39*$B39) -> 1778171.4 | F41: =(F29*$B29)+(F31*$B31)+(F33*$B33)+(F35*$B35)+(F37*$B37)+(F39*$B39) -> 0 | G41: =(G29*$B29)+(G31*$B31)+(G33*$B33)+(G35*$B35)+(G37*$B37)+(G39*$B39) -> 0 | H41: =(H29*$B29)+(H31*$B31)+(H33*$B33)+(H35*$B35)+(H37*$B37)+(H39*$B39) -> 0 | I41: =(I29*$B29)+(I31*$B31)+(I33*$B33)+(I35*$B35)+(I37*$B37)+(I39*$B39) -> 0 | J41: =(J29*$B29)+(J31*$B31)+(J33*$B33)+(J35*$B35)+(J37*$B37)+(J39*$B39) -> 0 | K41: =(K29*$B29)+(K31*$B31)+(K33*$B33)+(K35*$B35)+(K37*$B37)+(K39*$B39) -> 0 | ... O41: =(O29*$B29)+(O31*$B31)+(O33*$B33)+(O35*$B35)+(O37*$B37)+(O39*$B39) -> 0 | P41: =SUM(D41:O41) -> 3328777.1
A42: Cost/vol. Produced (chemicals) | C42: Mk/m3 | D42: =D41/D9 -> 46.318538 | E42: =E41/E9 -> 44.372197 | F42: =F41/F9 -> #DIV/0! | G42: =G41/G9 -> #DIV/0! | H42: =H41/H9 -> #DIV/0! | I42: =I41/I9 -> #DIV/0! | J42: =J41/J9 -> #DIV/0! | K42: =K41/K9 -> #DIV/0! | ... P42: =P41/P9 -> 45.258081
A43: Power
...

Sheet Zone Monthly
A1: SOUTHERN REGION WATER BOARD
A3: MONTHLY REPORTS - 2025/2026
A4: MANGOCHI ZONE
A5: MANGOCHI ZONE
A7: PARAMETERS | C7: UNITS | D7: APRIL | E7: MAY | F7: JUNE | G7: JULY | H7: AUGUST | I7: SEPTEMBER | J7: OCTOBER | K7: NOVEMBER | L7: DECEMBER | M7: JANUARY | N7: FEBRUARY | O7: MARCH | P7: TOTALS
A8: PRODUCTION
A9: Volume Produced | C9: m3 | D9: =Mangochi!D9+'Monkey Bay'!D9+Namwera!D9+Nkhudzi!D9 -> 247660 | E9: =Mangochi!E9+'Monkey Bay'!E9+Namwera!E9+Nkhudzi!E9 -> 255935 | F9: =Mangochi!F9+'Monkey Bay'!F9+Namwera!F9+Nkhudzi!F9 -> 0 | G9: =Mangochi!G9+'Monkey Bay'!G9+Namwera!G9+Nkhudzi!G9 -> 0 | H9: =Mangochi!H9+'Monkey Bay'!H9+Namwera!H9+Nkhudzi!H9 -> 0 | I9: =Mangochi!I9+'Monkey Bay'!I9+Namwera!I9+Nkhudzi!I9 -> 0 | J9: =Mangochi!J9+'Monkey Bay'!J9+Namwera!J9+Nkhudzi!J9 -> 0 | K9: =Mangochi!K9+'Monkey Bay'!K9+Namwera!K9+Nkhudzi!K9 -> 0 | ... O9: =Mangochi!O9+'Monkey Bay'!O9+Namwera!O9+Nkhudzi!O9 -> 0 | P9: =SUM(D9:O9) -> 503595
A10: REVENUE WATER - POSTPAID
A11: Volume Billed Individuals | C11: m3 | D11: =Mangochi!D11+'Monkey Bay'!D11+Namwera!D11+Nkhudzi!D11 -> 71261 | E11: =Mangochi!E11+'Monkey Bay'!E11+Namwera!E11+Nkhudzi!E11 -> 78663 | F11: =Mangochi!F11+'Monkey Bay'!F11+Namwera!F11+Nkhudzi!F11 -> 0 | G11: =Mangochi!G11+'Monkey Bay'!G11+Namwera!G11+Nkhudzi!G11 -> 0 | H11: =Mangochi!H11+'Monkey Bay'!H11+Namwera!H11+Nkhudzi!H11 -> 0 | I11: =Mangochi!I11+'Monkey Bay'!I11+Namwera!I11+Nkhudzi!I11 -> 0 | J11: =Mangochi!J11+'Monkey Bay'!J11+Namwera!J11+Nkhudzi!J11 -> 0 | K11: =Mangochi!K11+'Monkey Bay'!K11+Namwera!K11+Nkhudzi!K11 -> 0 | ... O11: =Mangochi!O11+'Monkey Bay'!O11+Namwera!O11+Nkhudzi!O11 -> 0 | P11: =SUM(D11:O11) -> 149924
A12: Volume Billed CWPs | C12: m3 | D12: =Mangochi!D12+'Monkey Bay'!D12+Namwera!D12+Nkhudzi!D12 -> 0 | E12: =Mangochi!E12+'Monkey Bay'!E12+Namwera!E12+Nkhudzi!E12 -> 0 | F12: =Mangochi!F12+'Monkey Bay'!F12+Namwera!F12+Nkhudzi!F12 -> 0 | G12: =Mangochi!G12+'Monkey Bay'!G12+Namwera!G12+Nkhudzi!G12 -> 0 | H12: =Mangochi!H12+'Monkey Bay'!H12+Namwera!H12+Nkhudzi!H12 -> 0 | I12: =Mangochi!I12+'Monkey Bay'!I12+Namwera!I12+Nkhudzi!I12 -> 0 | J12: =Mangochi!J12+'Monkey Bay'!J12+Namwera!J12+Nkhudzi!J12 -> 0 | K12: =Mangochi!K12+'Monkey Bay'!K12+Namwera!K12+Nkhudzi!K12 -> 0 | ... O12: =Mangochi!O12+'Monkey Bay'!O12+Namwera!O12+Nkhudzi!O12 -> 0 | P12: =SUM(D12:O12) -> 0
A13: Volume Billed Institutions | C13: m3 | D13: =Mangochi!D13+'Monkey Bay'!D13+Namwera!D13+Nkhudzi!D13 -> 4476 | E13: =Mangochi!E13+'Monkey Bay'!E13+Namwera!E13+Nkhudzi!E13 -> 5153 | F13: =Mangochi!F13+'Monkey Bay'!F13+Namwera!F13+Nkhudzi!F13 -> 0 | G13: =Mangochi!G13+'Monkey Bay'!G13+Namwera!G13+Nkhudzi!G13 -> 0 | H13: =Mangochi!H13+'Monkey Bay'!H13+Namwera!H13+Nkhudzi!H13 -> 0 | I13: =Mangochi!I13+'Monkey Bay'!I13+Namwera!I13+Nkhudzi!I13 -> 0 | J13: =Mangochi!J13+'Monkey Bay'!J13+Namwera!J13+Nkhudzi!J13 -> 0 | K13: =Mangochi!K13+'Monkey Bay'!K13+Namwera!K13+Nkhudzi!K13 -> 0 | ... O13: =Mangochi!O13+'Monkey Bay'!O13+Namwera!O13+Nkhudzi!O13 -> 0 | P13: =SUM(D13:O13) -> 9629
A14: Volume Billed Commercial/Industrial | C14: m3 | D14: =Mangochi!D14+'Monkey Bay'!D14+Namwera!D14+Nkhudzi!D14 -> 65 | E14: =Mangochi!E14+'Monkey Bay'!E14+Namwera!E14+Nkhudzi!E14 -> 80 | F14: =Mangochi!F14+'Monkey Bay'!F14+Namwera!F14+Nkhudzi!F14 -> 0 | G14: =Mangochi!G14+'Monkey Bay'!G14+Namwera!G14+Nkhudzi!G14 -> 0 | H14: =Mangochi!H14+'Monkey Bay'!H14+Namwera!H14+Nkhudzi!H14 -> 0 | I14: =Mangochi!I14+'Monkey Bay'!I14+Namwera!I14+Nkhudzi!I14 -> 0 | J14: =Mangochi!J14+'Monkey Bay'!J14+Namwera!J14+Nkhudzi!J14 -> 0 | K14: =Mangochi!K14+'Monkey Bay'!K14+Namwera!K14+Nkhudzi!K14 -> 0 | ... O14: =Mangochi!O14+'Monkey Bay'!O14+Namwera!O14+Nkhudzi!O14 -> 0 | P14: =SUM(D14:O14) -> 145
A15: Total Volume Billed Post Paid | C15: m3 | D15: =SUM(D11:D14) -> 75802 | E15: =SUM(E11:E14) -> 83896 | F15: =SUM(F11:F14) -> 0 | G15: =SUM(G11:G14) -> 0 | H15: =SUM(H11:H14) -> 0 | I15: =SUM(I11:I14) -> 0 | J15: =SUM(J11:J14) -> 0 | K15: =SUM(K11:K14) -> 0 | ... P15: =SUM(P11:P14) -> 159698
A16: REVENUE WATER - PREPAID
A17: Individuals | C17: m3 | D17: =Mangochi!D17+'Monkey Bay'!D17+Namwera!D17+Nkhudzi!D17 -> 59225.6 | E17: =Mangochi!E17+'Monkey Bay'!E17+Namwera!E17+Nkhudzi!E17 -> 69450.7 | F17: =Mangochi!F17+'Monkey Bay'!F17+Namwera!F17+Nkhudzi!F17 -> 0 | G17: =Mangochi!G17+'Monkey Bay'!G17+Namwera!G17+Nkhudzi!G17 -> 0 | H17: =Mangochi!H17+'Monkey Bay'!H17+Namwera!H17+Nkhudzi!H17 -> 0 | I17: =Mangochi!I17+'Monkey Bay'!I17+Namwera!I17+Nkhudzi!I17 -> 0 | J17: =Mangochi!J17+'Monkey Bay'!J17+Namwera!J17+Nkhudzi!J17 -> 0 | K17: =Mangochi!K17+'Monkey Bay'!K17+Namwera!K17+Nkhudzi!K17 -> 0 | ... O17: =Mangochi!O17+'Monkey Bay'!O17+Namwera!O17+Nkhudzi!O17 -> 0 | P17: =SUM(D17:O17) -> 128676.3
A18: CWPs | C18: m3 | D18: =Mangochi!D18+'Monkey Bay'!D18+Namwera!D18+Nkhudzi!D18 -> 6557.9 | E18: =Mangochi!E18+'Monkey Bay'!E18+Namwera!E18+Nkhudzi!E18 -> 6254.8 | F18: =Mangochi!F18+'Monkey Bay'!F18+Namwera!F18+Nkhudzi!F18 -> 0 | G18: =Mangochi!G18+'Monkey Bay'!G18+Namwera!G18+Nkhudzi!G18 -> 0 | H18: =Mangochi!H18+'Monkey Bay'!H18+Namwera!H18+Nkhudzi!H18 -> 0 | I18: =Mangochi!I18+'Monkey Bay'!I18+Namwera!I18+Nkhudzi!I18 -> 0 | J18: =Mangochi!J18+'Monkey Bay'!J18+Namwera!J18+Nkhudzi!J18 -> 0 | K18: =Mangochi!K18+'Monkey Bay'!K18+Namwera!K18+Nkhudzi!K18 -> 0 | ... O18: =Mangochi!O18+'Monkey Bay'!O18+Namwera!O18+Nkhudzi!O18 -> 0 | P18: =SUM(D18:O18) -> 12812.7
A19: Institutions | C19: m3 | D19: =Mangochi!D19+'Monkey Bay'!D19+Namwera!D19+Nkhudzi!D19 -> 9056.6 | E19: =Mangochi!E19+'Monkey Bay'!E19+Namwera!E19+Nkhudzi!E19 -> 8118.3 | F19: =Mangochi!F19+'Monkey Bay'!F19+Namwera!F19+Nkhudzi!F19 -> 0 | G19: =Mangochi!G19+'Monkey Bay'!G19+Namwera!G19+Nkhudzi!G19 -> 0 | H19: =Mangochi!H19+'Monkey Bay'!H19+Namwera!H19+Nkhudzi!H19 -> 0 | I19: =Mangochi!I19+'Monkey Bay'!I19+Namwera!I19+Nkhudzi!I19 -> 0 | J19: =Mangochi!J19+'Monkey Bay'!J19+Namwera!J19+Nkhudzi!J19 -> 0 | K19: =Mangochi!K19+'Monkey Bay'!K19+Namwera!K19+Nkhudzi!K19 -> 0 | ... O19: =Mangochi!O19+'Monkey Bay'!O19+Namwera!O19+Nkhudzi!O19 -> 0 | P19: =SUM(D19:O19) -> 17174.9
A20: Commercial/Industrial | C20: m3 | D20: =Mangochi!D20+'Monkey Bay'!D20+Namwera!D20+Nkhudzi!D20 -> 3615.4 | E20: =Mangochi!E20+'Monkey Bay'!E20+Namwera!E20+Nkhudzi!E20 -> 4196.8 | F20: =Mangochi!F20+'Monkey Bay'!F20+Namwera!F20+Nkhudzi!F20 -> 0 | G20: =Mangochi!G20+'Monkey Bay'!G20+Namwera!G20+Nkhudzi!G20 -> 0 | H20: =Mangochi!H20+'Monkey Bay'!H20+Namwera!H20+Nkhudzi!H20 -> 0 | I20: =Mangochi!I20+'Monkey Bay'!I20+Namwera!I20+Nkhudzi!I20 -> 0 | J20: =Mangochi!J20+'Monkey Bay'!J20+Namwera!J20+Nkhudzi!J20 -> 0 | K20: =Mangochi!K20+'Monkey Bay'!K20+Namwera!K20+Nkhudzi!K20 -> 0 | ... O20: =Mangochi!O20+'Monkey Bay'!O20+Namwera!O20+Nkhudzi!O20 -> 0 | P20: =SUM(D20:O20) -> 7812.2
A21: Total Volume Prepaid | C21: m3 | D21: =SUM(D17:D20) -> 78455.5 | E21: =SUM(E17:E20) -> 88020.6 | F21: =SUM(F17:F20) -> 0 | G21: =SUM(G17:G20) -> 0 | H21: =SUM(H17:H20) -> 0 | I21: =SUM(I17:I20) -> 0 | J21: =SUM(J17:J20) -> 0 | K21: =SUM(K17:K20) -> 0 | ... P21: =SUM(P17:P20) -> 166476.1
A22: TOTAL REVENUE WATER | C22: m3 | D22: =D21+D15 -> 154257.5 | E22: =E21+E15 -> 171916.6 | F22: =F21+F15 -> 0 | G22: =G21+G15 -> 0 | H22: =H21+H15 -> 0 | I22: =I21+I15 -> 0 | J22: =J21+J15 -> 0 | K22: =K21+K15 -> 0 | ... P22: =P21+P15 -> 326174.1
A24: Non-Revenue Water (NRW) | B24: Volume | C24: m3 | D24: =D9-D22 -> 93402.5 | E24: =E9-E22 -> 84018.4 | F24: =F9-F22 -> 0 | G24: =G9-G22 -> 0 | H24: =H9-H22 -> 0 | I24: =I9-I22 -> 0 | J24: =J9-J22 -> 0 | K24: =K9-K22 -> 0 | ... P24: =P9-P22 -> 177420.9
B25: Percentage | C25: % | D25: =D24/D9 -> 0.37714003 | E25: =E24/E9 -> 0.32828023 | F25: =F24/F9 -> #DIV/0! | G25: =G24/G9 -> #DIV/0! | H25: =H24/H9 -> #DIV/0! | I25: =I24/I9 -> #DIV/0! | J25: =J24/J9 -> #DIV/0! | K25: =K24/K9 -> #DIV/0! | ... P25: =P24/P9 -> 0.3523087
A26: OPERATING EXPENSES
A27: Chemicals
A28: Chemical | B28: Rate(MK/kg)
A29: Chlorine | B29: 23929.1 | C29: kg | D29: =Mangochi!D29+'Monkey Bay'!D29+Namwera!D29+Nkhudzi!D29 -> 694.5 | E29: =Mangochi!E29+'Monkey Bay'!E29+Namwera!E29+Nkhudzi!E29 -> 718.5 | F29: =Mangochi!F29+'Monkey Bay'!F29+Namwera!F29+Nkhudzi!F29 -> 0 | G29: =Mangochi!G29+'Monkey Bay'!G29+Namwera!G29+Nkhudzi!G29 -> 0 | H29: =Mangochi!H29+'Monkey Bay'!H29+Namwera!H29+Nkhudzi!H29 -> 0 | I29: =Mangochi!I29+'Monkey Bay'!I29+Namwera!I29+Nkhudzi!I29 -> 0 | J29: =Mangochi!J29+'Monkey Bay'!J29+Namwera!J29+Nkhudzi!J29 -> 0 | K29: =Mangochi!K29+'Monkey Bay'!K29+Namwera!K29+Nkhudzi!K29 -> 0 | ... O29: =Mangochi!O29+'Monkey Bay'!O29+Namwera!O29+Nkhudzi!O29 -> 0 | P29: =SUM(D29:O29) -> 1413
C30: kg/mg litre | D30: =Mangochi!D30+'Monkey Bay'!D30+Namwera!D30+Nkhudzi!D30 -> 8.6115359 | E30: =Mangochi!E30+'Monkey Bay'!E30+Namwera!E30+Nkhudzi!E30 -> 8.0512323 | F30: =Mangochi!F30+'Monkey Bay'!F30+Namwera!F30+Nkhudzi!F30 -> #DIV/0! | G30: =Mangochi!G30+'Monkey Bay'!G30+Namwera!G30+Nkhudzi!G30 -> #DIV/0! | H30: =Mangochi!H30+'Monkey Bay'!H30+Namwera!H30+Nkhudzi!H30 -> #DIV/0! | I30: =Mangochi!I30+'Monkey Bay'!I30+Namwera!I30+Nkhudzi!I30 -> #DIV/0! | J30: =Mangochi!J30+'Monkey Bay'!J30+Namwera!J30+Nkhudzi!J30 -> #DIV/0! | K30: =Mangochi!K30+'Monkey Bay'!K30+Namwera!K30+Nkhudzi!K30 -> #DIV/0! | ... O30: =Mangochi!O30+'Monkey Bay'!O30+Namwera!O30+Nkhudzi!O30 -> #DIV/0! | P30: =P29/(P9/1000) -> 2.8058261
A31: Aluminium sulphate | B31: 1090.4 | C31: kg | D31: =Mangochi!D31+'Monkey Bay'!D31+Namwera!D31+Nkhudzi!D31 -> 0 | E31: =Mangochi!E31+'Monkey Bay'!E31+Namwera!E31+Nkhudzi!E31 -> 0 | F31: =Mangochi!F31+'Monkey Bay'!F31+Namwera!F31+Nkhudzi!F31 -> 0 | G31: =Mangochi!G31+'Monkey Bay'!G31+Namwera!G31+Nkhudzi!G31 -> 0 | H31: =Mangochi!H31+'Monkey Bay'!H31+Namwera!H31+Nkhudzi!H31 -> 0 | I31: =Mangochi!I31+'Monkey Bay'!I31+Namwera!I31+Nkhudzi!I31 -> 0 | J31: =Mangochi!J31+'Monkey Bay'!J31+Namwera!J31+Nkhudzi!J31 -> 0 | K31: =Mangochi!K31+'Monkey Bay'!K31+Namwera!K31+Nkhudzi!K31 -> 0 | L31: =Mangochi!L31+'Monkey Bay'!L31+Namwera!L31+Nkhudzi!L31 -> 0 | M31: =Mangochi!M31+'Monkey Bay'!M31+Namwera!M31 -> 0 | N31: =Mangochi!N31+'Monkey Bay'!N31+Namwera!N31 -> 0 | O31: =Mangochi!O31+'Monkey Bay'!O31+Namwera!O31 -> 0 | P31: =SUM(D31:O31) -> 0
C32: kg/mg litre | D32: =Mangochi!D32+'Monkey Bay'!D32+Namwera!D32+Nkhudzi!D32 -> 0 | E32: =Mangochi!E32+'Monkey Bay'!E32+Namwera!E32+Nkhudzi!E32 -> 0 | F32: =Mangochi!F32+'Monkey Bay'!F32+Namwera!F32+Nkhudzi!F32 -> #DIV/0! | G32: =Mangochi!G32+'Monkey Bay'!G32+Namwera!G32+Nkhudzi!G32 -> #DIV/0! | H32: =Mangochi!H32+'Monkey Bay'!H32+Namwera!H32+Nkhudzi!H32 -> #DIV/0! | I32: =Mangochi!I32+'Monkey Bay'!I32+Namwera!I32+Nkhudzi!I32 -> #DIV/0! | J32: =Mangochi!J32+'Monkey Bay'!J32+Namwera!J32+Nkhudzi!J32 -> #DIV/0! | K32: =Mangochi!K32+'Monkey Bay'!K32+Namwera!K32+Nkhudzi!K32 -> #DIV/0! | L32: =Mangochi!L32+'Monkey Bay'!L32+Namwera!L32+Nkhudzi!L32 -> #DIV/0! | M32: =Mangochi!M32+'Monkey Bay'!M32+Namwera!M32 -> #DIV/0! | N32: =Mangochi!N32+'Monkey Bay'!N32+Namwera!N32 -> #DIV/0! | O32: =Mangochi!O32+'Monkey Bay'!O32+Namwera!O32 -> #DIV/0! | P32: =P31/(P9/1000) -> 0
A33: Soda | B33: 1228.2886 | C33: kg | D33: =Mangochi!D33+'Monkey Bay'!D33+Namwera!D33+Nkhudzi!D33 -> 0 | E33: =Mangochi!E33+'Monkey Bay'!E33+Namwera!E33+Nkhudzi!E33 -> 0 | F33: =Mangochi!F33+'Monkey Bay'!F33+Namwera!F33+Nkhudzi!F33 -> 0 | G33: =Mangochi!G33+'Monkey Bay'!G33+Namwera!G33+Nkhudzi!G33 -> 0 | H33: =Mangochi!H33+'Monkey Bay'!H33+Namwera!H33+Nkhudzi!H33 -> 0 | I33: =Mangochi!I33+'Monkey Bay'!I33+Namwera!I33+Nkhudzi!I33 -> 0 | J33: =Mangochi!J33+'Monkey Bay'!J33+Namwera!J33+Nkhudzi!J33 -> 0 | K33: =Mangochi!K33+'Monkey Bay'!K33+Namwera!K33+Nkhudzi!K33 -> 0 | L33: =Mangochi!L33+'Monkey Bay'!L33+Namwera!L33+Nkhudzi!L33 -> 0 | M33: =Mangochi!M33+'Monkey Bay'!M33+Namwera!M33 -> 0 | N33: =Mangochi!N33+'Monkey Bay'!N33+Namwera!N33 -> 0 | O33: =Mangochi!O33+'Monkey Bay'!O33+Namwera!O33 -> 0 | P33: =SUM(D33:O33) -> 0
C34: kg/mg litre | D34: =Mangochi!D34+'Monkey Bay'!D34+Namwera!D34+Nkhudzi!D34 -> 0 | E34: =Mangochi!E34+'Monkey Bay'!E34+Namwera!E34+Nkhudzi!E34 -> 0 | F34: =Mangochi!F34+'Monkey Bay'!F34+Namwera!F34+Nkhudzi!F34 -> #DIV/0! | G34: =Mangochi!G34+'Monkey Bay'!G34+Namwera!G34+Nkhudzi!G34 -> #DIV/0! | H34: =Mangochi!H34+'Monkey Bay'!H34+Namwera!H34+Nkhudzi!H34 -> #DIV/0! | I34: =Mangochi!I34+'Monkey Bay'!I34+Namwera!I34+Nkhudzi!I34 -> #DIV/0! | J34: =Mangochi!J34+'Monkey Bay'!J34+Namwera!J34+Nkhudzi!J34 -> #DIV/0! | K34: =Mangochi!K34+'Monkey Bay'!K34+Namwera!K34+Nkhudzi!K34 -> #DIV/0! | L34: =Mangochi!L34+'Monkey Bay'!L34+Namwera!L34+Nkhudzi!L34 -> #DIV/0! | M34: =Mangochi!M34+'Monkey Bay'!M34+Namwera!M34 -> #DIV/0! | N34: =Mangochi!N34+'Monkey Bay'!N34+Namwera!N34 -> #DIV/0! | O34: =Mangochi!O34+'Monkey Bay'!O34+Namwera!O34 -> #DIV/0! | P34: =P33/(P9/1000) -> 0
A35: Algae floc | B35: 3726.7258 | C35: litres | D35: =Mangochi!D35+'Monkey Bay'!D35+Namwera!D35+Nkhudzi!D35 -> 0 | E35: =Mangochi!E35+'Monkey Bay'!E35+Namwera!E35+Nkhudzi!E35 -> 0 | F35: =Mangochi!F35+'Monkey Bay'!F35+Namwera!F35+Nkhudzi!F35 -> 0 | G35: =Mangochi!G35+'Monkey Bay'!G35+Namwera!G35+Nkhudzi!G35 -> 0 | H35: =Mangochi!H35+'Monkey Bay'!H35+Namwera!H35+Nkhudzi!H35 -> 0 | I35: =Mangochi!I35+'Monkey Bay'!I35+Namwera!I35+Nkhudzi!I35 -> 0 | J35: =Mangochi!J35+'Monkey Bay'!J35+Namwera!J35+Nkhudzi!J35 -> 0 | K35: =Mangochi!K35+'Monkey Bay'!K35+Namwera!K35+Nkhudzi!K35 -> 0 | L35: =Mangochi!L35+'Monkey Bay'!L35+Namwera!L35+Nkhudzi!L35 -> 0 | M35: =Mangochi!M35+'Monkey Bay'!M35+Namwera!M35 -> 0 | N35: =Mangochi!N35+'Monkey Bay'!N35+Namwera!N35 -> 0 | O35: =Mangochi!O35+'Monkey Bay'!O35+Namwera!O35 -> 0
C36: litres/mg litre | D36: =Mangochi!D36+'Monkey Bay'!D36+Namwera!D36+Nkhudzi!D36 -> 0 | E36: =Mangochi!E36+'Monkey Bay'!E36+Namwera!E36+Nkhudzi!E36 -> 0 | F36: =Mangochi!F36+'Monkey Bay'!F36+Namwera!F36+Nkhudzi!F36 -> 0 | G36: =Mangochi!G36+'Monkey Bay'!G36+Namwera!G36+Nkhudzi!G36 -> 0 | H36: =Mangochi!H36+'Monkey Bay'!H36+Namwera!H36+Nkhudzi!H36 -> 0 | I36: =Mangochi!I36+'Monkey Bay'!I36+Namwera!I36+Nkhudzi!I36 -> 0 | J36: =Mangochi!J36+'Monkey Bay'!J36+Namwera!J36+Nkhudzi!J36 -> 0 | K36: =Mangochi!K36+'Monkey Bay'!K36+Namwera!K36+Nkhudzi!K36 -> 0 | L36: =Mangochi!L36+'Monkey Bay'!L36+Namwera!L36+Nkhudzi!L36 -> 0
A37: Sud floc | B37: 3951.5936 | C37: litres | D37: =Mangochi!D37+'Monkey Bay'!D37+Namwera!D37+Nkhudzi!D37 -> 0 | E37: =Mangochi!E37+'Monkey Bay'!E37+Namwera!E37+Nkhudzi!E37 -> 0 | F37: =Mangochi!F37+'Monkey Bay'!F37+Namwera!F37+Nkhudzi!F37 -> 0 | G37: =Mangochi!G37+'Monkey Bay'!G37+Namwera!G37+Nkhudzi!G37 -> 0 | H37: =Mangochi!H37+'Monkey Bay'!H37+Namwera!H37+Nkhudzi!H37 -> 0 | I37: =Mangochi!I37+'Monkey Bay'!I37+Namwera!I37+Nkhudzi!I37 -> 0 | J37: =Mangochi!J37+'Monkey Bay'!J37+Namwera!J37+Nkhudzi!J37 -> 0 | K37: =Mangochi!K37+'Monkey Bay'!K37+Namwera!K37+Nkhudzi!K37 -> 0 | L37: =Mangochi!L37+'Monkey Bay'!L37+Namwera!L37+Nkhudzi!L37 -> 0 | M37: =Mangochi!M37+'Monkey Bay'!M37+Namwera!M37 -> 0 | N37: =Mangochi!N37+'Monkey Bay'!N37+Namwera!N37 -> 0 | O37: =Mangochi!O37+'Monkey Bay'!O37+Namwera!O37 -> 0 | P37: =SUM(D37:O37) -> 0
C38: litres/mg litre | D38: =Mangochi!D38+'Monkey Bay'!D38+Namwera!D38+Nkhudzi!D38 -> 0 | E38: =Mangochi!E38+'Monkey Bay'!E38+Namwera!E38+Nkhudzi!E38 -> 0 | F38: =Mangochi!F38+'Monkey Bay'!F38+Namwera!F38+Nkhudzi!F38 -> #DIV/0! | G38: =Mangochi!G38+'Monkey Bay'!G38+Namwera!G38+Nkhudzi!G38 -> #DIV/0! | H38: =Mangochi!H38+'Monkey Bay'!H38+Namwera!H38+Nkhudzi!H38 -> #DIV/0! | I38: =Mangochi!I38+'Monkey Bay'!I38+Namwera!I38+Nkhudzi!I38 -> #DIV/0! | J38: =Mangochi!J38+'Monkey Bay'!J38+Namwera!J38+Nkhudzi!J38 -> #DIV/0! | K38: =Mangochi!K38+'Monkey Bay'!K38+Namwera!K38+Nkhudzi!K38 -> #DIV/0! | L38: =Mangochi!L38+'Monkey Bay'!L38+Namwera!L38+Nkhudzi!L38 -> #DIV/0! | M38: =Mangochi!M38+'Monkey Bay'!M38+Namwera!M38 -> #DIV/0! | N38: =Mangochi!N38+'Monkey Bay'!N38+Namwera!N38 -> #DIV/0! | O38: =Mangochi!O38+'Monkey Bay'!O38+Namwera!O38 -> #DIV/0! | P38: =P37/(P9/1000) -> 0
A39: Potasium permanganate | B39: 1950 | C39: kg | D39: =Mangochi!D39+'Monkey Bay'!D39+Namwera!D39+Nkhudzi!D39 -> 0 | E39: =Mangochi!E39+'Monkey Bay'!E39+Namwera!E39+Nkhudzi!E39 -> 0 | F39: =Mangochi!F39+'Monkey Bay'!F39+Namwera!F39+Nkhudzi!F39 -> 0 | G39: =Mangochi!G39+'Monkey Bay'!G39+Namwera!G39+Nkhudzi!G39 -> 0 | H39: =Mangochi!H39+'Monkey Bay'!H39+Namwera!H39+Nkhudzi!H39 -> 0 | I39: =Mangochi!I39+'Monkey Bay'!I39+Namwera!I39+Nkhudzi!I39 -> 0 | J39: =Mangochi!J39+'Monkey Bay'!J39+Namwera!J39+Nkhudzi!J39 -> 0 | K39: =Mangochi!K39+'Monkey Bay'!K39+Namwera!K39+Nkhudzi!K39 -> 0 | L39: =Mangochi!L39+'Monkey Bay'!L39+Namwera!L39+Nkhudzi!L39 -> 0 | M39: =Mangochi!M39+'Monkey Bay'!M39+Namwera!M39 -> 0 | N39: =Mangochi!N39+'Monkey Bay'!N39+Namwera!N39 -> 0 | O39: =Mangochi!O39+'Monkey Bay'!O39+Namwera!O39 -> 0 | P39: =SUM(D39:O39) -> 0
C40: kg/mg litre | D40: =Mangochi!D40+'Monkey Bay'!D40+Namwera!D40+Nkhudzi!D40 -> 0 | E40: =Mangochi!E40+'Monkey Bay'!E40+Namwera!E40+Nkhudzi!E40 -> 0 | F40: =Mangochi!F40+'Monkey Bay'!F40+Namwera!F40+Nkhudzi!F40 -> #DIV/0! | G40: =Mangochi!G40+'Monkey Bay'!G40+Namwera!G40+Nkhudzi!G40 -> #DIV/0! | H40: =Mangochi!H40+'Monkey Bay'!H40+Namwera!H40+Nkhudzi!H40 -> #DIV/0! | I40: =Mangochi!I40+'Monkey Bay'!I40+Namwera!I40+Nkhudzi!I40 -> #DIV/0! | J40: =Mangochi!J40+'Monkey Bay'!J40+Namwera!J40+Nkhudzi!J40 -> #DIV/0! | K40: =Mangochi!K40+'Monkey Bay'!K40+Namwera!K40+Nkhudzi!K40 -> #DIV/0! | L40: =Mangochi!L40+'Monkey Bay'!L40+Namwera!L40+Nkhudzi!L40 -> #DIV/0! | M40: =Mangochi!M40+'Monkey Bay'!M40+Namwera!M40 -> #DIV/0! | N40: =Mangochi!N40+'Monkey Bay'!N40+Namwera!N40 -> #DIV/0! | O40: =Mangochi!O40+'Monkey Bay'!O40+Namwera!O40 -> #DIV/0! | P40: =P39/(P9/1000) -> 0
A41: Cost of Chemicals | C41: Mk | D41: =Mangochi!D41+'Monkey Bay'!D41+Namwera!D41+Nkhudzi!D41 -> 16618760 | E41: =Mangochi!E41+'Monkey Bay'!E41+Namwera!E41+Nkhudzi!E41 -> 17193058 | F41: =Mangochi!F41+'Monkey Bay'!F41+Namwera!F41+Nkhudzi!F41 -> 0 | G41: =Mangochi!G41+'Monkey Bay'!G41+Namwera!G41+Nkhudzi!G41 -> 0 | H41: =Mangochi!H41+'Monkey Bay'!H41+Namwera!H41+Nkhudzi!H41 -> 0 | I41: =Mangochi!I41+'Monkey Bay'!I41+Namwera!I41+Nkhudzi!I41 -> 0 | J41: =Mangochi!J41+'Monkey Bay'!J41+Namwera!J41+Nkhudzi!J41 -> 0 | K41: =Mangochi!K41+'Monkey Bay'!K41+Namwera!K41+Nkhudzi!K41 -> 0 | ... O41: =Mangochi!O41+'Monkey Bay'!O41+Namwera!O41+Nkhudzi!O41 -> 0 | P41: =SUM(D41:O41) -> 33811818
A42: Cost/vol. Produced (chemicals) | C42: Mk/m3 | D42: =Mangochi!D42+'Monkey Bay'!D42+Namwera!D42+Nkhudzi!D42 -> 206.0663 | E42: =Mangochi!E42+'Monkey Bay'!E42+Namwera!E42+Nkhudzi!E42 -> 192.65874 | F42: =Mangochi!F42+'Monkey Bay'!F42+Namwera!F42+Nkhudzi!F42 -> #DIV/0! | G42: =Mangochi!G42+'Monkey Bay'!G42+Namwera!G42+Nkhudzi!G42 -> #DIV/0! | H42: =Mangochi!H42+'Monkey Bay'!H42+Namwera!H42+Nkhudzi!H42 -> #DIV/0! | I42: =Mangochi!I42+'Monkey Bay'!I42+Namwera!I42+Nkhudzi!I42 -> #DIV/0! | J42: =Mangochi!J42+'Monkey Bay'!J42+Namwera!J42+Nkhudzi!J42 -> #DIV/0! | K42: =Mangochi!K42+'Monkey Bay'!K42+Namwera!K42+Nkhudzi!K42 -> #DIV/0! | ... O42: =Mangochi!O42+'Monkey Bay'!O42+Namwera!O42+Nkhudzi!O42 -> #DIV/0! | P42: =P41/P9 -> 67.140894
A43: Power
...

Sheet 1st QTR
A1: SOUTHERN REGION WATER BOARD
A3: MONTHLY REPORTS - 2025/2026
A4: MANGOCHI ZONE
A5: MANGOCHI ZONE
A7: PARAMETERS | C7: UNITS | D7: Mangochi | E7: Monkey Bay | F7: Namwera | G7: Nkhudzi | H7: TOTALS
A8: PRODUCTION
A9: Volume Produced | C9: m3 | D9: =Mangochi!D9+Mangochi!E9+Mangochi!F9 -> 305608 | E9: ='Monkey Bay'!D9+'Monkey Bay'!E9+'Monkey Bay'!F9 -> 116050 | F9: =Namwera!D9+Namwera!E9+Namwera!F9 -> 8386 | G9: =Nkhudzi!D9+Nkhudzi!E9+Nkhudzi!F9 -> 73551 | H9: =SUM(D9:G9) -> 503595
A10: REVENUE WATER - POSTPAID
A11: Volume Billed Individuals | C11: m3 | D11: =Mangochi!D11+Mangochi!E11+Mangochi!F11 -> 113884 | E11: ='Monkey Bay'!D11+'Monkey Bay'!E11+'Monkey Bay'!F11 -> 35792 | F11: =Namwera!D11+Namwera!E11+Namwera!F11 -> 21 | G11: =Nkhudzi!D11+Nkhudzi!E11+Nkhudzi!F11 -> 227 | H11: =SUM(D11:G11) -> 149924
A12: Volume Billed CWPs | C12: m3 | D12: =Mangochi!D12+Mangochi!E12+Mangochi!F12 -> 0 | E12: ='Monkey Bay'!D12+'Monkey Bay'!E12+'Monkey Bay'!F12 -> 0 | F12: =Namwera!D12+Namwera!E12+Namwera!F12 -> 0 | G12: =Nkhudzi!D12+Nkhudzi!E12+Nkhudzi!F12 -> 0 | H12: =SUM(D12:G12) -> 0
A13: Volume Billed Institutions | C13: m3 | D13: =Mangochi!D13+Mangochi!E13+Mangochi!F13 -> 304 | E13: ='Monkey Bay'!D13+'Monkey Bay'!E13+'Monkey Bay'!F13 -> 8915 | F13: =Namwera!D13+Namwera!E13+Namwera!F13 -> 7 | G13: =Nkhudzi!D13+Nkhudzi!E13+Nkhudzi!F13 -> 403 | H13: =SUM(D13:G13) -> 9629
A14: Volume Billed Commercial/Industrial | C14: m3 | D14: =Mangochi!D14+Mangochi!E14+Mangochi!F14 -> 143 | E14: ='Monkey Bay'!D14+'Monkey Bay'!E14+'Monkey Bay'!F14 -> 0 | F14: =Namwera!D14+Namwera!E14+Namwera!F14 -> 0 | G14: =Nkhudzi!D14+Nkhudzi!E14+Nkhudzi!F14 -> 2 | H14: =SUM(D14:G14) -> 145
A15: Total Volume Billed Post Paid | C15: m3 | D15: =SUM(D11:D14) -> 114331 | E15: =SUM(E11:E14) -> 44707 | F15: =SUM(F11:F14) -> 28 | G15: =SUM(G11:G14) -> 632 | H15: =SUM(D15:G15) -> 159698
A16: REVENUE WATER - PREPAID
A17: Individuals | C17: m3 | D17: =Mangochi!D17+Mangochi!E17+Mangochi!F17 -> 54757.6 | E17: ='Monkey Bay'!D17+'Monkey Bay'!E17+'Monkey Bay'!F17 -> 18175.1 | F17: =Namwera!D17+Namwera!E17+Namwera!F17 -> 6849.8 | G17: =Nkhudzi!D17+Nkhudzi!E17+Nkhudzi!F17 -> 48893.8 | H17: =SUM(D17:G17) -> 128676.3
A18: CWPs | C18: m3 | D18: =Mangochi!D18+Mangochi!E18+Mangochi!F18 -> 9208.5 | E18: ='Monkey Bay'!D18+'Monkey Bay'!E18+'Monkey Bay'!F18 -> 2244.6 | F18: =Namwera!D18+Namwera!E18+Namwera!F18 -> 0 | G18: =Nkhudzi!D18+Nkhudzi!E18+Nkhudzi!F18 -> 1359.6 | H18: =SUM(D18:G18) -> 12812.7
A19: Institutions | C19: m3 | D19: =Mangochi!D19+Mangochi!E19+Mangochi!F19 -> 10854.9 | E19: ='Monkey Bay'!D19+'Monkey Bay'!E19+'Monkey Bay'!F19 -> 4598.5 | F19: =Namwera!D19+Namwera!E19+Namwera!F19 -> 753.9 | G19: =Nkhudzi!D19+Nkhudzi!E19+Nkhudzi!F19 -> 967.6 | H19: =SUM(D19:G19) -> 17174.9
A20: Commercial/Industrial | C20: m3 | D20: =Mangochi!D20+Mangochi!E20+Mangochi!F20 -> 4331.6 | E20: ='Monkey Bay'!D20+'Monkey Bay'!E20+'Monkey Bay'!F20 -> 1167.8 | F20: =Namwera!D20+Namwera!E20+Namwera!F20 -> 27.8 | G20: =Nkhudzi!D20+Nkhudzi!E20+Nkhudzi!F20 -> 2285 | H20: =SUM(D20:G20) -> 7812.2
A21: Total Volume Prepaid | C21: m3 | D21: =SUM(D17:D20) -> 79152.6 | E21: =SUM(E17:E20) -> 26186 | F21: =SUM(F17:F20) -> 7631.5 | G21: =SUM(G17:G20) -> 53506 | H21: =SUM(D21:G21) -> 166476.1
A22: TOTAL REVENUE WATER | C22: m3 | D22: =D21+D15 -> 193483.6 | E22: =E21+E15 -> 70893 | F22: =F21+F15 -> 7659.5 | G22: =G21+G15 -> 54138 | H22: =SUM(D22:G22) -> 326174.1
A23: NON-REVENUE WATER (NRW)
A24: Non-Revenue Water (NRW) | B24: Volume | C24: m3 | D24: =D9-D22 -> 112124.4 | E24: =E9-E22 -> 45157 | F24: =F9-F22 -> 726.5 | G24: =G9-G22 -> 19413 | H24: =H9-H22 -> 177420.9
B25: Percentage | C25: % | D25: =D24/D9 -> 0.36688961 | E25: =E24/E9 -> 0.38911676 | F25: =F24/F9 -> 0.086632483 | G25: =G24/G9 -> 0.26393931 | H25: =H24/H9 -> 0.3523087
A26: OPERATING EXPENSES
A27: Chemicals
A28: Chemical | B28: Rate(MK/kg)
A29: Chlorine | B29: 3525.29 | C29: kg | D29: =Mangochi!D29+Mangochi!E29+Mangochi!F29 -> 1035.39 | E29: ='Monkey Bay'!D29+'Monkey Bay'!E29+'Monkey Bay'!F29 -> 230 | F29: =Namwera!D29+Namwera!E29+Namwera!F29 -> 8.5 | G29: =Nkhudzi!D29+Nkhudzi!E29+Nkhudzi!F29 -> 139.11 | H29: =SUM(D29:G29) -> 1413
C30: kg/mg litre | D30: =D29/(D9/1000) -> 3.3879676 | E30: =E29/(E9/1000) -> 1.9819044 | F30: =F29/(F9/1000) -> 1.0135941 | G30: =G29/(G9/1000) -> 1.8913407 | H30: =H29/(H9/1000) -> 2.8058261
A31: Aluminium sulphate | B31: 1060.0102 | C31: kg | D31: =Mangochi!D31+Mangochi!E31+Mangochi!F31 -> 0 | E31: ='Monkey Bay'!D31+'Monkey Bay'!E31+'Monkey Bay'!F31 -> 0 | F31: =Namwera!D31+Namwera!E31+Namwera!F31 -> 0 | G31: =Nkhudzi!D31+Nkhudzi!E31+Nkhudzi!F31 -> 0 | H31: =SUM(D31:G31) -> 0
C32: kg/mg litre | D32: =D31/(D9/1000) -> 0 | E32: =E31/(E9/1000) -> 0 | F32: =F31/(F9/1000) -> 0 | G32: =Nkhudzi!D32+Nkhudzi!E32+Nkhudzi!F32 -> #DIV/0! | H32: =H31/(H9/1000) -> 0
A33: Soda | B33: 1228.2886 | C33: kg | D33: =Mangochi!D33+Mangochi!E33+Mangochi!F33 -> 0 | E33: ='Monkey Bay'!D33+'Monkey Bay'!E33+'Monkey Bay'!F33 -> 0 | F33: =Namwera!D33+Namwera!E33+Namwera!F33 -> 0 | G33: =Nkhudzi!D33+Nkhudzi!E33+Nkhudzi!F33 -> 0 | H33: =SUM(D33:F33) -> 0
C34: kg/mg litre | D34: =D33/(D9/1000) -> 0 | E34: =E33/(E9/1000) -> 0 | F34: =F33/(F9/1000) -> 0 | G34: =Nkhudzi!D34+Nkhudzi!E34+Nkhudzi!F34 -> #DIV/0! | H34: =H33/(H9/1000) -> 0
A35: Algae floc | B35: 3726.7258 | C35: litres | D35: =Mangochi!D35+Mangochi!E35+Mangochi!F35 -> 0 | E35: ='Monkey Bay'!D35+'Monkey Bay'!E35+'Monkey Bay'!F35 -> 0 | F35: =Namwera!D35+Namwera!E35+Namwera!F35 -> 0 | G35: =Nkhudzi!D35+Nkhudzi!E35+Nkhudzi!F35 -> 0
C36: litres/mg litre | D36: =D35/(D11/1000) -> 0 | E36: =E35/(E11/1000) -> 0 | F36: =F35/(F11/1000) -> 0 | G36: =Nkhudzi!D36+Nkhudzi!E36+Nkhudzi!F36 -> 0
A37: Sud floc | B37: 3951.5936 | C37: litres | D37: =Mangochi!D37+Mangochi!E37+Mangochi!F37 -> 0 | E37: ='Monkey Bay'!D37+'Monkey Bay'!E37+'Monkey Bay'!F37 -> 0 | F37: =Namwera!D37+Namwera!E37+Namwera!F37 -> 0 | G37: =Nkhudzi!D37+Nkhudzi!E37+Nkhudzi!F37 -> 0 | H37: =SUM(D37:F37) -> 0
C38: litres/mg litre | D38: =D37/(D13/1000) -> 0 | E38: =E37/(E13/1000) -> 0 | F38: =F37/(F13/1000) -> 0 | G38: =Nkhudzi!D38+Nkhudzi!E38+Nkhudzi!F38 -> #DIV/0! | H38: =H37/(H9/1000) -> 0
A39: Potasium permanganate | B39: 1950 | C39: kg | D39: =Mangochi!D39+Mangochi!E39+Mangochi!F39 -> 0 | E39: ='Monkey Bay'!D39+'Monkey Bay'!E39+'Monkey Bay'!F39 -> 0 | F39: =Namwera!D39+Namwera!E39+Namwera!F39 -> 0 | G39: =Nkhudzi!D39+Nkhudzi!E39+Nkhudzi!F39 -> 0 | H39: =SUM(D39:F39) -> 0
C40: kg/mg litre | D40: =D39/(D9/1000) -> 0 | E40: =E39/(E9/1000) -> 0 | F40: =F39/(F9/1000) -> 0 | G40: =Nkhudzi!D40+Nkhudzi!E40+Nkhudzi!F40 -> #DIV/0! | H40: =H39/(H9/1000) -> 0
A41: Cost of Chemicals | C41: Mk | D41: =(D29*$B29)+(D31*$B31)+(D33*$B33)+(D35*$B35)+(D37*$B37)+(D39*$B39) -> 3650050 | E41: =(E29*$B29)+(E31*$B31)+(E33*$B33)+(E35*$B35)+(E37*$B37)+(E39*$B39) -> 810816.7 | F41: =(F29*$B29)+(F31*$B31)+(F33*$B33)+(F35*$B35)+(F37*$B37)+(F39*$B39) -> 29964.965 | G41: =(G29*$B29)+(G31*$B31)+(G33*$B33)+(G35*$B35)+(G37*$B37)+(G39*$B39) -> 490403.09 | H41: =SUM(D41:G41) -> 4981234.8
A42: Cost/vol. Produced (chemicals) | C42: Mk/m3 | D42: =D41/D9 -> 11.943568 | E42: =E41/E9 -> 6.9867876 | F42: =F41/F9 -> 3.5732131 | G42: =G41/G9 -> 6.6675245 | H42: =H41/H9 -> 9.8913507
...

Sheet 2nd QTR 
A1: SOUTHERN REGION WATER BOARD
A3: MONTHLY REPORTS - 2025/2026
A4: MANGOCHI ZONE
A5: MANGOCHI ZONE
A7: PARAMETERS | C7: UNITS | D7: Mangochi | E7: Monkey Bay | F7: Namwera | G7: Nkhudzi | H7: TOTALS
A8: PRODUCTION
A9: Volume Produced | C9: m3 | D9: =Mangochi!G9+Mangochi!H9+Mangochi!I9 -> 0 | E9: ='Monkey Bay'!G9+'Monkey Bay'!H9+'Monkey Bay'!I9 -> 0 | F9: =Namwera!G9+Namwera!H9+Namwera!I9 -> 0 | G9: =Nkhudzi!G9+Nkhudzi!H9+Nkhudzi!I9 -> 0 | H9: =SUM(D9:G9) -> 0
A10: REVENUE WATER - POSTPAID
A11: Volume Billed Individuals | C11: m3 | D11: =Mangochi!G11+Mangochi!H11+Mangochi!I11 -> 0 | E11: ='Monkey Bay'!G11+'Monkey Bay'!H11+'Monkey Bay'!I11 -> 0 | F11: =Namwera!G11+Namwera!H11+Namwera!I11 -> 0 | G11: =Nkhudzi!G11+Nkhudzi!H11+Nkhudzi!I11 -> 0 | H11: =SUM(D11:G11) -> 0
A12: Volume Billed CWPs | C12: m3 | D12: =Mangochi!G12+Mangochi!H12+Mangochi!I12 -> 0 | E12: ='Monkey Bay'!G12+'Monkey Bay'!H12+'Monkey Bay'!I12 -> 0 | F12: =Namwera!G12+Namwera!H12+Namwera!I12 -> 0 | G12: =Nkhudzi!G12+Nkhudzi!H12+Nkhudzi!I12 -> 0 | H12: =SUM(D12:G12) -> 0
A13: Volume Billed Institutions | C13: m3 | D13: =Mangochi!G13+Mangochi!H13+Mangochi!I13 -> 0 | E13: ='Monkey Bay'!G13+'Monkey Bay'!H13+'Monkey Bay'!I13 -> 0 | F13: =Namwera!G13+Namwera!H13+Namwera!I13 -> 0 | G13: =Nkhudzi!G13+Nkhudzi!H13+Nkhudzi!I13 -> 0 | H13: =SUM(D13:G13) -> 0
A14: Volume Billed Commercial/Industrial | C14: m3 | D14: =Mangochi!G14+Mangochi!H14+Mangochi!I14 -> 0 | E14: ='Monkey Bay'!G14+'Monkey Bay'!H14+'Monkey Bay'!I14 -> 0 | F14: =Namwera!G14+Namwera!H14+Namwera!I14 -> 0 | G14: =Nkhudzi!G14+Nkhudzi!H14+Nkhudzi!I14 -> 0 | H14: =SUM(D14:G14) -> 0
A15: Total Volume Billed Post Paid | C15: m3 | D15: =SUM(D11:D14) -> 0 | E15: =SUM(E11:E14) -> 0 | F15: =SUM(F11:F14) -> 0 | G15: =SUM(G11:G14) -> 0 | H15: =SUM(D15:G15) -> 0
A16: REVENUE WATER - PREPAID
A17: Individuals | C17: m3 | D17: =Mangochi!G17+Mangochi!H17+Mangochi!I17 -> 0 | E17: ='Monkey Bay'!G17+'Monkey Bay'!H17+'Monkey Bay'!I17 -> 0 | F17: =Namwera!G17+Namwera!H17+Namwera!I17 -> 0 | G17: =Nkhudzi!G17+Nkhudzi!H17+Nkhudzi!I17 -> 0 | H17: =SUM(D17:G17) -> 0
A18: CWPs | C18: m3 | D18: =Mangochi!G18+Mangochi!H18+Mangochi!I18 -> 0 | E18: ='Monkey Bay'!G18+'Monkey Bay'!H18+'Monkey Bay'!I18 -> 0 | F18: =Namwera!G18+Namwera!H18+Namwera!I18 -> 0 | G18: =Nkhudzi!G18+Nkhudzi!H18+Nkhudzi!I18 -> 0 | H18: =SUM(D18:G18) -> 0
A19: Institutions | C19: m3 | D19: =Mangochi!G19+Mangochi!H19+Mangochi!I19 -> 0 | E19: ='Monkey Bay'!G19+'Monkey Bay'!H19+'Monkey Bay'!I19 -> 0 | F19: =Namwera!G19+Namwera!H19+Namwera!I19 -> 0 | G19: =Nkhudzi!G19+Nkhudzi!H19+Nkhudzi!I19 -> 0 | H19: =SUM(D19:G19) -> 0
A20: Commercial/Industrial | C20: m3 | D20: =Mangochi!G20+Mangochi!H20+Mangochi!I20 -> 0 | E20: ='Monkey Bay'!G20+'Monkey Bay'!H20+'Monkey Bay'!I20 -> 0 | F20: =Namwera!G20+Namwera!H20+Namwera!I20 -> 0 | G20: =Nkhudzi!G20+Nkhudzi!H20+Nkhudzi!I20 -> 0 | H20: =SUM(D20:G20) -> 0
A21: Total Volume Prepaid | C21: m3 | D21: =SUM(D17:D20) -> 0 | E21: =SUM(E17:E20) -> 0 | F21: =SUM(F17:F20) -> 0 | G21: =SUM(G17:G20) -> 0 | H21: =SUM(D21:G21) -> 0
A22: TOTAL REVENUE WATER | C22: m3 | D22: =D21+D15 -> 0 | E22: =E21+E15 -> 0 | F22: =F21+F15 -> 0 | G22: =G21+G15 -> 0 | H22: =SUM(D22:G22) -> 0
A23: NON-REVENUE WATER (NRW)
A24: Non-Revenue Water (NRW) | B24: Volume | C24: m3 | D24: =D9-D22 -> 0 | E24: =E9-E22 -> 0 | F24: =F9-F22 -> 0 | G24: =G9-G22 -> 0 | H24: =H9-H22 -> 0
B25: Percentage | C25: % | D25: =D24/D9 -> #DIV/0! | E25: =E24/E9 -> #DIV/0! | F25: =F24/F9 -> #DIV/0! | G25: =G24/G9 -> #DIV/0! | H25: =H24/H9 -> #DIV/0!
A26: OPERATING EXPENSES
A27: Chemicals
A28: Chemical | B28: Rate(MK/kg)
A29: Chlorine | B29: 3525.29 | C29: kg | D29: =Mangochi!G29+Mangochi!H29+Mangochi!I29 -> 0 | E29: ='Monkey Bay'!G29+'Monkey Bay'!H29+'Monkey Bay'!I29 -> 0 | F29: =Namwera!G29+Namwera!H29+Namwera!I29 -> 0 | G29: =Nkhudzi!G29+Nkhudzi!H29+Nkhudzi!I29 -> 0 | H29: =SUM(D29:G29) -> 0
C30: kg/mg litre | D30: =D29/(D9/1000) -> #DIV/0! | E30: =E29/(E9/1000) -> #DIV/0! | F30: =F29/(F9/1000) -> #DIV/0! | G30: =G29/(G9/1000) -> #DIV/0! | H30: =H29/(H9/1000) -> #DIV/0!
A31: Aluminium sulphate | B31: 1060.0102 | C31: kg | D31: =Mangochi!G31+Mangochi!H31+Mangochi!I31 -> 0 | E31: ='Monkey Bay'!G31+'Monkey Bay'!H31+'Monkey Bay'!I31 -> 0 | F31: =Namwera!G31+Namwera!H31+Namwera!I31 -> 0 | G31: =Nkhudzi!G31+Nkhudzi!H31+Nkhudzi!I31 -> 0 | H31: =SUM(D31:G31) -> 0
C32: kg/mg litre | D32: =D31/(D9/1000) -> #DIV/0! | E32: =E31/(E9/1000) -> #DIV/0! | F32: =F31/(F9/1000) -> #DIV/0! | G32: =Nkhudzi!J32+Nkhudzi!K32+Nkhudzi!L32 -> #DIV/0! | H32: =H31/(H9/1000) -> #DIV/0!
A33: Soda | B33: 1228.2886 | C33: kg | D33: =Mangochi!G33+Mangochi!H33+Mangochi!I33 -> 0 | E33: ='Monkey Bay'!G33+'Monkey Bay'!H33+'Monkey Bay'!I33 -> 0 | F33: =Namwera!G33+Namwera!H33+Namwera!I33 -> 0 | G33: =Nkhudzi!G33+Nkhudzi!H33+Nkhudzi!I33 -> 0 | H33: =SUM(D33:F33) -> 0
C34: kg/mg litre | D34: =D33/(D9/1000) -> #DIV/0! | E34: =E33/(E9/1000) -> #DIV/0! | F34: =F33/(F9/1000) -> #DIV/0! | G34: =Nkhudzi!J34+Nkhudzi!K34+Nkhudzi!L34 -> #DIV/0! | H34: =H33/(H9/1000) -> #DIV/0!
A35: Algae floc | B35: 3726.7258 | C35: litres | D35: =Mangochi!G35+Mangochi!H35+Mangochi!I35 -> 0 | E35: ='Monkey Bay'!G35+'Monkey Bay'!H35+'Monkey Bay'!I35 -> 0 | F35: =Namwera!G35+Namwera!H35+Namwera!I35 -> 0 | G35: =Nkhudzi!G35+Nkhudzi!H35+Nkhudzi!I35 -> 0
C36: litres/mg litre | G36: =Nkhudzi!G36+Nkhudzi!H36+Nkhudzi!I36 -> 0
A37: Sud floc | B37: 3951.5936 | C37: litres | D37: =Mangochi!G37+Mangochi!H37+Mangochi!I37 -> 0 | E37: ='Monkey Bay'!G37+'Monkey Bay'!H37+'Monkey Bay'!I37 -> 0 | F37: =Namwera!G37+Namwera!H37+Namwera!I37 -> 0 | G37: =Nkhudzi!G37+Nkhudzi!H37+Nkhudzi!I37 -> 0 | H37: =SUM(D37:F37) -> 0
C38: litres/mg litre | D38: =D37/(D9/1000) -> #DIV/0! | E38: =E37/(E9/1000) -> #DIV/0! | F38: =F37/(F9/1000) -> #DIV/0! | G38: =Nkhudzi!J38+Nkhudzi!K38+Nkhudzi!L38 -> #DIV/0! | H38: =H37/(H9/1000) -> #DIV/0!
A39: Potasium permanganate | B39: 1950 | C39: kg | D39: =Mangochi!G39+Mangochi!H39+Mangochi!I39 -> 0 | E39: ='Monkey Bay'!G39+'Monkey Bay'!H39+'Monkey Bay'!I39 -> 0 | F39: =Namwera!G39+Namwera!H39+Namwera!I39 -> 0 | G39: =Nkhudzi!G39+Nkhudzi!H39+Nkhudzi!I39 -> 0 | H39: =SUM(D39:F39) -> 0
C40: kg/mg litre | D40: =D39/(D9/1000) -> #DIV/0! | E40: =E39/(E9/1000) -> #DIV/0! | F40: =F39/(F9/1000) -> #DIV/0! | G40: =Nkhudzi!J40+Nkhudzi!K40+Nkhudzi!L40 -> #DIV/0! | H40: =H39/(H9/1000) -> #DIV/0!
A41: Cost of Chemicals | C41: Mk | D41: =(D29*$B29)+(D31*$B31)+(D33*$B33)+(D35*$B35)+(D37*$B37)+(D39*$B39) -> 0 | E41: =(E29*$B29)+(E31*$B31)+(E33*$B33)+(E35*$B35)+(E37*$B37)+(E39*$B39) -> 0 | F41: =(F29*$B29)+(F31*$B31)+(F33*$B33)+(F35*$B35)+(F37*$B37)+(F39*$B39) -> 0 | G41: =(G29*$B29)+(G31*$B31)+(G33*$B33)+(G35*$B35)+(G37*$B37)+(G39*$B39) -> 0 | H41: =SUM(D41:G41) -> 0
A42: Cost/vol. Produced (chemicals) | C42: Mk/m3 | D42: =D41/D9 -> #DIV/0! | E42: =E41/E9 -> #DIV/0! | F42: =F41/F9 -> #DIV/0! | G42: =G41/G9 -> #DIV/0! | H42: =H41/H9 -> #DIV/0!
...

Sheet Midyear Summary
A1: SOUTHERN REGION WATER BOARD
A3: MONTHLY REPORTS - 2025/2026
A4: MANGOCHI ZONE
A5: MANGOCHI ZONE
A7: PARAMETERS | C7: UNITS | D7: Mangochi | E7: Monkey Bay | F7: Namwera | G7: Nkhudzi | H7: TOTALS
A8: PRODUCTION
A9: Volume Produced | C9: m3 | D9: =Mangochi!D9+Mangochi!E9+Mangochi!F9+Mangochi!G9+Mangochi!H9+Mangochi!I9 -> 305608 | E9: ='Monkey Bay'!D9+'Monkey Bay'!E9+'Monkey Bay'!F9+'Monkey Bay'!G9+'Monkey Bay'!H9+'Monkey Bay'!I9 -> 116050 | F9: =Namwera!D9+Namwera!E9+Namwera!F9+Namwera!G9+Namwera!H9+Namwera!I9 -> 8386 | G9: =Nkhudzi!D9+Nkhudzi!E9+Nkhudzi!F9+Nkhudzi!G9+Nkhudzi!H9+Nkhudzi!I9 -> 73551 | H9: =SUM(D9:G9) -> 503595
A10: REVENUE WATER - POSTPAID
A11: Volume Billed Individuals | C11: m3 | D11: =Mangochi!D11+Mangochi!E11+Mangochi!F11+Mangochi!G11+Mangochi!H11+Mangochi!I11 -> 113884 | E11: ='Monkey Bay'!D11+'Monkey Bay'!E11+'Monkey Bay'!F11+'Monkey Bay'!G11+'Monkey Bay'!H11+'Monkey Bay'!I11 -> 35792 | F11: =Namwera!D11+Namwera!E11+Namwera!F11+Namwera!G11+Namwera!H11+Namwera!I11 -> 21 | G11: =Nkhudzi!D11+Nkhudzi!E11+Nkhudzi!F11+Nkhudzi!G11+Nkhudzi!H11+Nkhudzi!I11 -> 227 | H11: =SUM(D11:G11) -> 149924
A12: Volume Billed CWPs | C12: m3 | D12: =Mangochi!D12+Mangochi!E12+Mangochi!F12+Mangochi!G12+Mangochi!H12+Mangochi!I12 -> 0 | E12: ='Monkey Bay'!D12+'Monkey Bay'!E12+'Monkey Bay'!F12+'Monkey Bay'!G12+'Monkey Bay'!H12+'Monkey Bay'!I12 -> 0 | F12: =Namwera!D12+Namwera!E12+Namwera!F12+Namwera!G12+Namwera!H12+Namwera!I12 -> 0 | G12: =Nkhudzi!D12+Nkhudzi!E12+Nkhudzi!F12+Nkhudzi!G12+Nkhudzi!H12+Nkhudzi!I12 -> 0 | H12: =SUM(D12:G12) -> 0
A13: Volume Billed Institutions | C13: m3 | D13: =Mangochi!D13+Mangochi!E13+Mangochi!F13+Mangochi!G13+Mangochi!H13+Mangochi!I13 -> 304 | E13: ='Monkey Bay'!D13+'Monkey Bay'!E13+'Monkey Bay'!F13+'Monkey Bay'!G13+'Monkey Bay'!H13+'Monkey Bay'!I13 -> 8915 | F13: =Namwera!D13+Namwera!E13+Namwera!F13+Namwera!G13+Namwera!H13+Namwera!I13 -> 7 | G13: =Nkhudzi!D13+Nkhudzi!E13+Nkhudzi!F13+Nkhudzi!G13+Nkhudzi!H13+Nkhudzi!I13 -> 403 | H13: =SUM(D13:G13) -> 9629
A14: Volume Billed Commercial/Industrial | C14: m3 | D14: =Mangochi!D14+Mangochi!E14+Mangochi!F14+Mangochi!G14+Mangochi!H14+Mangochi!I14 -> 143 | E14: ='Monkey Bay'!D14+'Monkey Bay'!E14+'Monkey Bay'!F14+'Monkey Bay'!G14+'Monkey Bay'!H14+'Monkey Bay'!I14 -> 0 | F14: =Namwera!D14+Namwera!E14+Namwera!F14+Namwera!G14+Namwera!H14+Namwera!I14 -> 0 | G14: =Nkhudzi!D14+Nkhudzi!E14+Nkhudzi!F14+Nkhudzi!G14+Nkhudzi!H14+Nkhudzi!I14 -> 2 | H14: =SUM(D14:G14) -> 145
A15: Total Volume Billed Post Paid | C15: m3 | D15: =SUM(D11:D14) -> 114331 | E15: =SUM(E11:E14) -> 44707 | F15: =SUM(F11:F14) -> 28 | G15: =SUM(G11:G14) -> 632 | H15: =SUM(D15:G15) -> 159698
A16: REVENUE WATER - PREPAID
A17: Individuals | C17: m3 | D17: =Mangochi!D17+Mangochi!E17+Mangochi!F17+Mangochi!G17+Mangochi!H17+Mangochi!I17 -> 54757.6 | E17: ='Monkey Bay'!D17+'Monkey Bay'!E17+'Monkey Bay'!F17+'Monkey Bay'!G17+'Monkey Bay'!H17+'Monkey Bay'!I17 -> 18175.1 | F17: =Namwera!D17+Namwera!E17+Namwera!F17+Namwera!G17+Namwera!H17+Namwera!I17 -> 6849.8 | G17: =Nkhudzi!D17+Nkhudzi!E17+Nkhudzi!F17+Nkhudzi!G17+Nkhudzi!H17+Nkhudzi!I17 -> 48893.8 | H17: =SUM(D17:G17) -> 128676.3
